<sdf version='1.5'>
    <world name='default'>
        <light name='sun' type='directional'>
            <cast_shadows>1</cast_shadows>
            <pose>0 0 10 0 -0 0</pose>
            <diffuse>0.8 0.8 0.8 1</diffuse>
            <specular>0.2 0.2 0.2 1</specular>
            <attenuation>
                <range>1000</range>
                <constant>0.9</constant>
                <linear>0.01</linear>
                <quadratic>0.001</quadratic>
            </attenuation>
            <direction>-0.5 0.1 -0.9</direction>
        </light>
        <model name='ground_plane'>
            <static>1</static>
            <link name='link'>
                <collision name='collision'>
                    <geometry>
                        <plane>
                            <normal>0 0 1</normal>
                            <size>100 100</size>
                        </plane>
                    </geometry>
                    <surface>
                        <friction>
                            <ode>
                                <mu>100</mu>
                                <mu2>50</mu2>
                            </ode>
                        </friction>
                        <contact>
                            <ode/>
                        </contact>
                        <bounce/>
                    </surface>
                    <max_contacts>10</max_contacts>
                </collision>
                <visual name='visual'>
                    <cast_shadows>0</cast_shadows>
                    <geometry>
                        <plane>
                            <normal>0 0 1</normal>
                            <size>100 100</size>
                        </plane>
                    </geometry>
                    <material>
                        <script>
                            <uri>file://media/materials/scripts/gazebo.material</uri>
                            <name>Gazebo/Road</name>
                        </script>
                    </material>
                </visual>
                <self_collide>0</self_collide>
                <kinematic>0</kinematic>
                <gravity>1</gravity>
            </link>
        </model>
        <physics name='default_physics' default='0' type='ode'>
            <max_step_size>0.001</max_step_size>
            <real_time_factor>1</real_time_factor>
            <real_time_update_rate>1000</real_time_update_rate>
            <gravity>0 0 -9.8</gravity>
            <magnetic_field>5.5645e-06 2.28758e-05 -4.23884e-05</magnetic_field>
        </physics>
        <scene>
            <ambient>0.4 0.4 0.4 1</ambient>
            <background>0.0 0.0 0.0 1</background>
            <shadows>true</shadows>
            <grid>false</grid>
        </scene>
        <spherical_coordinates>
            <surface_model>EARTH_WGS84</surface_model>
            <latitude_deg>0</latitude_deg>
            <longitude_deg>0</longitude_deg>
            <elevation>0</elevation>
            <heading_deg>0</heading_deg>
        </spherical_coordinates>
        <model name='LIDAMaze_0'>
            <pose>2.56238 0 0 0 -0 0</pose>
            <link name='Wall_10'>
                <collision name='Wall_10_Collision'>
                    <geometry>
                        <box>
                            <size>12.25 0.15 2.5</size>
                        </box>
                    </geometry>
                    <pose>0 0 1.25 0 -0 0</pose>
                    <max_contacts>10</max_contacts>
                    <surface>
                        <contact>
                            <ode/>
                        </contact>
                        <bounce/>
                        <friction>
                            <ode/>
                        </friction>
                    </surface>
                </collision>
                <visual name='Wall_10_Visual'>
                    <pose>0 0 1.25 0 -0 0</pose>
                    <geometry>
                        <box>
                            <size>12.25 0.15 2.5</size>
                        </box>
                    </geometry>
                    <material>
                        <script>
                            <uri>file://media/materials/scripts/gazebo.material</uri>
                            <name>Gazebo/Bricks</name>
                        </script>
                        <ambient>0.760784 0.662745 0.627451 1</ambient>
                    </material>
                </visual>
                <pose>-20.0637 -12.4268 0 0 -0 0</pose>
                <self_collide>0</self_collide>
                <kinematic>0</kinematic>
                <gravity>1</gravity>
            </link>
            <link name='Wall_12'>
                <collision name='Wall_12_Collision'>
                    <geometry>
                        <box>
                            <size>5.5 0.15 2.5</size>
                        </box>
                    </geometry>
                    <pose>0 0 1.25 0 -0 0</pose>
                    <max_contacts>10</max_contacts>
                    <surface>
                        <contact>
                            <ode/>
                        </contact>
                        <bounce/>
                        <friction>
                            <ode/>
                        </friction>
                    </surface>
                </collision>
                <visual name='Wall_12_Visual'>
                    <pose>0 0 1.25 0 -0 0</pose>
                    <geometry>
                        <box>
                            <size>5.5 0.15 2.5</size>
                        </box>
                    </geometry>
                    <material>
                        <script>
                            <uri>file://media/materials/scripts/gazebo.material</uri>
                            <name>Gazebo/Bricks</name>
                        </script>
                        <ambient>0.760784 0.662745 0.627451 1</ambient>
                    </material>
                </visual>
                <pose>-23.4387 10.1732 0 0 -0 0</pose>
                <self_collide>0</self_collide>
                <kinematic>0</kinematic>
                <gravity>1</gravity>
            </link>
            <link name='Wall_13'>
                <collision name='Wall_13_Collision'>
                    <geometry>
                        <box>
                            <size>18 0.15 2.5</size>
                        </box>
                    </geometry>
                    <pose>0 0 1.25 0 -0 0</pose>
                    <max_contacts>10</max_contacts>
                    <surface>
                        <contact>
                            <ode/>
                        </contact>
                        <bounce/>
                        <friction>
                            <ode/>
                        </friction>
                    </surface>
                </collision>
                <visual name='Wall_13_Visual'>
                    <pose>0 0 1.25 0 -0 0</pose>
                    <geometry>
                        <box>
                            <size>18 0.15 2.5</size>
                        </box>
                    </geometry>
                    <material>
                        <script>
                            <uri>file://media/materials/scripts/gazebo.material</uri>
                            <name>Gazebo/Bricks</name>
                        </script>
                        <ambient>0.760784 0.662745 0.627451 1</ambient>
                    </material>
                </visual>
                <pose>-20.7637 1.24818 0 0 0 -1.5708</pose>
                <self_collide>0</self_collide>
                <kinematic>0</kinematic>
                <gravity>1</gravity>
            </link>
            <link name='Wall_18'>
                <collision name='Wall_18_Collision'>
                    <geometry>
                        <box>
                            <size>1.75 0.15 2.5</size>
                        </box>
                    </geometry>
                    <pose>0 0 1.25 0 -0 0</pose>
                    <max_contacts>10</max_contacts>
                    <surface>
                        <contact>
                            <ode/>
                        </contact>
                        <bounce/>
                        <friction>
                            <ode/>
                        </friction>
                    </surface>
                </collision>
                <visual name='Wall_18_Visual'>
                    <pose>0 0 1.25 0 -0 0</pose>
                    <geometry>
                        <box>
                            <size>1.75 0.15 2.5</size>
                        </box>
                    </geometry>
                    <material>
                        <script>
                            <uri>file://media/materials/scripts/gazebo.material</uri>
                            <name>Gazebo/Bricks</name>
                        </script>
                        <ambient>0.760784 0.662745 0.627451 1</ambient>
                    </material>
                </visual>
                <pose>-7.26372 -5.67682 0 0 -0 0</pose>
                <self_collide>0</self_collide>
                <kinematic>0</kinematic>
                <gravity>1</gravity>
            </link>
            <link name='Wall_19'>
                <collision name='Wall_19_Collision'>
                    <geometry>
                        <box>
                            <size>18.25 0.15 2.5</size>
                        </box>
                    </geometry>
                    <pose>0 0 1.25 0 -0 0</pose>
                    <max_contacts>10</max_contacts>
                    <surface>
                        <contact>
                            <ode/>
                        </contact>
                        <bounce/>
                        <friction>
                            <ode/>
                        </friction>
                    </surface>
                </collision>
                <visual name='Wall_19_Visual'>
                    <pose>0 0 1.25 0 -0 0</pose>
                    <geometry>
                        <box>
                            <size>18.25 0.15 2.5</size>
                        </box>
                    </geometry>
                    <material>
                        <script>
                            <uri>file://media/materials/scripts/gazebo.material</uri>
                            <name>Gazebo/Bricks</name>
                        </script>
                        <ambient>0.760784 0.662745 0.627451 1</ambient>
                    </material>
                </visual>
                <pose>-6.46372 3.37318 0 0 -0 1.5708</pose>
                <self_collide>0</self_collide>
                <kinematic>0</kinematic>
                <gravity>1</gravity>
            </link>
            <link name='Wall_20'>
                <collision name='Wall_20_Collision'>
                    <geometry>
                        <box>
                            <size>16.25 0.15 2.5</size>
                        </box>
                    </geometry>
                    <pose>0 0 1.25 0 -0 0</pose>
                    <max_contacts>10</max_contacts>
                    <surface>
                        <contact>
                            <ode/>
                        </contact>
                        <bounce/>
                        <friction>
                            <ode/>
                        </friction>
                    </surface>
                </collision>
                <visual name='Wall_20_Visual'>
                    <pose>0 0 1.25 0 -0 0</pose>
                    <geometry>
                        <box>
                            <size>16.25 0.15 2.5</size>
                        </box>
                    </geometry>
                    <material>
                        <script>
                            <uri>file://media/materials/scripts/gazebo.material</uri>
                            <name>Gazebo/Bricks</name>
                        </script>
                        <ambient>0.760784 0.662745 0.627451 1</ambient>
                    </material>
                </visual>
                <pose>-0.771507 6.73097 0 0 0 -0.785398</pose>
                <self_collide>0</self_collide>
                <kinematic>0</kinematic>
                <gravity>1</gravity>
            </link>
            <link name='Wall_21'>
                <collision name='Wall_21_Collision'>
                    <geometry>
                        <box>
                            <size>10 0.15 2.5</size>
                        </box>
                    </geometry>
                    <pose>0 0 1.25 0 -0 0</pose>
                    <max_contacts>10</max_contacts>
                    <surface>
                        <contact>
                            <ode/>
                        </contact>
                        <bounce/>
                        <friction>
                            <ode/>
                        </friction>
                    </surface>
                </collision>
                <visual name='Wall_21_Visual'>
                    <pose>0 0 1.25 0 -0 0</pose>
                    <geometry>
                        <box>
                            <size>10 0.15 2.5</size>
                        </box>
                    </geometry>
                    <material>
                        <script>
                            <uri>file://media/materials/scripts/gazebo.material</uri>
                            <name>Gazebo/Bricks</name>
                        </script>
                        <ambient>0.760784 0.662745 0.627451 1</ambient>
                    </material>
                </visual>
                <pose>3.64602 -3.71842 0 0 0 -1.8326</pose>
                <self_collide>0</self_collide>
                <kinematic>0</kinematic>
                <gravity>1</gravity>
            </link>
            <link name='Wall_22'>
                <collision name='Wall_22_Collision'>
                    <geometry>
                        <box>
                            <size>2 0.15 2.5</size>
                        </box>
                    </geometry>
                    <pose>0 0 1.25 0 -0 0</pose>
                    <max_contacts>10</max_contacts>
                    <surface>
                        <contact>
                            <ode/>
                        </contact>
                        <bounce/>
                        <friction>
                            <ode/>
                        </friction>
                    </surface>
                </collision>
                <visual name='Wall_22_Visual'>
                    <pose>0 0 1.25 0 -0 0</pose>
                    <geometry>
                        <box>
                            <size>2 0.15 2.5</size>
                        </box>
                    </geometry>
                    <material>
                        <script>
                            <uri>file://media/materials/scripts/gazebo.material</uri>
                            <name>Gazebo/Bricks</name>
                        </script>
                        <ambient>0.760784 0.662745 0.627451 1</ambient>
                    </material>
                </visual>
                <pose>3.29634 -8.4756 0 0 -0 0</pose>
                <self_collide>0</self_collide>
                <kinematic>0</kinematic>
                <gravity>1</gravity>
            </link>
            <link name='Wall_23'>
                <collision name='Wall_23_Collision'>
                    <geometry>
                        <box>
                            <size>19.75 0.15 2.5</size>
                        </box>
                    </geometry>
                    <pose>0 0 1.25 0 -0 0</pose>
                    <max_contacts>10</max_contacts>
                    <surface>
                        <contact>
                            <ode/>
                        </contact>
                        <bounce/>
                        <friction>
                            <ode/>
                        </friction>
                    </surface>
                </collision>
                <visual name='Wall_23_Visual'>
                    <pose>0 0 1.25 0 -0 0</pose>
                    <geometry>
                        <box>
                            <size>19.75 0.15 2.5</size>
                        </box>
                    </geometry>
                    <material>
                        <script>
                            <uri>file://media/materials/scripts/gazebo.material</uri>
                            <name>Gazebo/Bricks</name>
                        </script>
                        <ambient>0.760784 0.662745 0.627451 1</ambient>
                    </material>
                </visual>
                <pose>9.12134 0.011445 0 0 -0 1.0472</pose>
                <self_collide>0</self_collide>
                <kinematic>0</kinematic>
                <gravity>1</gravity>
            </link>
            <link name='Wall_26'>
                <collision name='Wall_26_Collision'>
                    <geometry>
                        <box>
                            <size>40.25 0.15 2.5</size>
                        </box>
                    </geometry>
                    <pose>0 0 1.25 0 -0 0</pose>
                    <max_contacts>10</max_contacts>
                    <surface>
                        <contact>
                            <ode/>
                        </contact>
                        <bounce/>
                        <friction>
                            <ode/>
                        </friction>
                    </surface>
                </collision>
                <visual name='Wall_26_Visual'>
                    <pose>0 0 1.25 0 -0 0</pose>
                    <geometry>
                        <box>
                            <size>40.25 0.15 2.5</size>
                        </box>
                    </geometry>
                    <material>
                        <script>
                            <uri>file://media/materials/scripts/gazebo.material</uri>
                            <name>Gazebo/Bricks</name>
                        </script>
                        <ambient>0.760784 0.662745 0.627451 1</ambient>
                    </material>
                </visual>
                <pose>6.03628 -12.4268 0 0 -0 0</pose>
                <self_collide>0</self_collide>
                <kinematic>0</kinematic>
                <gravity>1</gravity>
            </link>
            <link name='Wall_27'>
                <collision name='Wall_27_Collision'>
                    <geometry>
                        <box>
                            <size>24.3043 0.15 2.5</size>
                        </box>
                    </geometry>
                    <pose>0 0 1.25 0 -0 0</pose>
                    <max_contacts>10</max_contacts>
                    <surface>
                        <contact>
                            <ode/>
                        </contact>
                        <bounce/>
                        <friction>
                            <ode/>
                        </friction>
                    </surface>
                </collision>
                <visual name='Wall_27_Visual'>
                    <pose>0 0 1.25 0 -0 0</pose>
                    <geometry>
                        <box>
                            <size>24.3043 0.15 2.5</size>
                        </box>
                    </geometry>
                    <material>
                        <script>
                            <uri>file://media/materials/scripts/gazebo.material</uri>
                            <name>Gazebo/Bricks</name>
                        </script>
                        <ambient>0.760784 0.662745 0.627451 1</ambient>
                    </material>
                </visual>
                <pose>20.0538 -1.96416 0 0 -0 2.09381</pose>
                <self_collide>0</self_collide>
                <kinematic>0</kinematic>
                <gravity>1</gravity>
            </link>
            <link name='Wall_56'>
                <collision name='Wall_56_Collision'>
                    <geometry>
                        <box>
                            <size>5.25 0.15 2.5</size>
                        </box>
                    </geometry>
                    <pose>0 0 1.25 0 -0 0</pose>
                    <max_contacts>10</max_contacts>
                    <surface>
                        <contact>
                            <ode/>
                        </contact>
                        <bounce/>
                        <friction>
                            <ode/>
                        </friction>
                    </surface>
                </collision>
                <visual name='Wall_56_Visual'>
                    <pose>0 0 1.25 0 -0 0</pose>
                    <geometry>
                        <box>
                            <size>5.25 0.15 2.5</size>
                        </box>
                    </geometry>
                    <material>
                        <script>
                            <uri>file://media/materials/scripts/gazebo.material</uri>
                            <name>Gazebo/Bricks</name>
                        </script>
                        <ambient>0.760784 0.662745 0.627451 1</ambient>
                    </material>
                </visual>
                <pose>-18.2137 -7.67682 0 0 -0 0</pose>
                <self_collide>0</self_collide>
                <kinematic>0</kinematic>
                <gravity>1</gravity>
            </link>
            <link name='Wall_57'>
                <collision name='Wall_57_Collision'>
                    <geometry>
                        <box>
                            <size>14.25 0.15 2.5</size>
                        </box>
                    </geometry>
                    <pose>0 0 1.25 0 -0 0</pose>
                    <max_contacts>10</max_contacts>
                    <surface>
                        <contact>
                            <ode/>
                        </contact>
                        <bounce/>
                        <friction>
                            <ode/>
                        </friction>
                    </surface>
                </collision>
                <visual name='Wall_57_Visual'>
                    <pose>0 0 1.25 0 -0 0</pose>
                    <geometry>
                        <box>
                            <size>14.25 0.15 2.5</size>
                        </box>
                    </geometry>
                    <material>
                        <script>
                            <uri>file://media/materials/scripts/gazebo.material</uri>
                            <name>Gazebo/Bricks</name>
                        </script>
                        <ambient>0.760784 0.662745 0.627451 1</ambient>
                    </material>
                </visual>
                <pose>-15.6637 -0.626816 0 0 -0 1.5708</pose>
                <self_collide>0</self_collide>
                <kinematic>0</kinematic>
                <gravity>1</gravity>
            </link>
            <link name='Wall_60'>
                <collision name='Wall_60_Collision'>
                    <geometry>
                        <box>
                            <size>12.25 0.15 2.5</size>
                        </box>
                    </geometry>
                    <pose>0 0 1.25 0 -0 0</pose>
                    <max_contacts>10</max_contacts>
                    <surface>
                        <contact>
                            <ode/>
                        </contact>
                        <bounce/>
                        <friction>
                            <ode/>
                        </friction>
                    </surface>
                </collision>
                <visual name='Wall_60_Visual'>
                    <pose>0 0 1.25 0 -0 0</pose>
                    <geometry>
                        <box>
                            <size>12.25 0.15 2.5</size>
                        </box>
                    </geometry>
                    <material>
                        <script>
                            <uri>file://media/materials/scripts/gazebo.material</uri>
                            <name>Gazebo/Bricks</name>
                        </script>
                        <ambient>0.760784 0.662745 0.627451 1</ambient>
                    </material>
                </visual>
                <pose>-8.06372 0.373184 0 0 -0 1.5708</pose>
                <self_collide>0</self_collide>
                <kinematic>0</kinematic>
                <gravity>1</gravity>
            </link>
            <link name='Wall_62'>
                <collision name='Wall_62_Collision'>
                    <geometry>
                        <box>
                            <size>7.75 0.15 2.5</size>
                        </box>
                    </geometry>
                    <pose>0 0 1.25 0 -0 0</pose>
                    <max_contacts>10</max_contacts>
                    <surface>
                        <contact>
                            <ode/>
                        </contact>
                        <bounce/>
                        <friction>
                            <ode/>
                        </friction>
                    </surface>
                </collision>
                <visual name='Wall_62_Visual'>
                    <pose>0 0 1.25 0 -0 0</pose>
                    <geometry>
                        <box>
                            <size>7.75 0.15 2.5</size>
                        </box>
                    </geometry>
                    <material>
                        <script>
                            <uri>file://media/materials/scripts/gazebo.material</uri>
                            <name>Gazebo/Bricks</name>
                        </script>
                        <ambient>0.760784 0.662745 0.627451 1</ambient>
                    </material>
                </visual>
                <pose>-11.8637 6.42318 0 0 -0 0</pose>
                <self_collide>0</self_collide>
                <kinematic>0</kinematic>
                <gravity>1</gravity>
            </link>
            <link name='Wall_66'>
                <collision name='Wall_66_Collision'>
                    <geometry>
                        <box>
                            <size>13.75 0.15 2.5</size>
                        </box>
                    </geometry>
                    <pose>0 0 1.25 0 -0 0</pose>
                    <max_contacts>10</max_contacts>
                    <surface>
                        <contact>
                            <ode/>
                        </contact>
                        <bounce/>
                        <friction>
                            <ode/>
                        </friction>
                    </surface>
                </collision>
                <visual name='Wall_66_Visual'>
                    <pose>0 0 1.25 0 -0 0</pose>
                    <geometry>
                        <box>
                            <size>13.75 0.15 2.5</size>
                        </box>
                    </geometry>
                    <material>
                        <script>
                            <uri>file://media/materials/scripts/gazebo.material</uri>
                            <name>Gazebo/Bricks</name>
                        </script>
                        <ambient>0.760784 0.662745 0.627451 1</ambient>
                    </material>
                </visual>
                <pose>-11.8252 -5.37061 0 0 0 -1.5708</pose>
                <self_collide>0</self_collide>
                <kinematic>0</kinematic>
                <gravity>1</gravity>
            </link>
            <link name='Wall_77'>
                <collision name='Wall_77_Collision'>
                    <geometry>
                        <box>
                            <size>14.25 0.15 2.5</size>
                        </box>
                    </geometry>
                    <pose>0 0 1.25 0 -0 0</pose>
                    <max_contacts>10</max_contacts>
                    <surface>
                        <contact>
                            <ode/>
                        </contact>
                        <bounce/>
                        <friction>
                            <ode/>
                        </friction>
                    </surface>
                </collision>
                <visual name='Wall_77_Visual'>
                    <pose>0 0 1.25 0 -0 0</pose>
                    <geometry>
                        <box>
                            <size>14.25 0.15 2.5</size>
                        </box>
                    </geometry>
                    <material>
                        <script>
                            <uri>file://media/materials/scripts/gazebo.material</uri>
                            <name>Gazebo/Bricks</name>
                        </script>
                        <ambient>0.760784 0.662745 0.627451 1</ambient>
                    </material>
                </visual>
                <pose>-1.29537 -5.42338 0 0 -0 1.309</pose>
                <self_collide>0</self_collide>
                <kinematic>0</kinematic>
                <gravity>1</gravity>
            </link>
            <link name='Wall_78'>
                <collision name='Wall_78_Collision'>
                    <geometry>
                        <box>
                            <size>5.25 0.15 2.5</size>
                        </box>
                    </geometry>
                    <pose>0 0 1.25 0 -0 0</pose>
                    <max_contacts>10</max_contacts>
                    <surface>
                        <contact>
                            <ode/>
                        </contact>
                        <bounce/>
                        <friction>
                            <ode/>
                        </friction>
                    </surface>
                </collision>
                <visual name='Wall_78_Visual'>
                    <pose>0 0 1.25 0 -0 0</pose>
                    <geometry>
                        <box>
                            <size>5.25 0.15 2.5</size>
                        </box>
                    </geometry>
                    <material>
                        <script>
                            <uri>file://media/materials/scripts/gazebo.material</uri>
                            <name>Gazebo/Bricks</name>
                        </script>
                        <ambient>0.760784 0.662745 0.627451 1</ambient>
                    </material>
                </visual>
                <pose>-1.27382 3.18952 0 0 -0 2.35619</pose>
                <self_collide>0</self_collide>
                <kinematic>0</kinematic>
                <gravity>1</gravity>
            </link>
            <link name='Wall_80'>
                <collision name='Wall_80_Collision'>
                    <geometry>
                        <box>
                            <size>17.3759 0.15 2.5</size>
                        </box>
                    </geometry>
                    <pose>0 0 1.25 0 -0 0</pose>
                    <max_contacts>10</max_contacts>
                    <surface>
                        <contact>
                            <ode/>
                        </contact>
                        <bounce/>
                        <friction>
                            <ode/>
                        </friction>
                    </surface>
                </collision>
                <visual name='Wall_80_Visual'>
                    <pose>0 0 1.25 0 -0 0</pose>
                    <geometry>
                        <box>
                            <size>17.3759 0.15 2.5</size>
                        </box>
                    </geometry>
                    <material>
                        <script>
                            <uri>file://media/materials/scripts/gazebo.material</uri>
                            <name>Gazebo/Bricks</name>
                        </script>
                        <ambient>0.760784 0.662745 0.627451 1</ambient>
                    </material>
                </visual>
                <pose>-3.09849 -3.62025 0 0 0 -1.5733</pose>
                <self_collide>0</self_collide>
                <kinematic>0</kinematic>
                <gravity>1</gravity>
            </link>
            <link name='Wall_82'>
                <collision name='Wall_82_Collision'>
                    <geometry>
                        <box>
                            <size>13.6254 0.15 2.5</size>
                        </box>
                    </geometry>
                    <pose>0 0 1.25 0 -0 0</pose>
                    <max_contacts>10</max_contacts>
                    <surface>
                        <contact>
                            <ode/>
                        </contact>
                        <bounce/>
                        <friction>
                            <ode/>
                        </friction>
                    </surface>
                </collision>
                <visual name='Wall_82_Visual'>
                    <pose>0 0 1.25 0 -0 0</pose>
                    <geometry>
                        <box>
                            <size>13.6254 0.15 2.5</size>
                        </box>
                    </geometry>
                    <material>
                        <script>
                            <uri>file://media/materials/scripts/gazebo.material</uri>
                            <name>Gazebo/Bricks</name>
                        </script>
                        <ambient>0.760784 0.662745 0.627451 1</ambient>
                    </material>
                </visual>
                <pose>9.74979 -6.43774 0 0 0 -2.05523</pose>
                <self_collide>0</self_collide>
                <kinematic>0</kinematic>
                <gravity>1</gravity>
            </link>
            <link name='Wall_84'>
                <collision name='Wall_84_Collision'>
                    <geometry>
                        <box>
                            <size>2.75 0.15 2.5</size>
                        </box>
                    </geometry>
                    <pose>0 0 1.25 0 -0 0</pose>
                    <max_contacts>10</max_contacts>
                    <surface>
                        <contact>
                            <ode/>
                        </contact>
                        <bounce/>
                        <friction>
                            <ode/>
                        </friction>
                    </surface>
                </collision>
                <visual name='Wall_84_Visual'>
                    <pose>0 0 1.25 0 -0 0</pose>
                    <geometry>
                        <box>
                            <size>2.75 0.15 2.5</size>
                        </box>
                    </geometry>
                    <material>
                        <script>
                            <uri>file://media/materials/scripts/gazebo.material</uri>
                            <name>Gazebo/Bricks</name>
                        </script>
                        <ambient>0.760784 0.662745 0.627451 1</ambient>
                    </material>
                </visual>
                <pose>14.1876 -0.475286 0 0 -0 0</pose>
                <self_collide>0</self_collide>
                <kinematic>0</kinematic>
                <gravity>1</gravity>
            </link>
            <link name='Wall_85'>
                <collision name='Wall_85_Collision'>
                    <geometry>
                        <box>
                            <size>4.91506 0.15 2.5</size>
                        </box>
                    </geometry>
                    <pose>0 0 1.25 0 -0 0</pose>
                    <max_contacts>10</max_contacts>
                    <surface>
                        <contact>
                            <ode/>
                        </contact>
                        <bounce/>
                        <friction>
                            <ode/>
                        </friction>
                    </surface>
                </collision>
                <visual name='Wall_85_Visual'>
                    <pose>0 0 1.25 0 -0 0</pose>
                    <geometry>
                        <box>
                            <size>4.91506 0.15 2.5</size>
                        </box>
                    </geometry>
                    <material>
                        <script>
                            <uri>file://media/materials/scripts/gazebo.material</uri>
                            <name>Gazebo/Bricks</name>
                        </script>
                        <ambient>0.760784 0.662745 0.627451 1</ambient>
                    </material>
                </visual>
                <pose>16.5617 -2.60193 0 0 0 -1.10308</pose>
                <self_collide>0</self_collide>
                <kinematic>0</kinematic>
                <gravity>1</gravity>
            </link>
            <link name='Wall_9'>
                <collision name='Wall_9_Collision'>
                    <geometry>
                        <box>
                            <size>22.75 0.15 2.5</size>
                        </box>
                    </geometry>
                    <pose>0 0 1.25 0 -0 0</pose>
                    <max_contacts>10</max_contacts>
                    <surface>
                        <contact>
                            <ode/>
                        </contact>
                        <bounce/>
                        <friction>
                            <ode/>
                        </friction>
                    </surface>
                </collision>
                <visual name='Wall_9_Visual'>
                    <pose>0 0 1.25 0 -0 0</pose>
                    <geometry>
                        <box>
                            <size>22.75 0.15 2.5</size>
                        </box>
                    </geometry>
                    <material>
                        <script>
                            <uri>file://media/materials/scripts/gazebo.material</uri>
                            <name>Gazebo/Bricks</name>
                        </script>
                        <ambient>0.760784 0.662745 0.627451 1</ambient>
                    </material>
                </visual>
                <pose>-26.1137 -1.12682 0 0 0 -1.5708</pose>
                <self_collide>0</self_collide>
                <kinematic>0</kinematic>
                <gravity>1</gravity>
            </link>
            <link name='Wall_91'>
                <collision name='Wall_91_Collision'>
                    <geometry>
                        <box>
                            <size>6.77035 0.15 2.5</size>
                        </box>
                    </geometry>
                    <pose>0 0 1.25 0 -0 0</pose>
                    <max_contacts>10</max_contacts>
                    <surface>
                        <contact>
                            <ode/>
                        </contact>
                        <bounce/>
                        <friction>
                            <ode/>
                        </friction>
                    </surface>
                </collision>
                <visual name='Wall_91_Visual'>
                    <pose>0 0 1.25 0 -0 0</pose>
                    <geometry>
                        <box>
                            <size>6.77035 0.15 2.5</size>
                        </box>
                    </geometry>
                    <material>
                        <script>
                            <uri>file://media/materials/scripts/gazebo.material</uri>
                            <name>Gazebo/Bricks</name>
                        </script>
                        <ambient>0.760784 0.662745 0.627451 1</ambient>
                    </material>
                </visual>
                <pose>16.0913 -8.17085 0 0 -0 0</pose>
                <self_collide>0</self_collide>
                <kinematic>0</kinematic>
                <gravity>1</gravity>
            </link>
            <link name='Wall_92'>
                <collision name='Wall_92_Collision'>
                    <geometry>
                        <box>
                            <size>5.05478 0.15 2.5</size>
                        </box>
                    </geometry>
                    <pose>0 0 1.25 0 -0 0</pose>
                    <max_contacts>10</max_contacts>
                    <surface>
                        <contact>
                            <ode/>
                        </contact>
                        <bounce/>
                        <friction>
                            <ode/>
                        </friction>
                    </surface>
                </collision>
                <visual name='Wall_92_Visual'>
                    <pose>0 0 1.25 0 -0 0</pose>
                    <geometry>
                        <box>
                            <size>5.05478 0.15 2.5</size>
                        </box>
                    </geometry>
                    <material>
                        <script>
                            <uri>file://media/materials/scripts/gazebo.material</uri>
                            <name>Gazebo/Bricks</name>
                        </script>
                        <ambient>0.760784 0.662745 0.627451 1</ambient>
                    </material>
                </visual>
                <pose>20.6368 -10.2892 0 0 0 -1.04272</pose>
                <self_collide>0</self_collide>
                <kinematic>0</kinematic>
                <gravity>1</gravity>
            </link>
            <static>1</static>
        </model>
        <model name='youbot'>
            <pose>-21.417 8 0.09 0 -0 0</pose>
            <link name='base_footprint'>
                <pose>0 0 0 0 -0 0</pose>
                <inertial>
                    <pose>0 0 -0.05 0 -0 0</pose>
                    <inertia>
                        <ixx>1</ixx>
                        <ixy>0</ixy>
                        <ixz>0</ixz>
                        <iyy>1</iyy>
                        <iyz>0</iyz>
                        <izz>1</izz>
                    </inertia>
                    <mass>0.1</mass>
                </inertial>
                <collision name='base_footprint_geom'>
                    <pose>0 0 -0.05 0 -0 0</pose>
                    <geometry>
                        <box>
                            <size>0.001 0.001 0.001</size>
                        </box>
                    </geometry>
                    <surface>
                        <friction>
                            <ode>
                                <mu>1</mu>
                                <mu2>1</mu2>
                                <fdir1>0 0 0</fdir1>
                                <slip1>0</slip1>
                                <slip2>0</slip2>
                            </ode>
                        </friction>
                        <bounce>
                            <restitution_coefficient>0</restitution_coefficient>
                            <threshold>0</threshold>
                        </bounce>
                        <contact>
                            <ode>
                                <soft_cfm>0</soft_cfm>
                                <soft_erp>0.2</soft_erp>
                                <kp>1e+13</kp>
                                <kd>1e+11</kd>
                                <max_vel>-1</max_vel>
                                <min_depth>0</min_depth>
                            </ode>
                        </contact>
                    </surface>
                    <laser_retro>0</laser_retro>
                    <max_contacts>10</max_contacts>
                </collision>
                <visual name='base_footprint_geom_visual'>
                    <pose>0 0 0 0 -0 0</pose>
                    <geometry>
                        <box>
                            <size>0.001 0.001 0.001</size>
                        </box>
                    </geometry>
                </visual>
                <gravity>1</gravity>
                <self_collide>0</self_collide>
                <kinematic>0</kinematic>
            </link>
            <link name='base_link'>
                <pose>0 0 0 0 -0 0</pose>
                <inertial>
                    <pose>0 0 0 0 -0 0</pose>
                    <inertia>
                        <ixx>5.65223</ixx>
                        <ixy>-0.00972</ixy>
                        <ixz>1.29399</ixz>
                        <iyy>5.66947</iyy>
                        <iyz>-0.00738</iyz>
                        <izz>3.6832</izz>
                    </inertia>
                    <mass>22</mass>
                </inertial>
                <collision name='base_link_geom'>
                    <pose>0 0 0 0 -0 0</pose>
                    <geometry>
                        <mesh>
                            <uri>model://youbot/meshes/base/base_convex.stl</uri>
                        </mesh>
                    </geometry>
                    <surface>
                        <friction>
                            <ode>
                                <mu>1</mu>
                                <mu2>1</mu2>
                                <fdir1>0 0 0</fdir1>
                                <slip1>0</slip1>
                                <slip2>0</slip2>
                            </ode>
                        </friction>
                        <bounce>
                            <restitution_coefficient>0</restitution_coefficient>
                            <threshold>0</threshold>
                        </bounce>
                        <contact>
                            <ode>
                                <soft_cfm>0</soft_cfm>
                                <soft_erp>0.2</soft_erp>
                                <kp>1e+13</kp>
                                <kd>1e+11</kd>
                                <max_vel>-1</max_vel>
                                <min_depth>0</min_depth>
                            </ode>
                        </contact>
                    </surface>
                    <laser_retro>0</laser_retro>
                    <max_contacts>10</max_contacts>
                </collision>
                <visual name='base_link_geom_visual'>
                    <pose>0 0 0 0 -0 0</pose>
                    <geometry>
                        <mesh>
                            <uri>model://youbot/meshes/base/base.dae</uri>
                        </mesh>
                    </geometry>
                </visual>
                <gravity>1</gravity>
                <self_collide>0</self_collide>
                <kinematic>0</kinematic>
            </link>
            <link name='arm_link_0'>
                <pose>0.143 0 0.046 0 -0 0</pose>
                <inertial>
                    <pose>0 0 0 0 -0 0</pose>
                    <inertia>
                        <ixx>0.01</ixx>
                        <ixy>0</ixy>
                        <ixz>0</ixz>
                        <iyy>0.01</iyy>
                        <iyz>0</iyz>
                        <izz>0.01</izz>
                    </inertia>
                    <mass>0.845</mass>
                </inertial>
                <collision name='arm_link_0_geom'>
                    <pose>0 0 0 0 -0 0</pose>
                    <geometry>
                        <mesh>
                            <uri>model://youbot/meshes/arm/arm0_convex.stl</uri>
                        </mesh>
                    </geometry>
                    <surface>
                        <friction>
                            <ode>
                                <mu>1</mu>
                                <mu2>1</mu2>
                                <fdir1>0 0 0</fdir1>
                                <slip1>0</slip1>
                                <slip2>0</slip2>
                            </ode>
                        </friction>
                        <bounce>
                            <restitution_coefficient>0</restitution_coefficient>
                            <threshold>0</threshold>
                        </bounce>
                        <contact>
                            <ode>
                                <soft_cfm>0</soft_cfm>
                                <soft_erp>0.2</soft_erp>
                                <kp>1e+13</kp>
                                <kd>1e+11</kd>
                                <max_vel>-1</max_vel>
                                <min_depth>0</min_depth>
                            </ode>
                        </contact>
                    </surface>
                    <laser_retro>0</laser_retro>
                    <max_contacts>10</max_contacts>
                </collision>
                <visual name='arm_link_0_geom_visual'>
                    <pose>0 0 0 0 -0 0</pose>
                    <geometry>
                        <mesh>
                            <uri>model://youbot/meshes/arm/arm0.dae</uri>
                        </mesh>
                    </geometry>
                    <material>
                        <script>
                            <uri>model://youbot/materials/scripts/youbot.material</uri>
                            <name>youbot/DarkGrey</name>
                        </script>
                    </material>
                </visual>
                <gravity>1</gravity>
                <self_collide>0</self_collide>
                <kinematic>0</kinematic>
            </link>
            <link name='arm_link_1'>
                <pose>0.167 0 0.142 0 -0 2.96706</pose>
                <inertial>
                    <pose>0.01489 0.00213 0.00213 0 -0 0</pose>
                    <inertia>
                        <ixx>0.003863</ixx>
                        <ixy>-0.000979</ixy>
                        <ixz>0</ixz>
                        <iyy>0.006196</iyy>
                        <iyz>0</iyz>
                        <izz>0.006369</izz>
                    </inertia>
                    <mass>2.412</mass>
                </inertial>
                <collision name='arm_link_1_geom'>
                    <pose>0 0 0 0 -0 0</pose>
                    <geometry>
                        <mesh>
                            <uri>model://youbot/meshes/arm/arm1_convex.stl</uri>
                        </mesh>
                    </geometry>
                    <surface>
                        <friction>
                            <ode>
                                <mu>1</mu>
                                <mu2>1</mu2>
                                <fdir1>0 0 0</fdir1>
                                <slip1>0</slip1>
                                <slip2>0</slip2>
                            </ode>
                        </friction>
                        <bounce>
                            <restitution_coefficient>0</restitution_coefficient>
                            <threshold>0</threshold>
                        </bounce>
                        <contact>
                            <ode>
                                <soft_cfm>0</soft_cfm>
                                <soft_erp>0.2</soft_erp>
                                <kp>1e+13</kp>
                                <kd>1e+11</kd>
                                <max_vel>-1</max_vel>
                                <min_depth>0</min_depth>
                            </ode>
                        </contact>
                    </surface>
                    <laser_retro>0</laser_retro>
                    <max_contacts>10</max_contacts>
                </collision>
                <visual name='arm_link_1_geom_visual'>
                    <pose>0 0 0 0 -0 0</pose>
                    <geometry>
                        <mesh>
                            <uri>model://youbot/meshes/arm/arm1.dae</uri>
                        </mesh>
                    </geometry>
                </visual>
                <gravity>1</gravity>
                <self_collide>0</self_collide>
                <kinematic>0</kinematic>
            </link>
            <link name='arm_link_2'>
                <pose>0.134501 0.00573 0.161 1.31349e-16 -1.13446 2.96706</pose>
                <inertial>
                    <pose>0.10453 0.0017 -0.00297 0 -0 0</pose>
                    <inertia>
                        <ixx>0.000823</ixx>
                        <ixy>0</ixy>
                        <ixz>-0</ixz>
                        <iyy>0.004447</iyy>
                        <iyz>0</iyz>
                        <izz>0.004439</izz>
                    </inertia>
                    <mass>1.155</mass>
                </inertial>
                <collision name='arm_link_2_geom'>
                    <pose>0 -0.032 0.078 0 -0 0</pose>
                    <geometry>
                        <mesh>
                            <uri>model://youbot/meshes/arm/arm2_convex.stl</uri>
                        </mesh>
                    </geometry>
                    <surface>
                        <friction>
                            <ode>
                                <mu>1</mu>
                                <mu2>1</mu2>
                                <fdir1>0 0 0</fdir1>
                                <slip1>0</slip1>
                                <slip2>0</slip2>
                            </ode>
                        </friction>
                        <bounce>
                            <restitution_coefficient>0</restitution_coefficient>
                            <threshold>0</threshold>
                        </bounce>
                        <contact>
                            <ode>
                                <soft_cfm>0</soft_cfm>
                                <soft_erp>0.2</soft_erp>
                                <kp>1e+13</kp>
                                <kd>1e+11</kd>
                                <max_vel>-1</max_vel>
                                <min_depth>0</min_depth>
                            </ode>
                        </contact>
                    </surface>
                    <laser_retro>0</laser_retro>
                    <max_contacts>10</max_contacts>
                </collision>
                <visual name='arm_link_2_geom_visual'>
                    <pose>0 -0.032 0.078 0 -0 0</pose>
                    <geometry>
                        <mesh>
                            <uri>model://youbot/meshes/arm/arm2.dae</uri>
                        </mesh>
                    </geometry>
                </visual>
                <gravity>1</gravity>
                <self_collide>0</self_collide>
                <kinematic>0</kinematic>
            </link>
            <link name='arm_link_3'>
                <pose>0.272845 -0.018663 0.226506 -8.8715e-16 1.41372 2.96706</pose>
                <inertial>
                    <pose>0.0001 0.0967 0.02107 0 -0 0</pose>
                    <inertia>
                        <ixx>0.002459</ixx>
                        <ixy>0</ixy>
                        <ixz>0</ixz>
                        <iyy>0.002571</iyy>
                        <iyz>-0</iyz>
                        <izz>0.000535</izz>
                    </inertia>
                    <mass>0.934</mass>
                </inertial>
                <collision name='arm_link_3_geom'>
                    <pose>0 0.028 0.079 0 -0 0</pose>
                    <geometry>
                        <mesh>
                            <uri>model://youbot/meshes/arm/arm3_convex.stl</uri>
                        </mesh>
                    </geometry>
                    <surface>
                        <friction>
                            <ode>
                                <mu>1</mu>
                                <mu2>1</mu2>
                                <fdir1>0 0 0</fdir1>
                                <slip1>0</slip1>
                                <slip2>0</slip2>
                            </ode>
                        </friction>
                        <bounce>
                            <restitution_coefficient>0</restitution_coefficient>
                            <threshold>0</threshold>
                        </bounce>
                        <contact>
                            <ode>
                                <soft_cfm>0</soft_cfm>
                                <soft_erp>0.2</soft_erp>
                                <kp>1e+13</kp>
                                <kd>1e+11</kd>
                                <max_vel>-1</max_vel>
                                <min_depth>0</min_depth>
                            </ode>
                        </contact>
                    </surface>
                    <laser_retro>0</laser_retro>
                    <max_contacts>10</max_contacts>
                </collision>
                <visual name='arm_link_3_geom_visual'>
                    <pose>0 0.028 0.079 0 -0 0</pose>
                    <geometry>
                        <mesh>
                            <uri>model://youbot/meshes/arm/arm3.dae</uri>
                        </mesh>
                    </geometry>
                </visual>
                <gravity>1</gravity>
                <self_collide>0</self_collide>
                <kinematic>0</kinematic>
            </link>
            <link name='arm_link_4'>
                <pose>0.141533 0.004491 0.247624 0 -0.375246 2.96706</pose>
                <inertial>
                    <pose>0.00011 0.05103 -0.02319 0 -0 0</pose>
                    <inertia>
                        <ixx>0.000869</ixx>
                        <ixy>0</ixy>
                        <ixz>-0</ixz>
                        <iyy>0.001173</iyy>
                        <iyz>-0.000231</iyz>
                        <izz>0.001091</izz>
                    </inertia>
                    <mass>0.877</mass>
                </inertial>
                <collision name='arm_link_4_geom'>
                    <pose>0 -0.01 0.029 0 -0 0</pose>
                    <geometry>
                        <mesh>
                            <uri>model://youbot/meshes/arm/arm4_convex.stl</uri>
                        </mesh>
                    </geometry>
                    <surface>
                        <friction>
                            <ode>
                                <mu>1</mu>
                                <mu2>1</mu2>
                                <fdir1>0 0 0</fdir1>
                                <slip1>0</slip1>
                                <slip2>0</slip2>
                            </ode>
                        </friction>
                        <bounce>
                            <restitution_coefficient>0</restitution_coefficient>
                            <threshold>0</threshold>
                        </bounce>
                        <contact>
                            <ode>
                                <soft_cfm>0</soft_cfm>
                                <soft_erp>0.2</soft_erp>
                                <kp>1e+13</kp>
                                <kd>1e+11</kd>
                                <max_vel>-1</max_vel>
                                <min_depth>0</min_depth>
                            </ode>
                        </contact>
                    </surface>
                    <laser_retro>0</laser_retro>
                    <max_contacts>10</max_contacts>
                </collision>
                <visual name='arm_link_4_geom_visual'>
                    <pose>0 -0.01 0.029 0 -0 0</pose>
                    <geometry>
                        <mesh>
                            <uri>model://youbot/meshes/arm/arm4.dae</uri>
                        </mesh>
                    </geometry>
                </visual>
                <gravity>1</gravity>
                <self_collide>0</self_collide>
                <kinematic>0</kinematic>
            </link>
            <link name='arm_link_5'>
                <pose>0.190287 -0.004106 0.367846 -0.085052 0.365926 -0.408445</pose>
                <inertial>
                    <pose>0 0.00115 -0.01683 0 -0 0</pose>
                    <inertia>
                        <ixx>0.00028</ixx>
                        <ixy>0</ixy>
                        <ixz>0</ixz>
                        <iyy>0.000339</iyy>
                        <iyz>0</iyz>
                        <izz>0.000119</izz>
                    </inertia>
                    <mass>0.251</mass>
                </inertial>
                <collision name='arm_link_5_geom'>
                    <pose>0.003 0 -0.034 0 -0 0</pose>
                    <geometry>
                        <mesh>
                            <uri>model://youbot/meshes/arm/arm5_convex.stl</uri>
                        </mesh>
                    </geometry>
                    <surface>
                        <friction>
                            <ode>
                                <mu>1</mu>
                                <mu2>1</mu2>
                                <fdir1>0 0 0</fdir1>
                                <slip1>0</slip1>
                                <slip2>0</slip2>
                            </ode>
                        </friction>
                        <bounce>
                            <restitution_coefficient>0</restitution_coefficient>
                            <threshold>0</threshold>
                        </bounce>
                        <contact>
                            <ode>
                                <soft_cfm>0</soft_cfm>
                                <soft_erp>0.2</soft_erp>
                                <kp>1e+13</kp>
                                <kd>1e+11</kd>
                                <max_vel>-1</max_vel>
                                <min_depth>0</min_depth>
                            </ode>
                        </contact>
                    </surface>
                    <laser_retro>0</laser_retro>
                    <max_contacts>10</max_contacts>
                </collision>
                <visual name='arm_link_5_geom_visual'>
                    <pose>0.003 0 -0.034 0 -0 0</pose>
                    <geometry>
                        <mesh>
                            <uri>model://youbot/meshes/arm/arm5.dae</uri>
                        </mesh>
                    </geometry>
                </visual>
                <gravity>1</gravity>
                <self_collide>0</self_collide>
                <kinematic>0</kinematic>
            </link>
            <link name='gripper_palm_link'>
                <pose>0.190287 -0.004106 0.367846 -0.085052 0.365926 -0.408445</pose>
                <inertial>
                    <pose>0 0 0 0 -0 0</pose>
                    <inertia>
                        <ixx>0.01</ixx>
                        <ixy>0</ixy>
                        <ixz>0</ixz>
                        <iyy>0.01</iyy>
                        <iyz>0</iyz>
                        <izz>0.01</izz>
                    </inertia>
                    <mass>0.1</mass>
                </inertial>
                <collision name='gripper_palm_link_geom'>
                    <pose>0 0 0 0 -0 0</pose>
                    <geometry>
                        <mesh>
                            <uri>model://youbot/meshes/gripper/palm_convex.stl</uri>
                        </mesh>
                    </geometry>
                    <surface>
                        <friction>
                            <ode>
                                <mu>1</mu>
                                <mu2>1</mu2>
                                <fdir1>0 0 0</fdir1>
                                <slip1>0</slip1>
                                <slip2>0</slip2>
                            </ode>
                        </friction>
                        <bounce>
                            <restitution_coefficient>0</restitution_coefficient>
                            <threshold>0</threshold>
                        </bounce>
                        <contact>
                            <ode>
                                <soft_cfm>0</soft_cfm>
                                <soft_erp>0.2</soft_erp>
                                <kp>1e+13</kp>
                                <kd>1e+11</kd>
                                <max_vel>-1</max_vel>
                                <min_depth>0</min_depth>
                            </ode>
                        </contact>
                    </surface>
                    <laser_retro>0</laser_retro>
                    <max_contacts>10</max_contacts>
                </collision>
                <visual name='gripper_palm_link_geom_visual'>
                    <pose>0 0 0 0 -0 0</pose>
                    <geometry>
                        <mesh>
                            <uri>model://youbot/meshes/gripper/palm.stl</uri>
                        </mesh>
                    </geometry>
                    <material>
                        <script>
                            <uri>file://media/materials/scripts/gazebo.material</uri>
                            <name>Gazebo/Black</name>
                        </script>
                    </material>
                </visual>
                <gravity>1</gravity>
                <self_collide>1</self_collide>
                <kinematic>0</kinematic>
            </link>
            <link name='gripper_finger_link_l'>
                <pose>0.21326 -0.001105 0.408579 0.085052 -0.365926 2.73315</pose>
                <inertial>
                    <pose>0 -0.001 0 0 -0 0</pose>
                    <inertia>
                        <ixx>0.01</ixx>
                        <ixy>0</ixy>
                        <ixz>0</ixz>
                        <iyy>0.01</iyy>
                        <iyz>0</iyz>
                        <izz>0.01</izz>
                    </inertia>
                    <mass>0.01</mass>
                </inertial>
                <collision name='gripper_finger_link_l_geom'>
                    <pose>0 0 0 0 -0 0</pose>
                    <geometry>
                        <mesh>
                            <uri>model://youbot/meshes/gripper/finger_convex.stl</uri>
                        </mesh>
                    </geometry>
                    <surface>
                        <friction>
                            <ode>
                                <mu>1</mu>
                                <mu2>1</mu2>
                                <fdir1>0 0 0</fdir1>
                                <slip1>0</slip1>
                                <slip2>0</slip2>
                            </ode>
                        </friction>
                        <bounce>
                            <restitution_coefficient>0</restitution_coefficient>
                            <threshold>0</threshold>
                        </bounce>
                        <contact>
                            <ode>
                                <soft_cfm>0</soft_cfm>
                                <soft_erp>0.2</soft_erp>
                                <kp>1e+13</kp>
                                <kd>1e+11</kd>
                                <max_vel>-1</max_vel>
                                <min_depth>0</min_depth>
                            </ode>
                        </contact>
                    </surface>
                    <laser_retro>0</laser_retro>
                    <max_contacts>10</max_contacts>
                </collision>
                <visual name='gripper_finger_link_l_geom_visual'>
                    <pose>0 0 0 0 -0 0</pose>
                    <geometry>
                        <mesh>
                            <uri>model://youbot/meshes/gripper/finger.stl</uri>
                        </mesh>
                    </geometry>
                </visual>
                <gravity>1</gravity>
                <self_collide>0</self_collide>
                <kinematic>0</kinematic>
            </link>
            <link name='gripper_finger_link_r'>
                <pose>0.207375 -0.015929 0.409848 -0.085052 0.365926 -0.408445</pose>
                <inertial>
                    <pose>0 -0.001 0 0 -0 0</pose>
                    <inertia>
                        <ixx>0.01</ixx>
                        <ixy>0</ixy>
                        <ixz>0</ixz>
                        <iyy>0.01</iyy>
                        <iyz>0</iyz>
                        <izz>0.01</izz>
                    </inertia>
                    <mass>0.01</mass>
                </inertial>
                <collision name='gripper_finger_link_r_geom'>
                    <pose>0 0 0 0 -0 0</pose>
                    <geometry>
                        <mesh>
                            <uri>model://youbot/meshes/gripper/finger_convex.stl</uri>
                        </mesh>
                    </geometry>
                    <surface>
                        <friction>
                            <ode>
                                <mu>1</mu>
                                <mu2>1</mu2>
                                <fdir1>0 0 0</fdir1>
                                <slip1>0</slip1>
                                <slip2>0</slip2>
                            </ode>
                        </friction>
                        <bounce>
                            <restitution_coefficient>0</restitution_coefficient>
                            <threshold>0</threshold>
                        </bounce>
                        <contact>
                            <ode>
                                <soft_cfm>0</soft_cfm>
                                <soft_erp>0.2</soft_erp>
                                <kp>1e+13</kp>
                                <kd>1e+11</kd>
                                <max_vel>-1</max_vel>
                                <min_depth>0</min_depth>
                            </ode>
                        </contact>
                    </surface>
                    <laser_retro>0</laser_retro>
                    <max_contacts>10</max_contacts>
                </collision>
                <visual name='gripper_finger_link_r_geom_visual'>
                    <pose>0 0 0 0 -0 0</pose>
                    <geometry>
                        <mesh>
                            <uri>model://youbot/meshes/gripper/finger.stl</uri>
                        </mesh>
                    </geometry>
                </visual>
                <gravity>1</gravity>
                <self_collide>0</self_collide>
                <kinematic>0</kinematic>
            </link>
            <link name='base_laser_front_link'>
                <pose>0.3 0 -0.03 0 -0 0</pose>
                <inertial>
                    <pose>0 0 0 0 -0 0</pose>
                    <inertia>
                        <ixx>0.1</ixx>
                        <ixy>0</ixy>
                        <ixz>0</ixz>
                        <iyy>0.1</iyy>
                        <iyz>0</iyz>
                        <izz>0.1</izz>
                    </inertia>
                    <mass>0.16</mass>
                </inertial>
                <collision name='base_laser_front_link_geom'>
                    <pose>0 0 0 0 -0 0</pose>
                    <geometry>
                        <mesh>
                            <uri>model://hokuyo/meshes/hokuyo_convex.stl</uri>
                        </mesh>
                    </geometry>
                    <surface>
                        <friction>
                            <ode>
                                <mu>1</mu>
                                <mu2>1</mu2>
                                <fdir1>0 0 0</fdir1>
                                <slip1>0</slip1>
                                <slip2>0</slip2>
                            </ode>
                        </friction>
                        <bounce>
                            <restitution_coefficient>0</restitution_coefficient>
                            <threshold>0</threshold>
                        </bounce>
                        <contact>
                            <ode>
                                <soft_cfm>0</soft_cfm>
                                <soft_erp>0.2</soft_erp>
                                <kp>1e+13</kp>
                                <kd>1e+11</kd>
                                <max_vel>-1</max_vel>
                                <min_depth>0</min_depth>
                            </ode>
                        </contact>
                    </surface>
                    <laser_retro>0</laser_retro>
                    <max_contacts>10</max_contacts>
                </collision>
                <visual name='base_laser_front_link_geom_visual'>
                    <pose>0 0 0 0 -0 0</pose>
                    <geometry>
                        <mesh>
                            <uri>model://hokuyo/meshes/hokuyo.dae</uri>
                        </mesh>
                    </geometry>
                </visual>
                <sensor name='base_laser_front' type='ray'>
                    <plugin name="gazebo_rayscan_sensor_plugin" filename="librayscan.so"/>
                    <pose>0 0 0 0 -0 0</pose>
                    <ray>
                        <scan>
                            <horizontal>
                                <samples>640</samples>
                                <resolution>1</resolution>
                                <min_angle>-1.57</min_angle>
                                <max_angle>1.57</max_angle>
                            </horizontal>
                        </scan>
                        <range>
                            <min>0.05</min>
                            <max>5.6</max>
                            <resolution>0.36</resolution>
                        </range>
                    </ray>
                    <always_on>0</always_on>
                    <update_rate>10</update_rate>
                    <visualize>0</visualize>
                </sensor>
                <gravity>1</gravity>
                <self_collide>0</self_collide>
                <kinematic>0</kinematic>
            </link>
            <link name='caster_link_bl'>
                <pose>-0.228 0.158 -0.034 0 -0 0</pose>
                <inertial>
                    <pose>0 0 0 0 -0 0</pose>
                    <inertia>
                        <ixx>0.012412</ixx>
                        <ixy>-0.000712</ixy>
                        <ixz>0.000503</ixz>
                        <iyy>0.015218</iyy>
                        <iyz>-4e-06</iyz>
                        <izz>0.011764</izz>
                    </inertia>
                    <mass>0.1</mass>
                </inertial>
                <gravity>1</gravity>
                <self_collide>0</self_collide>
                <kinematic>0</kinematic>
            </link>
            <link name='wheel_link_bl'>
                <pose>-0.228 0.158 -0.034 0 -0 0</pose>
                <inertial>
                    <pose>0 0 0 0 -0 0</pose>
                    <inertia>
                        <ixx>0.012412</ixx>
                        <ixy>-0.000712</ixy>
                        <ixz>0.000503</ixz>
                        <iyy>0.015218</iyy>
                        <iyz>-4e-06</iyz>
                        <izz>0.011764</izz>
                    </inertia>
                    <mass>0.4</mass>
                </inertial>
                <collision name='wheel_link_bl_geom'>
                    <pose>0 0 0 1.5708 -0 0</pose>
                    <geometry>
                        <cylinder>
                            <radius>0.05</radius>
                            <length>0.005</length>
                        </cylinder>
                    </geometry>
                    <surface>
                        <friction>
                            <ode>
                                <mu>1</mu>
                                <mu2>1</mu2>
                                <fdir1>0 0 0</fdir1>
                                <slip1>0</slip1>
                                <slip2>0</slip2>
                            </ode>
                        </friction>
                        <bounce>
                            <restitution_coefficient>0</restitution_coefficient>
                            <threshold>0</threshold>
                        </bounce>
                        <contact>
                            <ode>
                                <soft_cfm>0</soft_cfm>
                                <soft_erp>0.2</soft_erp>
                                <kp>1e+13</kp>
                                <kd>1e+11</kd>
                                <max_vel>-1</max_vel>
                                <min_depth>0</min_depth>
                            </ode>
                        </contact>
                    </surface>
                    <laser_retro>0</laser_retro>
                    <max_contacts>10</max_contacts>
                </collision>
                <visual name='wheel_link_bl_geom_visual'>
                    <pose>0 0 0 0 -0 0</pose>
                    <geometry>
                        <mesh>
                            <uri>model://youbot/meshes/base/back-left_wheel.dae</uri>
                        </mesh>
                    </geometry>
                    <material>
                        <script>
                            <uri>model://youbot/materials/scripts/youbot.material</uri>
                            <name>youbot/Orange</name>
                        </script>
                    </material>
                </visual>
                <gravity>1</gravity>
                <self_collide>0</self_collide>
                <kinematic>0</kinematic>
            </link>
            <link name='caster_link_br'>
                <pose>-0.228 -0.158 -0.034 0 -0 0</pose>
                <inertial>
                    <pose>0 0 0 0 -0 0</pose>
                    <inertia>
                        <ixx>0.012412</ixx>
                        <ixy>-0.000712</ixy>
                        <ixz>0.000503</ixz>
                        <iyy>0.015218</iyy>
                        <iyz>-4e-06</iyz>
                        <izz>0.011764</izz>
                    </inertia>
                    <mass>0.1</mass>
                </inertial>
                <gravity>1</gravity>
                <self_collide>0</self_collide>
                <kinematic>0</kinematic>
            </link>
            <link name='wheel_link_br'>
                <pose>-0.228 -0.158 -0.034 0 -0 0</pose>
                <inertial>
                    <pose>0 0 0 0 -0 0</pose>
                    <inertia>
                        <ixx>0.012412</ixx>
                        <ixy>-0.000712</ixy>
                        <ixz>0.000503</ixz>
                        <iyy>0.015218</iyy>
                        <iyz>-4e-06</iyz>
                        <izz>0.011764</izz>
                    </inertia>
                    <mass>0.4</mass>
                </inertial>
                <collision name='wheel_link_br_geom'>
                    <pose>0 0 0 1.5708 -0 0</pose>
                    <geometry>
                        <cylinder>
                            <radius>0.05</radius>
                            <length>0.005</length>
                        </cylinder>
                    </geometry>
                    <surface>
                        <friction>
                            <ode>
                                <mu>1</mu>
                                <mu2>1</mu2>
                                <fdir1>0 0 0</fdir1>
                                <slip1>0</slip1>
                                <slip2>0</slip2>
                            </ode>
                        </friction>
                        <bounce>
                            <restitution_coefficient>0</restitution_coefficient>
                            <threshold>0</threshold>
                        </bounce>
                        <contact>
                            <ode>
                                <soft_cfm>0</soft_cfm>
                                <soft_erp>0.2</soft_erp>
                                <kp>1e+13</kp>
                                <kd>1e+11</kd>
                                <max_vel>-1</max_vel>
                                <min_depth>0</min_depth>
                            </ode>
                        </contact>
                    </surface>
                    <laser_retro>0</laser_retro>
                    <max_contacts>10</max_contacts>
                </collision>
                <visual name='wheel_link_br_geom_visual'>
                    <pose>0 0 0 0 -0 0</pose>
                    <geometry>
                        <mesh>
                            <uri>model://youbot/meshes/base/back-right_wheel.dae</uri>
                        </mesh>
                    </geometry>
                    <material>
                        <script>
                            <uri>model://youbot/materials/scripts/youbot.material</uri>
                            <name>youbot/Orange</name>
                        </script>
                    </material>
                </visual>
                <gravity>1</gravity>
                <self_collide>0</self_collide>
                <kinematic>0</kinematic>
            </link>
            <link name='caster_link_fl'>
                <pose>0.228 0.158 -0.034 0 -0 0</pose>
                <inertial>
                    <pose>0 0 0 0 -0 0</pose>
                    <inertia>
                        <ixx>0.012412</ixx>
                        <ixy>-0.000712</ixy>
                        <ixz>0.000503</ixz>
                        <iyy>0.015218</iyy>
                        <iyz>-4e-06</iyz>
                        <izz>0.011764</izz>
                    </inertia>
                    <mass>0.1</mass>
                </inertial>
                <gravity>1</gravity>
                <self_collide>0</self_collide>
                <kinematic>0</kinematic>
            </link>
            <link name='wheel_link_fl'>
                <pose>0.228 0.158 -0.034 0 -0 0</pose>
                <inertial>
                    <pose>0 0 0 0 -0 0</pose>
                    <inertia>
                        <ixx>0.012412</ixx>
                        <ixy>-0.000712</ixy>
                        <ixz>0.000503</ixz>
                        <iyy>0.015218</iyy>
                        <iyz>-4e-06</iyz>
                        <izz>0.011764</izz>
                    </inertia>
                    <mass>0.4</mass>
                </inertial>
                <collision name='wheel_link_fl_geom'>
                    <pose>0 0 0 1.5708 -0 0</pose>
                    <geometry>
                        <cylinder>
                            <radius>0.05</radius>
                            <length>0.005</length>
                        </cylinder>
                    </geometry>
                    <surface>
                        <friction>
                            <ode>
                                <mu>1</mu>
                                <mu2>1</mu2>
                                <fdir1>0 0 0</fdir1>
                                <slip1>0</slip1>
                                <slip2>0</slip2>
                            </ode>
                        </friction>
                        <bounce>
                            <restitution_coefficient>0</restitution_coefficient>
                            <threshold>0</threshold>
                        </bounce>
                        <contact>
                            <ode>
                                <soft_cfm>0</soft_cfm>
                                <soft_erp>0.2</soft_erp>
                                <kp>1e+13</kp>
                                <kd>1e+11</kd>
                                <max_vel>-1</max_vel>
                                <min_depth>0</min_depth>
                            </ode>
                        </contact>
                    </surface>
                    <laser_retro>0</laser_retro>
                    <max_contacts>10</max_contacts>
                </collision>
                <visual name='wheel_link_fl_geom_visual'>
                    <pose>0 0 0 0 -0 0</pose>
                    <geometry>
                        <mesh>
                            <uri>model://youbot/meshes/base/front-left_wheel.dae</uri>
                        </mesh>
                    </geometry>
                    <material>
                        <script>
                            <uri>model://youbot/materials/scripts/youbot.material</uri>
                            <name>youbot/Orange</name>
                        </script>
                    </material>
                </visual>
                <gravity>1</gravity>
                <self_collide>0</self_collide>
                <kinematic>0</kinematic>
            </link>
            <link name='caster_link_fr'>
                <pose>0.228 -0.158 -0.034 0 -0 0</pose>
                <inertial>
                    <pose>0 0 0 0 -0 0</pose>
                    <inertia>
                        <ixx>0.012412</ixx>
                        <ixy>-0.000712</ixy>
                        <ixz>0.000503</ixz>
                        <iyy>0.015218</iyy>
                        <iyz>-4e-06</iyz>
                        <izz>0.011764</izz>
                    </inertia>
                    <mass>0.1</mass>
                </inertial>
                <gravity>1</gravity>
                <self_collide>0</self_collide>
                <kinematic>0</kinematic>
            </link>
            <link name='wheel_link_fr'>
                <pose>0.228 -0.158 -0.034 0 -0 0</pose>
                <inertial>
                    <pose>0 0 0 0 -0 0</pose>
                    <inertia>
                        <ixx>0.012412</ixx>
                        <ixy>-0.000712</ixy>
                        <ixz>0.000503</ixz>
                        <iyy>0.015218</iyy>
                        <iyz>-4e-06</iyz>
                        <izz>0.011764</izz>
                    </inertia>
                    <mass>0.4</mass>
                </inertial>
                <collision name='wheel_link_fr_geom'>
                    <pose>0 0 0 1.5708 -0 0</pose>
                    <geometry>
                        <cylinder>
                            <radius>0.05</radius>
                            <length>0.005</length>
                        </cylinder>
                    </geometry>
                    <surface>
                        <friction>
                            <ode>
                                <mu>1</mu>
                                <mu2>1</mu2>
                                <fdir1>0 0 0</fdir1>
                                <slip1>0</slip1>
                                <slip2>0</slip2>
                            </ode>
                        </friction>
                        <bounce>
                            <restitution_coefficient>0</restitution_coefficient>
                            <threshold>0</threshold>
                        </bounce>
                        <contact>
                            <ode>
                                <soft_cfm>0</soft_cfm>
                                <soft_erp>0.2</soft_erp>
                                <kp>1e+13</kp>
                                <kd>1e+11</kd>
                                <max_vel>-1</max_vel>
                                <min_depth>0</min_depth>
                            </ode>
                        </contact>
                    </surface>
                    <laser_retro>0</laser_retro>
                    <max_contacts>10</max_contacts>
                </collision>
                <visual name='wheel_link_fr_geom_visual'>
                    <pose>0 0 0 0 -0 0</pose>
                    <geometry>
                        <mesh>
                            <uri>model://youbot/meshes/base/front-right_wheel.dae</uri>
                        </mesh>
                    </geometry>
                    <material>
                        <script>
                            <uri>model://youbot/materials/scripts/youbot.material</uri>
                            <name>youbot/Orange</name>
                        </script>
                    </material>
                </visual>
                <gravity>1</gravity>
                <self_collide>0</self_collide>
                <kinematic>0</kinematic>
            </link>
            <link name='plate_link'>
                <pose>-0.159 0 0.046 0 -0 0</pose>
                <inertial>
                    <pose>0 0 0 0 -0 0</pose>
                    <inertia>
                        <ixx>0.01</ixx>
                        <ixy>0</ixy>
                        <ixz>0</ixz>
                        <iyy>0.01</iyy>
                        <iyz>0</iyz>
                        <izz>0.01</izz>
                    </inertia>
                    <mass>1</mass>
                </inertial>
                <collision name='plate_link_geom'>
                    <pose>0 0 0 0 -0 0</pose>
                    <geometry>
                        <mesh>
                            <uri>model://youbot/meshes/plate/plate_convex.stl</uri>
                        </mesh>
                    </geometry>
                    <surface>
                        <friction>
                            <ode>
                                <mu>1</mu>
                                <mu2>1</mu2>
                                <fdir1>0 0 0</fdir1>
                                <slip1>0</slip1>
                                <slip2>0</slip2>
                            </ode>
                        </friction>
                        <bounce>
                            <restitution_coefficient>0</restitution_coefficient>
                            <threshold>0</threshold>
                        </bounce>
                        <contact>
                            <ode>
                                <soft_cfm>0</soft_cfm>
                                <soft_erp>0.2</soft_erp>
                                <kp>1e+13</kp>
                                <kd>1e+11</kd>
                                <max_vel>-1</max_vel>
                                <min_depth>0</min_depth>
                            </ode>
                        </contact>
                    </surface>
                    <laser_retro>0</laser_retro>
                    <max_contacts>10</max_contacts>
                </collision>
                <visual name='plate_link_geom_visual'>
                    <pose>0 0 0 0 -0 0</pose>
                    <geometry>
                        <mesh>
                            <uri>model://youbot/meshes/plate/plate.dae</uri>
                        </mesh>
                    </geometry>
                </visual>
                <gravity>1</gravity>
                <self_collide>0</self_collide>
                <kinematic>0</kinematic>
            </link>
            <joint name='base_footprint_joint' type='revolute'>
                <pose>0 0 0 0 -0 0</pose>
                <parent>base_footprint</parent>
                <child>base_link</child>
                <axis>
                    <dynamics>
                        <damping>0</damping>
                        <friction>0</friction>
                        <spring_reference>0</spring_reference>
                        <spring_stiffness>0</spring_stiffness>
                    </dynamics>
                    <limit>
                        <lower>0</lower>
                        <upper>0</upper>
                        <effort>100</effort>
                        <velocity>100</velocity>
                    </limit>
                    <xyz>0 0 1</xyz>
                    <use_parent_model_frame>1</use_parent_model_frame>
                </axis>
            </joint>
            <joint name='arm_joint_0' type='revolute'>
                <pose>0 0 0 0 -0 0</pose>
                <parent>base_link</parent>
                <child>arm_link_0</child>
                <axis>
                    <dynamics>
                        <damping>0</damping>
                        <friction>0</friction>
                        <spring_reference>0</spring_reference>
                        <spring_stiffness>0</spring_stiffness>
                    </dynamics>
                    <limit>
                        <lower>0</lower>
                        <upper>0</upper>
                        <effort>100</effort>
                        <velocity>100</velocity>
                    </limit>
                    <xyz>0 0 1</xyz>
                    <use_parent_model_frame>1</use_parent_model_frame>
                </axis>
            </joint>
            <joint name='arm_joint_1' type='revolute'>
                <pose>0 0 0 0 -0 0</pose>
                <parent>arm_link_0</parent>
                <child>arm_link_1</child>
                <axis>
                    <dynamics>
                        <damping>1</damping>
                        <friction>0</friction>
                        <spring_reference>0</spring_reference>
                        <spring_stiffness>0</spring_stiffness>
                    </dynamics>
                    <limit>
                        <lower>0</lower>
                        <upper>5.89921</upper>
                        <effort>100</effort>
                        <velocity>100</velocity>
                    </limit>
                    <xyz>0 0 -1</xyz>
                    <use_parent_model_frame>1</use_parent_model_frame>
                </axis>
            </joint>
            <joint name='arm_joint_2' type='revolute'>
                <pose>0 0 0 0 -0 0</pose>
                <parent>arm_link_1</parent>
                <child>arm_link_2</child>
                <axis>
                    <dynamics>
                        <damping>1</damping>
                        <friction>0</friction>
                        <spring_reference>0</spring_reference>
                        <spring_stiffness>0</spring_stiffness>
                    </dynamics>
                    <limit>
                        <lower>0</lower>
                        <upper>2.70526</upper>
                        <effort>100</effort>
                        <velocity>100</velocity>
                    </limit>
                    <xyz>-0.173648 -0.984808 0</xyz>
                    <use_parent_model_frame>1</use_parent_model_frame>
                </axis>
            </joint>
            <joint name='arm_joint_3' type='revolute'>
                <pose>0 0 0 0 -0 0</pose>
                <parent>arm_link_2</parent>
                <child>arm_link_3</child>
                <axis>
                    <dynamics>
                        <damping>1</damping>
                        <friction>0</friction>
                        <spring_reference>0</spring_reference>
                        <spring_stiffness>0</spring_stiffness>
                    </dynamics>
                    <limit>
                        <lower>-5.18363</lower>
                        <upper>0</upper>
                        <effort>100</effort>
                        <velocity>100</velocity>
                    </limit>
                    <xyz>-0.173648 -0.984808 0</xyz>
                    <use_parent_model_frame>1</use_parent_model_frame>
                </axis>
            </joint>
            <joint name='arm_joint_4' type='revolute'>
                <pose>0 0 0 0 -0 0</pose>
                <parent>arm_link_3</parent>
                <child>arm_link_4</child>
                <axis>
                    <dynamics>
                        <damping>1</damping>
                        <friction>0</friction>
                        <spring_reference>0</spring_reference>
                        <spring_stiffness>0</spring_stiffness>
                    </dynamics>
                    <limit>
                        <lower>0</lower>
                        <upper>3.57793</upper>
                        <effort>100</effort>
                        <velocity>100</velocity>
                    </limit>
                    <xyz>-0.173648 -0.984808 0</xyz>
                    <use_parent_model_frame>1</use_parent_model_frame>
                </axis>
            </joint>
            <joint name='arm_joint_5' type='revolute'>
                <pose>0 0 0 0 -0 0</pose>
                <parent>arm_link_4</parent>
                <child>arm_link_5</child>
                <axis>
                    <dynamics>
                        <damping>1</damping>
                        <friction>0</friction>
                        <spring_reference>0</spring_reference>
                        <spring_stiffness>0</spring_stiffness>
                    </dynamics>
                    <limit>
                        <lower>0</lower>
                        <upper>5.84685</upper>
                        <effort>100</effort>
                        <velocity>100</velocity>
                    </limit>
                    <xyz>-0.360933 0.063642 -0.930418</xyz>
                    <use_parent_model_frame>1</use_parent_model_frame>
                </axis>
            </joint>
            <joint name='gripper_palm_joint' type='revolute'>
                <pose>0 0 0 0 -0 0</pose>
                <parent>arm_link_5</parent>
                <child>gripper_palm_link</child>
                <axis>
                    <dynamics>
                        <damping>0</damping>
                        <friction>0</friction>
                        <spring_reference>0</spring_reference>
                        <spring_stiffness>0</spring_stiffness>
                    </dynamics>
                    <limit>
                        <lower>0</lower>
                        <upper>0</upper>
                        <effort>100</effort>
                        <velocity>100</velocity>
                    </limit>
                    <xyz>0 0 1</xyz>
                    <use_parent_model_frame>1</use_parent_model_frame>
                </axis>
            </joint>
            <joint name='gripper_finger_joint_l' type='prismatic'>
                <pose>0 0 0 0 -0 0</pose>
                <parent>gripper_palm_link</parent>
                <child>gripper_finger_link_l</child>
                <axis>
                    <dynamics>
                        <damping>1</damping>
                        <friction>0</friction>
                        <spring_reference>0</spring_reference>
                        <spring_stiffness>0</spring_stiffness>
                    </dynamics>
                    <limit>
                        <lower>0</lower>
                        <upper>0.0115</upper>
                        <effort>100</effort>
                        <velocity>100</velocity>
                    </limit>
                    <xyz>0.367852 0.926495 -0.079325</xyz>
                    <use_parent_model_frame>1</use_parent_model_frame>
                </axis>
            </joint>
            <joint name='gripper_finger_joint_r' type='prismatic'>
                <pose>0 0 0 0 -0 0</pose>
                <parent>gripper_palm_link</parent>
                <child>gripper_finger_link_r</child>
                <axis>
                    <dynamics>
                        <damping>1</damping>
                        <friction>0</friction>
                        <spring_reference>0</spring_reference>
                        <spring_stiffness>0</spring_stiffness>
                    </dynamics>
                    <limit>
                        <lower>0</lower>
                        <upper>0.0115</upper>
                        <effort>100</effort>
                        <velocity>100</velocity>
                    </limit>
                    <xyz>-0.367852 -0.926495 0.079325</xyz>
                    <use_parent_model_frame>1</use_parent_model_frame>
                </axis>
            </joint>
            <joint name='base_laser_front_hokuyo_urg04_laser_joint' type='revolute'>
                <pose>0 0 0 0 -0 0</pose>
                <parent>base_link</parent>
                <child>base_laser_front_link</child>
                <axis>
                    <dynamics>
                        <damping>0</damping>
                        <friction>0</friction>
                        <spring_reference>0</spring_reference>
                        <spring_stiffness>0</spring_stiffness>
                    </dynamics>
                    <limit>
                        <lower>0</lower>
                        <upper>0</upper>
                        <effort>100</effort>
                        <velocity>100</velocity>
                    </limit>
                    <xyz>0 0 1</xyz>
                    <use_parent_model_frame>1</use_parent_model_frame>
                </axis>
            </joint>
            <joint name='caster_joint_bl' type='revolute'>
                <pose>0 0 0 0 -0 0</pose>
                <parent>base_link</parent>
                <child>caster_link_bl</child>
                <axis>
                    <dynamics>
                        <damping>1</damping>
                        <friction>0</friction>
                        <spring_reference>0</spring_reference>
                        <spring_stiffness>0</spring_stiffness>
                    </dynamics>
                    <limit>
                        <lower>-1e+16</lower>
                        <upper>1e+16</upper>
                        <effort>100</effort>
                        <velocity>100</velocity>
                    </limit>
                    <xyz>0 0 1</xyz>
                    <use_parent_model_frame>1</use_parent_model_frame>
                </axis>
            </joint>
            <joint name='wheel_joint_bl' type='revolute'>
                <pose>0 0 0 0 -0 0</pose>
                <parent>caster_link_bl</parent>
                <child>wheel_link_bl</child>
                <axis>
                    <dynamics>
                        <damping>1</damping>
                        <friction>0</friction>
                        <spring_reference>0</spring_reference>
                        <spring_stiffness>0</spring_stiffness>
                    </dynamics>
                    <limit>
                        <lower>-1e+16</lower>
                        <upper>1e+16</upper>
                        <effort>100</effort>
                        <velocity>100</velocity>
                    </limit>
                    <xyz>0 1 0</xyz>
                    <use_parent_model_frame>1</use_parent_model_frame>
                </axis>
            </joint>
            <joint name='caster_joint_br' type='revolute'>
                <pose>0 0 0 0 -0 0</pose>
                <parent>base_link</parent>
                <child>caster_link_br</child>
                <axis>
                    <dynamics>
                        <damping>1</damping>
                        <friction>0</friction>
                        <spring_reference>0</spring_reference>
                        <spring_stiffness>0</spring_stiffness>
                    </dynamics>
                    <limit>
                        <lower>-1e+16</lower>
                        <upper>1e+16</upper>
                        <effort>100</effort>
                        <velocity>100</velocity>
                    </limit>
                    <xyz>0 0 1</xyz>
                    <use_parent_model_frame>1</use_parent_model_frame>
                </axis>
            </joint>
            <joint name='wheel_joint_br' type='revolute'>
                <pose>0 0 0 0 -0 0</pose>
                <parent>caster_link_br</parent>
                <child>wheel_link_br</child>
                <axis>
                    <dynamics>
                        <damping>1</damping>
                        <friction>0</friction>
                        <spring_reference>0</spring_reference>
                        <spring_stiffness>0</spring_stiffness>
                    </dynamics>
                    <limit>
                        <lower>-1e+16</lower>
                        <upper>1e+16</upper>
                        <effort>100</effort>
                        <velocity>100</velocity>
                    </limit>
                    <xyz>0 1 0</xyz>
                    <use_parent_model_frame>1</use_parent_model_frame>
                </axis>
            </joint>
            <joint name='caster_joint_fl' type='revolute'>
                <pose>0 0 0 0 -0 0</pose>
                <parent>base_link</parent>
                <child>caster_link_fl</child>
                <axis>
                    <dynamics>
                        <damping>1</damping>
                        <friction>0</friction>
                        <spring_reference>0</spring_reference>
                        <spring_stiffness>0</spring_stiffness>
                    </dynamics>
                    <limit>
                        <lower>-1e+16</lower>
                        <upper>1e+16</upper>
                        <effort>100</effort>
                        <velocity>100</velocity>
                    </limit>
                    <xyz>0 0 1</xyz>
                    <use_parent_model_frame>1</use_parent_model_frame>
                </axis>
            </joint>
            <joint name='wheel_joint_fl' type='revolute'>
                <pose>0 0 0 0 -0 0</pose>
                <parent>caster_link_fl</parent>
                <child>wheel_link_fl</child>
                <axis>
                    <dynamics>
                        <damping>1</damping>
                        <friction>0</friction>
                        <spring_reference>0</spring_reference>
                        <spring_stiffness>0</spring_stiffness>
                    </dynamics>
                    <limit>
                        <lower>-1e+16</lower>
                        <upper>1e+16</upper>
                        <effort>100</effort>
                        <velocity>100</velocity>
                    </limit>
                    <xyz>0 1 0</xyz>
                    <use_parent_model_frame>1</use_parent_model_frame>
                </axis>
            </joint>
            <joint name='caster_joint_fr' type='revolute'>
                <pose>0 0 0 0 -0 0</pose>
                <parent>base_link</parent>
                <child>caster_link_fr</child>
                <axis>
                    <dynamics>
                        <damping>1</damping>
                        <friction>0</friction>
                        <spring_reference>0</spring_reference>
                        <spring_stiffness>0</spring_stiffness>
                    </dynamics>
                    <limit>
                        <lower>-1e+16</lower>
                        <upper>1e+16</upper>
                        <effort>100</effort>
                        <velocity>100</velocity>
                    </limit>
                    <xyz>0 0 1</xyz>
                    <use_parent_model_frame>1</use_parent_model_frame>
                </axis>
            </joint>
            <joint name='wheel_joint_fr' type='revolute'>
                <pose>0 0 0 0 -0 0</pose>
                <parent>caster_link_fr</parent>
                <child>wheel_link_fr</child>
                <axis>
                    <dynamics>
                        <damping>1</damping>
                        <friction>0</friction>
                        <spring_reference>0</spring_reference>
                        <spring_stiffness>0</spring_stiffness>
                    </dynamics>
                    <limit>
                        <lower>-1e+16</lower>
                        <upper>1e+16</upper>
                        <effort>100</effort>
                        <velocity>100</velocity>
                    </limit>
                    <xyz>0 1 0</xyz>
                    <use_parent_model_frame>1</use_parent_model_frame>
                </axis>
            </joint>
            <joint name='plate_joint' type='revolute'>
                <parent>base_link</parent>
                <child>plate_link</child>
                <axis>
                    <dynamics>
                        <damping>0</damping>
                        <friction>0</friction>
                        <spring_reference>0</spring_reference>
                        <spring_stiffness>0</spring_stiffness>
                    </dynamics>
                    <limit>
                        <lower>0</lower>
                        <upper>0</upper>
                        <effort>100</effort>
                        <velocity>100</velocity>
                    </limit>
                    <xyz>0 0 1</xyz>
                    <use_parent_model_frame>1</use_parent_model_frame>
                </axis>
            </joint>
            <plugin name="gazebo_joint_cmd_plugin" filename="libwheelcmd.so">
                <topicName>/gazebo/commands</topicName>
            </plugin>
            <static>0</static>
        </model>
        <state world_name='default'>
            <sim_time>190 457000000</sim_time>
            <real_time>202 516772622</real_time>
            <wall_time>1485114140 143291505</wall_time>
            <model name='LIDAMaze_0'>
                <pose>2.56238 0 0 0 -0 0</pose>
                <link name='Wall_10'>
                    <pose>-17.5013 -12.4268 0 0 -0 0</pose>
                    <velocity>0 0 0 0 -0 0</velocity>
                    <acceleration>0 0 0 0 -0 0</acceleration>
                    <wrench>0 0 0 0 -0 0</wrench>
                </link>
                <link name='Wall_12'>
                    <pose>-20.8763 10.1732 0 0 -0 0</pose>
                    <velocity>0 0 0 0 -0 0</velocity>
                    <acceleration>0 0 0 0 -0 0</acceleration>
                    <wrench>0 0 0 0 -0 0</wrench>
                </link>
                <link name='Wall_13'>
                    <pose>-18.2013 1.24818 0 0 0 -1.5708</pose>
                    <velocity>0 0 0 0 -0 0</velocity>
                    <acceleration>0 0 0 0 -0 0</acceleration>
                    <wrench>0 0 0 0 -0 0</wrench>
                </link>
                <link name='Wall_18'>
                    <pose>-4.70134 -5.67682 0 0 -0 0</pose>
                    <velocity>0 0 0 0 -0 0</velocity>
                    <acceleration>0 0 0 0 -0 0</acceleration>
                    <wrench>0 0 0 0 -0 0</wrench>
                </link>
                <link name='Wall_19'>
                    <pose>-3.90134 3.37318 0 0 -0 1.5708</pose>
                    <velocity>0 0 0 0 -0 0</velocity>
                    <acceleration>0 0 0 0 -0 0</acceleration>
                    <wrench>0 0 0 0 -0 0</wrench>
                </link>
                <link name='Wall_20'>
                    <pose>1.79087 6.73097 0 0 0 -0.785398</pose>
                    <velocity>0 0 0 0 -0 0</velocity>
                    <acceleration>0 0 0 0 -0 0</acceleration>
                    <wrench>0 0 0 0 -0 0</wrench>
                </link>
                <link name='Wall_21'>
                    <pose>6.2084 -3.71842 0 0 0 -1.8326</pose>
                    <velocity>0 0 0 0 -0 0</velocity>
                    <acceleration>0 0 0 0 -0 0</acceleration>
                    <wrench>0 0 0 0 -0 0</wrench>
                </link>
                <link name='Wall_22'>
                    <pose>5.85872 -8.4756 0 0 -0 0</pose>
                    <velocity>0 0 0 0 -0 0</velocity>
                    <acceleration>0 0 0 0 -0 0</acceleration>
                    <wrench>0 0 0 0 -0 0</wrench>
                </link>
                <link name='Wall_23'>
                    <pose>11.6837 0.011445 0 0 -0 1.0472</pose>
                    <velocity>0 0 0 0 -0 0</velocity>
                    <acceleration>0 0 0 0 -0 0</acceleration>
                    <wrench>0 0 0 0 -0 0</wrench>
                </link>
                <link name='Wall_26'>
                    <pose>8.59866 -12.4268 0 0 -0 0</pose>
                    <velocity>0 0 0 0 -0 0</velocity>
                    <acceleration>0 0 0 0 -0 0</acceleration>
                    <wrench>0 0 0 0 -0 0</wrench>
                </link>
                <link name='Wall_27'>
                    <pose>22.6162 -1.96416 0 0 -0 2.09381</pose>
                    <velocity>0 0 0 0 -0 0</velocity>
                    <acceleration>0 0 0 0 -0 0</acceleration>
                    <wrench>0 0 0 0 -0 0</wrench>
                </link>
                <link name='Wall_56'>
                    <pose>-15.6513 -7.67682 0 0 -0 0</pose>
                    <velocity>0 0 0 0 -0 0</velocity>
                    <acceleration>0 0 0 0 -0 0</acceleration>
                    <wrench>0 0 0 0 -0 0</wrench>
                </link>
                <link name='Wall_57'>
                    <pose>-13.1013 -0.626816 0 0 -0 1.5708</pose>
                    <velocity>0 0 0 0 -0 0</velocity>
                    <acceleration>0 0 0 0 -0 0</acceleration>
                    <wrench>0 0 0 0 -0 0</wrench>
                </link>
                <link name='Wall_60'>
                    <pose>-5.50134 0.373184 0 0 -0 1.5708</pose>
                    <velocity>0 0 0 0 -0 0</velocity>
                    <acceleration>0 0 0 0 -0 0</acceleration>
                    <wrench>0 0 0 0 -0 0</wrench>
                </link>
                <link name='Wall_62'>
                    <pose>-9.30132 6.42318 0 0 -0 0</pose>
                    <velocity>0 0 0 0 -0 0</velocity>
                    <acceleration>0 0 0 0 -0 0</acceleration>
                    <wrench>0 0 0 0 -0 0</wrench>
                </link>
                <link name='Wall_66'>
                    <pose>-9.26282 -5.37061 0 0 0 -1.5708</pose>
                    <velocity>0 0 0 0 -0 0</velocity>
                    <acceleration>0 0 0 0 -0 0</acceleration>
                    <wrench>0 0 0 0 -0 0</wrench>
                </link>
                <link name='Wall_77'>
                    <pose>1.26701 -5.42338 0 0 -0 1.309</pose>
                    <velocity>0 0 0 0 -0 0</velocity>
                    <acceleration>0 0 0 0 -0 0</acceleration>
                    <wrench>0 0 0 0 -0 0</wrench>
                </link>
                <link name='Wall_78'>
                    <pose>1.28856 3.18952 0 0 -0 2.35619</pose>
                    <velocity>0 0 0 0 -0 0</velocity>
                    <acceleration>0 0 0 0 -0 0</acceleration>
                    <wrench>0 0 0 0 -0 0</wrench>
                </link>
                <link name='Wall_80'>
                    <pose>-0.53611 -3.62025 0 0 0 -1.5733</pose>
                    <velocity>0 0 0 0 -0 0</velocity>
                    <acceleration>0 0 0 0 -0 0</acceleration>
                    <wrench>0 0 0 0 -0 0</wrench>
                </link>
                <link name='Wall_82'>
                    <pose>12.3122 -6.43774 0 0 0 -2.05523</pose>
                    <velocity>0 0 0 0 -0 0</velocity>
                    <acceleration>0 0 0 0 -0 0</acceleration>
                    <wrench>0 0 0 0 -0 0</wrench>
                </link>
                <link name='Wall_84'>
                    <pose>16.75 -0.475286 0 0 -0 0</pose>
                    <velocity>0 0 0 0 -0 0</velocity>
                    <acceleration>0 0 0 0 -0 0</acceleration>
                    <wrench>0 0 0 0 -0 0</wrench>
                </link>
                <link name='Wall_85'>
                    <pose>19.1241 -2.60193 0 0 0 -1.10308</pose>
                    <velocity>0 0 0 0 -0 0</velocity>
                    <acceleration>0 0 0 0 -0 0</acceleration>
                    <wrench>0 0 0 0 -0 0</wrench>
                </link>
                <link name='Wall_9'>
                    <pose>-23.5513 -1.12682 0 0 0 -1.5708</pose>
                    <velocity>0 0 0 0 -0 0</velocity>
                    <acceleration>0 0 0 0 -0 0</acceleration>
                    <wrench>0 0 0 0 -0 0</wrench>
                </link>
                <link name='Wall_91'>
                    <pose>18.6537 -8.17085 0 0 -0 0</pose>
                    <velocity>0 0 0 0 -0 0</velocity>
                    <acceleration>0 0 0 0 -0 0</acceleration>
                    <wrench>0 0 0 0 -0 0</wrench>
                </link>
                <link name='Wall_92'>
                    <pose>23.1992 -10.2892 0 0 0 -1.04272</pose>
                    <velocity>0 0 0 0 -0 0</velocity>
                    <acceleration>0 0 0 0 -0 0</acceleration>
                    <wrench>0 0 0 0 -0 0</wrench>
                </link>
            </model>
            <model name='ground_plane'>
                <pose>0 0 0 0 -0 0</pose>
                <link name='link'>
                    <pose>0 0 0 0 -0 0</pose>
                    <velocity>0 0 0 0 -0 0</velocity>
                    <acceleration>0 0 0 0 -0 0</acceleration>
                    <wrench>0 0 0 0 -0 0</wrench>
                </link>
            </model>
            <model name='youbot'>
                <pose>-21.4193 8.00039 0.083976 1.8e-05 2.7e-05 -1.48991</pose>
                <link name='arm_link_0'>
                    <pose>-21.4077 7.85786 0.12997 2.4e-05 2.7e-05 -1.48991</pose>
                    <velocity>-0.000361 3e-05 -0.00069 -0.00162 -0.002788 -0.000791</velocity>
                    <acceleration>0.0294 0.274021 -1.32736 -0.054257 -0.009582 -0.025249</acceleration>
                    <wrench>0.024843 0.231547 -1.12162 0 -0 0</wrench>
                </link>
                <link name='arm_link_1'>
                    <pose>-21.4058 7.83393 0.225969 -3.4e-05 -3.7e-05 1.46782</pose>
                    <velocity>-0.000485 7e-05 -0.000694 -0.002312 -0.005716 0.002404</velocity>
                    <acceleration>0.166668 0.568434 -1.37461 -0.005488 -0.011917 -0.005072</acceleration>
                    <wrench>0.402003 1.37106 -3.31555 0 -0 0</wrench>
                </link>
                <link name='arm_link_2'>
                    <pose>-21.4024 7.86676 0.244969 -0.000115 -1.13451 1.46789</pose>
                    <velocity>-0.000724 0.000232 -0.000939 0.008873 -0.009802 -0.006588</velocity>
                    <acceleration>-0.263966 -0.080089 -1.36192 0.018694 -0.05123 -0.056868</acceleration>
                    <wrench>-0.30488 -0.092503 -1.57302 0 -0 0</wrench>
                </link>
                <link name='arm_link_3'>
                    <pose>-21.4168 7.72702 0.310451 0.000367 1.41372 1.46816</pose>
                    <velocity>-0.0011 -0.000243 -0.004882 0.026931 -0.001154 -0.004787</velocity>
                    <acceleration>-0.284947 1.04203 -4.51497 0.113737 0.037213 -0.00604</acceleration>
                    <wrench>-0.26614 0.973253 -4.21698 0 -0 0</wrench>
                </link>
                <link name='arm_link_4'>
                    <pose>-21.4031 7.85965 0.331567 9e-05 -0.375304 1.46776</pose>
                    <velocity>-0.000453 -0.000875 -0.002401 0.010982 0.003405 -0.004968</velocity>
                    <acceleration>0.497186 -1.58304 5.45079 0.080494 0.029245 -0.022182</acceleration>
                    <wrench>0.436032 -1.38833 4.78034 0 -0 0</wrench>
                </link>
                <link name='arm_link_5'>
                    <pose>-21.4082 7.8104 0.451786 -0.138624 0.349889 -2.06013</pose>
                    <velocity>0.000428 -0.002161 -0.003279 0.004722 -0.009958 -0.008048</velocity>
                    <acceleration>4.1045 -2.44244 3.58238 0.000558 0.063779 -0.052938</acceleration>
                    <wrench>1.03023 -0.613053 0.899176 0 -0 0</wrench>
                </link>
                <link name='base_footprint'>
                    <pose>-21.4193 8.00039 0.083976 1.8e-05 2.7e-05 -1.48991</pose>
                    <velocity>-0.000292 -3.3e-05 -0.000626 -0.000364 -0.001138 0.000267</velocity>
                    <acceleration>-0.097332 -0.075208 -1.43585 -2.86165 0.965778 -2.97478</acceleration>
                    <wrench>-0.009733 -0.007521 -0.143585 0 -0 0</wrench>
                </link>
                <link name='base_laser_front_link'>
                    <pose>-21.395 7.70137 0.053968 1.8e-05 2.7e-05 -1.48991</pose>
                    <velocity>-0.000174 -4e-05 -0.000483 -0.000367 -0.001131 0.000293</velocity>
                    <acceleration>0.032379 -0.015149 -0.616666 -1.75198 0.849808 0.232211</acceleration>
                    <wrench>0.005181 -0.002424 -0.098667 0 -0 0</wrench>
                </link>
                <link name='base_link'>
                    <pose>-21.4193 8.00039 0.083976 1.8e-05 2.7e-05 -1.48991</pose>
                    <velocity>-0.000292 -3.5e-05 -0.000625 -0.000359 -0.001141 0.000268</velocity>
                    <acceleration>-0.029721 0.063916 -1.43563 -0.699944 0.349639 -0.10941</acceleration>
                    <wrench>-0.653854 1.40616 -31.5838 0 -0 0</wrench>
                </link>
                <link name='caster_link_bl'>
                    <pose>-21.2802 8.24041 0.049997 1.8e-05 2.7e-05 -1.49055</pose>
                    <velocity>-0.000153 1e-06 -0.003871 -0.000364 -0.001153 -0.000176</velocity>
                    <acceleration>-0.011448 -0.023946 -3.92701 -0.325845 0.208255 -0.006389</acceleration>
                    <wrench>-0.001145 -0.002395 -0.392701 0 -0 0</wrench>
                </link>
                <link name='caster_link_br'>
                    <pose>-21.5952 8.21488 0.050001 1.9e-05 2.7e-05 -1.49049</pose>
                    <velocity>-0.000164 -2.8e-05 0.00048 -0.000334 -0.001238 -0.000148</velocity>
                    <acceleration>-0.010719 -0.113113 0.243449 -0.31105 0.209984 0.003064</acceleration>
                    <wrench>-0.001072 -0.011311 0.024345 0 -0 0</wrench>
                </link>
                <link name='caster_link_fl'>
                    <pose>-21.2434 7.7859 0.050002 1.9e-05 2.7e-05 -1.4876</pose>
                    <velocity>-0.000115 7e-06 0.000533 -0.000347 -0.001204 -0.000135</velocity>
                    <acceleration>0.046515 -0.016799 0.145718 -0.327508 0.217314 -0.003372</acceleration>
                    <wrench>0.004652 -0.00168 0.014572 0 -0 0</wrench>
                </link>
                <link name='caster_link_fr'>
                    <pose>-21.5583 7.76037 0.049996 1.9e-05 2.7e-05 -1.48716</pose>
                    <velocity>-0.000113 -2.9e-05 0.000648 -0.000341 -0.00121 -0.000148</velocity>
                    <acceleration>0.053939 -0.101047 0.090157 -0.31635 0.219338 0.00167</acceleration>
                    <wrench>0.005394 -0.010105 0.009016 0 -0 0</wrench>
                </link>
                <link name='gripper_finger_link_l'>
                    <pose>-21.3942 7.78205 0.490682 0.138627 -0.349891 1.08147</pose>
                    <velocity>-0.003113 -0.000963 -0.0028 0.00549 -0.007986 -0.003983</velocity>
                    <acceleration>1.6792 -0.889284 4.13278 -2.95568 0.368193 2.93901</acceleration>
                    <wrench>0.016792 -0.008893 0.041328 0 -0 0</wrench>
                </link>
                <link name='gripper_finger_link_r'>
                    <pose>-21.4189 7.7937 0.494252 -0.138627 0.349891 -2.06013</pose>
                    <velocity>-0.003094 -0.000892 -0.002923 0.005559 -0.007811 -0.003912</velocity>
                    <acceleration>1.66668 -0.963823 4.29225 -2.8686 0.588403 3.02844</acceleration>
                    <wrench>0.016667 -0.009638 0.042922 0 -0 0</wrench>
                </link>
                <link name='gripper_palm_link'>
                    <pose>-21.4082 7.8104 0.451786 -0.138627 0.34989 -2.06013</pose>
                    <velocity>0.000765 -0.002307 -0.003276 0.00546 -0.008069 -0.004017</velocity>
                    <acceleration>4.58143 -2.55752 3.63134 -0.299461 0.65498 0.289794</acceleration>
                    <wrench>0.458143 -0.255752 0.363134 0 -0 0</wrench>
                </link>
                <link name='plate_link'>
                    <pose>-21.4321 8.15887 0.12998 1.8e-05 2.7e-05 -1.48991</pose>
                    <velocity>-0.000388 -2.4e-05 -0.00069 -0.000344 -0.001148 0.000271</velocity>
                    <acceleration>-0.020192 0.185881 -1.86031 -0.027942 0.013495 0.003347</acceleration>
                    <wrench>-0.020192 0.185881 -1.86031 0 -0 0</wrench>
                </link>
                <link name='wheel_link_bl'>
                    <pose>-21.2802 8.24041 0.049997 1.7e-05 -0.032358 -1.49055</pose>
                    <velocity>-5.7e-05 1.3e-05 -0.00363 -0.000992 -0.001383 -0.000184</velocity>
                    <acceleration>0.072308 -0.038776 -3.77007 -0.007084 0.047819 0.001594</acceleration>
                    <wrench>0.028923 -0.015511 -1.50803 0 -0 0</wrench>
                </link>
                <link name='wheel_link_br'>
                    <pose>-21.5952 8.21488 0.05 1.9e-05 -0.028905 -1.49049</pose>
                    <velocity>-7.5e-05 1.4e-05 0.000412 -0.000294 -0.001458 -0.000156</velocity>
                    <acceleration>0.071595 -0.121042 0.142826 0.061912 0.051958 0.00665</acceleration>
                    <wrench>0.028638 -0.048417 0.05713 0 -0 0</wrench>
                </link>
                <link name='wheel_link_fl'>
                    <pose>-21.2434 7.7859 0.05 1.9e-05 0.02723 -1.4876</pose>
                    <velocity>-6.6e-05 1.4e-05 0.00049 -0.000264 -0.001313 -0.000141</velocity>
                    <acceleration>0.075518 -0.037913 0.085559 0.013913 0.05687 0.003298</acceleration>
                    <wrench>0.030207 -0.015165 0.034224 0 -0 0</wrench>
                </link>
                <link name='wheel_link_fr'>
                    <pose>-21.5583 7.76037 0.049994 2e-05 0.032997 -1.48716</pose>
                    <velocity>-6.8e-05 6e-06 0.000573 -0.000128 -0.001316 -0.000151</velocity>
                    <acceleration>0.082561 -0.109218 0.059061 0.055042 0.059744 0.00634</acceleration>
                    <wrench>0.033024 -0.043687 0.023624 0 -0 0</wrench>
                </link>
            </model>
        </state>
        <gui fullscreen='0'>
            <camera name='user_camera'>
                <pose>-2.64269 -41.5126 38.8587 0 0.763643 1.54019</pose>
                <view_controller>orbit</view_controller>
            </camera>
        </gui>
    </world>
</sdf>
