<sdf version='1.5'>
  <world name='default'>
    <light name='sun' type='directional'>
      <cast_shadows>1</cast_shadows>
      <pose>0 0 10 0 -0 0</pose>
      <diffuse>0.8 0.8 0.8 1</diffuse>
      <specular>0.2 0.2 0.2 1</specular>
      <attenuation>
        <range>1000</range>
        <constant>0.9</constant>
        <linear>0.01</linear>
        <quadratic>0.001</quadratic>
      </attenuation>
      <direction>-0.5 0.1 -0.9</direction>
    </light>
    <model name='ground_plane'>
      <static>1</static>
      <link name='link'>
        <collision name='collision'>
          <geometry>
            <plane>
              <normal>0 0 1</normal>
              <size>100 100</size>
            </plane>
          </geometry>
          <surface>
            <friction>
              <ode>
                <mu>100</mu>
                <mu2>50</mu2>
              </ode>
            </friction>
            <contact>
              <ode/>
            </contact>
            <bounce/>
          </surface>
          <max_contacts>10</max_contacts>
        </collision>
        <visual name='visual'>
          <cast_shadows>0</cast_shadows>
          <geometry>
            <plane>
              <normal>0 0 1</normal>
              <size>100 100</size>
            </plane>
          </geometry>
          <material>
            <script>
              <uri>file://media/materials/scripts/gazebo.material</uri>
              <name>Gazebo/Grey</name>
            </script>
          </material>
        </visual>
        <self_collide>0</self_collide>
        <kinematic>0</kinematic>
        <gravity>1</gravity>
      </link>
    </model>
    <physics name='default_physics' default='0' type='ode'>
      <max_step_size>0.001</max_step_size>
      <real_time_factor>1</real_time_factor>
      <real_time_update_rate>1000</real_time_update_rate>
      <gravity>0 0 -9.8</gravity>
      <magnetic_field>5.5645e-06 2.28758e-05 -4.23884e-05</magnetic_field>
    </physics>
    <scene>
      <ambient>0.4 0.4 0.4 1</ambient>
      <background>0.7 0.7 0.7 1</background>
      <shadows>1</shadows>
    </scene>
    <spherical_coordinates>
      <surface_model>EARTH_WGS84</surface_model>
      <latitude_deg>0</latitude_deg>
      <longitude_deg>0</longitude_deg>
      <elevation>0</elevation>
      <heading_deg>0</heading_deg>
    </spherical_coordinates>
    <model name='Simple_Maze'>
      <pose>0 -2 0 0 -0 0</pose>
      <link name='Wall_1'>
        <collision name='Wall_1_Collision'>
          <geometry>
            <box>
              <size>17 0.15 2.5</size>
            </box>
          </geometry>
          <pose>0 0 1.25 0 -0 0</pose>
          <max_contacts>10</max_contacts>
          <surface>
            <contact>
              <ode/>
            </contact>
            <bounce/>
            <friction>
              <ode/>
            </friction>
          </surface>
        </collision>
        <visual name='Wall_1_Visual'>
          <pose>0 0 1.25 0 -0 0</pose>
          <geometry>
            <box>
              <size>17 0.15 2.5</size>
            </box>
          </geometry>
          <material>
            <script>
              <uri>file://media/materials/scripts/gazebo.material</uri>
              <name>Gazebo/Bricks</name>
            </script>
            <ambient>1 1 1 1</ambient>
          </material>
        </visual>
        <pose>16.8 -0 0 0 0 -1.5708</pose>
        <self_collide>0</self_collide>
        <kinematic>0</kinematic>
        <gravity>1</gravity>
      </link>
      <link name='Wall_10'>
        <collision name='Wall_10_Collision'>
          <geometry>
            <box>
              <size>7.25 0.15 2.5</size>
            </box>
          </geometry>
          <pose>0 0 1.25 0 -0 0</pose>
          <max_contacts>10</max_contacts>
          <surface>
            <contact>
              <ode/>
            </contact>
            <bounce/>
            <friction>
              <ode/>
            </friction>
          </surface>
        </collision>
        <visual name='Wall_10_Visual'>
          <pose>0 0 1.25 0 -0 0</pose>
          <geometry>
            <box>
              <size>7.25 0.15 2.5</size>
            </box>
          </geometry>
          <material>
            <script>
              <uri>file://media/materials/scripts/gazebo.material</uri>
              <name>Gazebo/Bricks</name>
            </script>
            <ambient>1 1 1 1</ambient>
          </material>
        </visual>
        <pose>-10.161 -4.76651 0 0 -0 3.14159</pose>
        <self_collide>0</self_collide>
        <kinematic>0</kinematic>
        <gravity>1</gravity>
      </link>
      <link name='Wall_16'>
        <collision name='Wall_16_Collision'>
          <geometry>
            <box>
              <size>3.5 0.15 2.5</size>
            </box>
          </geometry>
          <pose>0 0 1.25 0 -0 0</pose>
          <max_contacts>10</max_contacts>
          <surface>
            <contact>
              <ode/>
            </contact>
            <bounce/>
            <friction>
              <ode/>
            </friction>
          </surface>
        </collision>
        <visual name='Wall_16_Visual'>
          <pose>0 0 1.25 0 -0 0</pose>
          <geometry>
            <box>
              <size>3.5 0.15 2.5</size>
            </box>
          </geometry>
          <material>
            <script>
              <uri>file://media/materials/scripts/gazebo.material</uri>
              <name>Gazebo/Bricks</name>
            </script>
            <ambient>1 1 1 1</ambient>
          </material>
        </visual>
        <pose>-3.5354 -6.66942 0 0 -0 1.5708</pose>
        <self_collide>0</self_collide>
        <kinematic>0</kinematic>
        <gravity>1</gravity>
      </link>
      <link name='Wall_19'>
        <collision name='Wall_19_Collision'>
          <geometry>
            <box>
              <size>3.25 0.15 2.5</size>
            </box>
          </geometry>
          <pose>0 0 1.25 0 -0 0</pose>
          <max_contacts>10</max_contacts>
          <surface>
            <contact>
              <ode/>
            </contact>
            <bounce/>
            <friction>
              <ode/>
            </friction>
          </surface>
        </collision>
        <visual name='Wall_19_Visual'>
          <pose>0 0 1.25 0 -0 0</pose>
          <geometry>
            <box>
              <size>3.25 0.15 2.5</size>
            </box>
          </geometry>
          <material>
            <script>
              <uri>file://media/materials/scripts/gazebo.material</uri>
              <name>Gazebo/Bricks</name>
            </script>
            <ambient>1 1 1 1</ambient>
          </material>
        </visual>
        <pose>-15.1813 -1.62924 0 0 -0 0</pose>
        <self_collide>0</self_collide>
        <kinematic>0</kinematic>
        <gravity>1</gravity>
      </link>
      <link name='Wall_2'>
        <pose>0 -8.425 0 0 -0 3.14159</pose>
        <visual name='Wall_2_Visual_0'>
          <pose>-16.667 0 1.25 0 -0 0</pose>
          <geometry>
            <box>
              <size>0.416079 0.15 2.5</size>
            </box>
          </geometry>
          <material>
            <script>
              <uri>file://media/materials/scripts/gazebo.material</uri>
              <name>Gazebo/Bricks</name>
            </script>
            <ambient>1 1 1 1</ambient>
          </material>
        </visual>
        <collision name='Wall_2_Collision_0'>
          <geometry>
            <box>
              <size>0.416079 0.15 2.5</size>
            </box>
          </geometry>
          <pose>-16.667 0 1.25 0 -0 0</pose>
          <max_contacts>10</max_contacts>
          <surface>
            <contact>
              <ode/>
            </contact>
            <bounce/>
            <friction>
              <ode/>
            </friction>
          </surface>
        </collision>
        <visual name='Wall_2_Visual_1'>
          <pose>1.52986 0 1.25 0 -0 0</pose>
          <geometry>
            <box>
              <size>30.6903 0.15 2.5</size>
            </box>
          </geometry>
          <material>
            <script>
              <uri>file://media/materials/scripts/gazebo.material</uri>
              <name>Gazebo/Bricks</name>
            </script>
            <ambient>1 1 1 1</ambient>
          </material>
        </visual>
        <collision name='Wall_2_Collision_1'>
          <geometry>
            <box>
              <size>30.6903 0.15 2.5</size>
            </box>
          </geometry>
          <pose>1.52986 0 1.25 0 -0 0</pose>
          <max_contacts>10</max_contacts>
          <surface>
            <contact>
              <ode/>
            </contact>
            <bounce/>
            <friction>
              <ode/>
            </friction>
          </surface>
        </collision>
        <visual name='Wall_2_Visual_2'>
          <pose>-15.1371 0 2.25 0 -0 0</pose>
          <geometry>
            <box>
              <size>2.64364 0.15 0.5</size>
            </box>
          </geometry>
          <material>
            <script>
              <uri>file://media/materials/scripts/gazebo.material</uri>
              <name>Gazebo/Bricks</name>
            </script>
            <ambient>1 1 1 1</ambient>
          </material>
        </visual>
        <collision name='Wall_2_Collision_2'>
          <geometry>
            <box>
              <size>2.64364 0.15 0.5</size>
            </box>
          </geometry>
          <pose>-15.1371 0 2.25 0 -0 0</pose>
          <max_contacts>10</max_contacts>
          <surface>
            <contact>
              <ode/>
            </contact>
            <bounce/>
            <friction>
              <ode/>
            </friction>
          </surface>
        </collision>
        <self_collide>0</self_collide>
        <kinematic>0</kinematic>
        <gravity>1</gravity>
      </link>
      <link name='Wall_21'>
        <collision name='Wall_21_Collision'>
          <geometry>
            <box>
              <size>3.5 0.15 2.5</size>
            </box>
          </geometry>
          <pose>0 0 1.25 0 -0 0</pose>
          <max_contacts>10</max_contacts>
          <surface>
            <contact>
              <ode/>
            </contact>
            <bounce/>
            <friction>
              <ode/>
            </friction>
          </surface>
        </collision>
        <visual name='Wall_21_Visual'>
          <pose>0 0 1.25 0 -0 0</pose>
          <geometry>
            <box>
              <size>3.5 0.15 2.5</size>
            </box>
          </geometry>
          <material>
            <script>
              <uri>file://media/materials/scripts/gazebo.material</uri>
              <name>Gazebo/Bricks</name>
            </script>
            <ambient>1 1 1 1</ambient>
          </material>
        </visual>
        <pose>-11.8153 5.20589 0 0 -0 3.14159</pose>
        <self_collide>0</self_collide>
        <kinematic>0</kinematic>
        <gravity>1</gravity>
      </link>
      <link name='Wall_22'>
        <collision name='Wall_22_Collision'>
          <geometry>
            <box>
              <size>3.5 0.15 2.5</size>
            </box>
          </geometry>
          <pose>0 0 1.25 0 -0 0</pose>
          <max_contacts>10</max_contacts>
          <surface>
            <contact>
              <ode/>
            </contact>
            <bounce/>
            <friction>
              <ode/>
            </friction>
          </surface>
        </collision>
        <visual name='Wall_22_Visual'>
          <pose>0 0 1.25 0 -0 0</pose>
          <geometry>
            <box>
              <size>3.5 0.15 2.5</size>
            </box>
          </geometry>
          <material>
            <script>
              <uri>file://media/materials/scripts/gazebo.material</uri>
              <name>Gazebo/Bricks</name>
            </script>
            <ambient>1 1 1 1</ambient>
          </material>
        </visual>
        <pose>-13.4903 3.5309 0 0 0 -1.5708</pose>
        <self_collide>0</self_collide>
        <kinematic>0</kinematic>
        <gravity>1</gravity>
      </link>
      <link name='Wall_24'>
        <collision name='Wall_24_Collision'>
          <geometry>
            <box>
              <size>6.75 0.15 2.5</size>
            </box>
          </geometry>
          <pose>0 0 1.25 0 -0 0</pose>
          <max_contacts>10</max_contacts>
          <surface>
            <contact>
              <ode/>
            </contact>
            <bounce/>
            <friction>
              <ode/>
            </friction>
          </surface>
        </collision>
        <visual name='Wall_24_Visual'>
          <pose>0 0 1.25 0 -0 0</pose>
          <geometry>
            <box>
              <size>6.75 0.15 2.5</size>
            </box>
          </geometry>
          <material>
            <script>
              <uri>file://media/materials/scripts/gazebo.material</uri>
              <name>Gazebo/Bricks</name>
            </script>
            <ambient>1 1 1 1</ambient>
          </material>
        </visual>
        <pose>-10.161 1.68349 0 0 -0 3.14159</pose>
        <self_collide>0</self_collide>
        <kinematic>0</kinematic>
        <gravity>1</gravity>
      </link>
      <link name='Wall_26'>
        <collision name='Wall_26_Collision'>
          <geometry>
            <box>
              <size>3.5 0.15 2.5</size>
            </box>
          </geometry>
          <pose>0 0 1.25 0 -0 0</pose>
          <max_contacts>10</max_contacts>
          <surface>
            <contact>
              <ode/>
            </contact>
            <bounce/>
            <friction>
              <ode/>
            </friction>
          </surface>
        </collision>
        <visual name='Wall_26_Visual'>
          <pose>0 0 1.25 0 -0 0</pose>
          <geometry>
            <box>
              <size>3.5 0.15 2.5</size>
            </box>
          </geometry>
          <material>
            <script>
              <uri>file://media/materials/scripts/gazebo.material</uri>
              <name>Gazebo/Bricks</name>
            </script>
            <ambient>1 1 1 1</ambient>
          </material>
        </visual>
        <pose>-10.2217 -0.130783 0 0 0 -1.5708</pose>
        <self_collide>0</self_collide>
        <kinematic>0</kinematic>
        <gravity>1</gravity>
      </link>
      <link name='Wall_29'>
        <collision name='Wall_29_Collision'>
          <geometry>
            <box>
              <size>4 0.15 2.5</size>
            </box>
          </geometry>
          <pose>0 0 1.25 0 -0 0</pose>
          <max_contacts>10</max_contacts>
          <surface>
            <contact>
              <ode/>
            </contact>
            <bounce/>
            <friction>
              <ode/>
            </friction>
          </surface>
        </collision>
        <visual name='Wall_29_Visual'>
          <pose>0 0 1.25 0 -0 0</pose>
          <geometry>
            <box>
              <size>4 0.15 2.5</size>
            </box>
          </geometry>
          <material>
            <script>
              <uri>file://media/materials/scripts/gazebo.material</uri>
              <name>Gazebo/Bricks</name>
            </script>
            <ambient>1 1 1 1</ambient>
          </material>
        </visual>
        <pose>-2.1125 5.12452 0 0 -0 0</pose>
        <self_collide>0</self_collide>
        <kinematic>0</kinematic>
        <gravity>1</gravity>
      </link>
      <link name='Wall_3'>
        <collision name='Wall_3_Collision'>
          <geometry>
            <box>
              <size>17 0.15 2.5</size>
            </box>
          </geometry>
          <pose>0 0 1.25 0 -0 0</pose>
          <max_contacts>10</max_contacts>
          <surface>
            <contact>
              <ode/>
            </contact>
            <bounce/>
            <friction>
              <ode/>
            </friction>
          </surface>
        </collision>
        <visual name='Wall_3_Visual'>
          <pose>0 0 1.25 0 -0 0</pose>
          <geometry>
            <box>
              <size>17 0.15 2.5</size>
            </box>
          </geometry>
          <material>
            <script>
              <uri>file://media/materials/scripts/gazebo.material</uri>
              <name>Gazebo/Bricks</name>
            </script>
            <ambient>1 1 1 1</ambient>
          </material>
        </visual>
        <pose>-16.8 -0 0 0 -0 1.5708</pose>
        <self_collide>0</self_collide>
        <kinematic>0</kinematic>
        <gravity>1</gravity>
      </link>
      <link name='Wall_30'>
        <collision name='Wall_30_Collision'>
          <geometry>
            <box>
              <size>3.5 0.15 2.5</size>
            </box>
          </geometry>
          <pose>0 0 1.25 0 -0 0</pose>
          <max_contacts>10</max_contacts>
          <surface>
            <contact>
              <ode/>
            </contact>
            <bounce/>
            <friction>
              <ode/>
            </friction>
          </surface>
        </collision>
        <visual name='Wall_30_Visual'>
          <pose>0 0 1.25 0 -0 0</pose>
          <geometry>
            <box>
              <size>3.5 0.15 2.5</size>
            </box>
          </geometry>
          <material>
            <script>
              <uri>file://media/materials/scripts/gazebo.material</uri>
              <name>Gazebo/Bricks</name>
            </script>
            <ambient>1 1 1 1</ambient>
          </material>
        </visual>
        <pose>-0.187496 3.44952 0 0 0 -1.5708</pose>
        <self_collide>0</self_collide>
        <kinematic>0</kinematic>
        <gravity>1</gravity>
      </link>
      <link name='Wall_31'>
        <collision name='Wall_31_Collision'>
          <geometry>
            <box>
              <size>3.5 0.15 2.5</size>
            </box>
          </geometry>
          <pose>0 0 1.25 0 -0 0</pose>
          <max_contacts>10</max_contacts>
          <surface>
            <contact>
              <ode/>
            </contact>
            <bounce/>
            <friction>
              <ode/>
            </friction>
          </surface>
        </collision>
        <visual name='Wall_31_Visual'>
          <pose>0 0 1.25 0 -0 0</pose>
          <geometry>
            <box>
              <size>3.5 0.15 2.5</size>
            </box>
          </geometry>
          <material>
            <script>
              <uri>file://media/materials/scripts/gazebo.material</uri>
              <name>Gazebo/Bricks</name>
            </script>
            <ambient>1 1 1 1</ambient>
          </material>
        </visual>
        <pose>1.4875 1.77452 0 0 -0 0</pose>
        <self_collide>0</self_collide>
        <kinematic>0</kinematic>
        <gravity>1</gravity>
      </link>
      <link name='Wall_32'>
        <collision name='Wall_32_Collision'>
          <geometry>
            <box>
              <size>3.5 0.15 2.5</size>
            </box>
          </geometry>
          <pose>0 0 1.25 0 -0 0</pose>
          <max_contacts>10</max_contacts>
          <surface>
            <contact>
              <ode/>
            </contact>
            <bounce/>
            <friction>
              <ode/>
            </friction>
          </surface>
        </collision>
        <visual name='Wall_32_Visual'>
          <pose>0 0 1.25 0 -0 0</pose>
          <geometry>
            <box>
              <size>3.5 0.15 2.5</size>
            </box>
          </geometry>
          <material>
            <script>
              <uri>file://media/materials/scripts/gazebo.material</uri>
              <name>Gazebo/Bricks</name>
            </script>
            <ambient>1 1 1 1</ambient>
          </material>
        </visual>
        <pose>3.1625 0.099524 0 0 0 -1.5708</pose>
        <self_collide>0</self_collide>
        <kinematic>0</kinematic>
        <gravity>1</gravity>
      </link>
      <link name='Wall_33'>
        <collision name='Wall_33_Collision'>
          <geometry>
            <box>
              <size>7 0.15 2.5</size>
            </box>
          </geometry>
          <pose>0 0 1.25 0 -0 0</pose>
          <max_contacts>10</max_contacts>
          <surface>
            <contact>
              <ode/>
            </contact>
            <bounce/>
            <friction>
              <ode/>
            </friction>
          </surface>
        </collision>
        <visual name='Wall_33_Visual'>
          <pose>0 0 1.25 0 -0 0</pose>
          <geometry>
            <box>
              <size>7 0.15 2.5</size>
            </box>
          </geometry>
          <material>
            <script>
              <uri>file://media/materials/scripts/gazebo.material</uri>
              <name>Gazebo/Bricks</name>
            </script>
            <ambient>1 1 1 1</ambient>
          </material>
        </visual>
        <pose>6.5875 -1.57548 0 0 -0 0</pose>
        <self_collide>0</self_collide>
        <kinematic>0</kinematic>
        <gravity>1</gravity>
      </link>
      <link name='Wall_34'>
        <collision name='Wall_34_Collision'>
          <geometry>
            <box>
              <size>6.75 0.15 2.5</size>
            </box>
          </geometry>
          <pose>0 0 1.25 0 -0 0</pose>
          <max_contacts>10</max_contacts>
          <surface>
            <contact>
              <ode/>
            </contact>
            <bounce/>
            <friction>
              <ode/>
            </friction>
          </surface>
        </collision>
        <visual name='Wall_34_Visual'>
          <pose>0 0 1.25 0 -0 0</pose>
          <geometry>
            <box>
              <size>6.75 0.15 2.5</size>
            </box>
          </geometry>
          <material>
            <script>
              <uri>file://media/materials/scripts/gazebo.material</uri>
              <name>Gazebo/Bricks</name>
            </script>
            <ambient>1 1 1 1</ambient>
          </material>
        </visual>
        <pose>10.0125 1.72452 0 0 -0 1.5708</pose>
        <self_collide>0</self_collide>
        <kinematic>0</kinematic>
        <gravity>1</gravity>
      </link>
      <link name='Wall_35'>
        <collision name='Wall_35_Collision'>
          <geometry>
            <box>
              <size>3.5 0.15 2.5</size>
            </box>
          </geometry>
          <pose>0 0 1.25 0 -0 0</pose>
          <max_contacts>10</max_contacts>
          <surface>
            <contact>
              <ode/>
            </contact>
            <bounce/>
            <friction>
              <ode/>
            </friction>
          </surface>
        </collision>
        <visual name='Wall_35_Visual'>
          <pose>0 0 1.25 0 -0 0</pose>
          <geometry>
            <box>
              <size>3.5 0.15 2.5</size>
            </box>
          </geometry>
          <material>
            <script>
              <uri>file://media/materials/scripts/gazebo.material</uri>
              <name>Gazebo/Bricks</name>
            </script>
            <ambient>1 1 1 1</ambient>
          </material>
        </visual>
        <pose>8.3375 5.02452 0 0 -0 3.14159</pose>
        <self_collide>0</self_collide>
        <kinematic>0</kinematic>
        <gravity>1</gravity>
      </link>
      <link name='Wall_36'>
        <collision name='Wall_36_Collision'>
          <geometry>
            <box>
              <size>4 0.15 2.5</size>
            </box>
          </geometry>
          <pose>0 0 1.25 0 -0 0</pose>
          <max_contacts>10</max_contacts>
          <surface>
            <contact>
              <ode/>
            </contact>
            <bounce/>
            <friction>
              <ode/>
            </friction>
          </surface>
        </collision>
        <visual name='Wall_36_Visual'>
          <pose>0 0 1.25 0 -0 0</pose>
          <geometry>
            <box>
              <size>4 0.15 2.5</size>
            </box>
          </geometry>
          <material>
            <script>
              <uri>file://media/materials/scripts/gazebo.material</uri>
              <name>Gazebo/Bricks</name>
            </script>
            <ambient>1 1 1 1</ambient>
          </material>
        </visual>
        <pose>6.6625 3.09952 0 0 0 -1.5708</pose>
        <self_collide>0</self_collide>
        <kinematic>0</kinematic>
        <gravity>1</gravity>
      </link>
      <link name='Wall_38'>
        <collision name='Wall_38_Collision'>
          <geometry>
            <box>
              <size>4 0.15 2.5</size>
            </box>
          </geometry>
          <pose>0 0 1.25 0 -0 0</pose>
          <max_contacts>10</max_contacts>
          <surface>
            <contact>
              <ode/>
            </contact>
            <bounce/>
            <friction>
              <ode/>
            </friction>
          </surface>
        </collision>
        <visual name='Wall_38_Visual'>
          <pose>0 0 1.25 0 -0 0</pose>
          <geometry>
            <box>
              <size>4 0.15 2.5</size>
            </box>
          </geometry>
          <material>
            <script>
              <uri>file://media/materials/scripts/gazebo.material</uri>
              <name>Gazebo/Bricks</name>
            </script>
            <ambient>1 1 1 1</ambient>
          </material>
        </visual>
        <pose>11.9375 5.02452 0 0 -0 0</pose>
        <self_collide>0</self_collide>
        <kinematic>0</kinematic>
        <gravity>1</gravity>
      </link>
      <link name='Wall_41'>
        <collision name='Wall_41_Collision'>
          <geometry>
            <box>
              <size>3.25 0.15 2.5</size>
            </box>
          </geometry>
          <pose>0 0 1.25 0 -0 0</pose>
          <max_contacts>10</max_contacts>
          <surface>
            <contact>
              <ode/>
            </contact>
            <bounce/>
            <friction>
              <ode/>
            </friction>
          </surface>
        </collision>
        <visual name='Wall_41_Visual'>
          <pose>0 0 1.25 0 -0 0</pose>
          <geometry>
            <box>
              <size>3.25 0.15 2.5</size>
            </box>
          </geometry>
          <material>
            <script>
              <uri>file://media/materials/scripts/gazebo.material</uri>
              <name>Gazebo/Bricks</name>
            </script>
            <ambient>1 1 1 1</ambient>
          </material>
        </visual>
        <pose>15.0806 1.54422 0 0 -0 3.14159</pose>
        <self_collide>0</self_collide>
        <kinematic>0</kinematic>
        <gravity>1</gravity>
      </link>
      <link name='Wall_42'>
        <collision name='Wall_42_Collision'>
          <geometry>
            <box>
              <size>4.25 0.15 2.5</size>
            </box>
          </geometry>
          <pose>0 0 1.25 0 -0 0</pose>
          <max_contacts>10</max_contacts>
          <surface>
            <contact>
              <ode/>
            </contact>
            <bounce/>
            <friction>
              <ode/>
            </friction>
          </surface>
        </collision>
        <visual name='Wall_42_Visual'>
          <pose>0 0 1.25 0 -0 0</pose>
          <geometry>
            <box>
              <size>4.25 0.15 2.5</size>
            </box>
          </geometry>
          <material>
            <script>
              <uri>file://media/materials/scripts/gazebo.material</uri>
              <name>Gazebo/Bricks</name>
            </script>
            <ambient>1 1 1 1</ambient>
          </material>
        </visual>
        <pose>13.5306 -0.505783 0 0 0 -1.5708</pose>
        <self_collide>0</self_collide>
        <kinematic>0</kinematic>
        <gravity>1</gravity>
      </link>
      <link name='Wall_44'>
        <collision name='Wall_44_Collision'>
          <geometry>
            <box>
              <size>7 0.15 2.5</size>
            </box>
          </geometry>
          <pose>0 0 1.25 0 -0 0</pose>
          <max_contacts>10</max_contacts>
          <surface>
            <contact>
              <ode/>
            </contact>
            <bounce/>
            <friction>
              <ode/>
            </friction>
          </surface>
        </collision>
        <visual name='Wall_44_Visual'>
          <pose>0 0 1.25 0 -0 0</pose>
          <geometry>
            <box>
              <size>7 0.15 2.5</size>
            </box>
          </geometry>
          <material>
            <script>
              <uri>file://media/materials/scripts/gazebo.material</uri>
              <name>Gazebo/Bricks</name>
            </script>
            <ambient>1 1 1 1</ambient>
          </material>
        </visual>
        <pose>13.287 -5.12817 0 0 -0 3.14159</pose>
        <self_collide>0</self_collide>
        <kinematic>0</kinematic>
        <gravity>1</gravity>
      </link>
      <link name='Wall_46'>
        <collision name='Wall_46_Collision'>
          <geometry>
            <box>
              <size>3.25 0.15 2.5</size>
            </box>
          </geometry>
          <pose>0 0 1.25 0 -0 0</pose>
          <max_contacts>10</max_contacts>
          <surface>
            <contact>
              <ode/>
            </contact>
            <bounce/>
            <friction>
              <ode/>
            </friction>
          </surface>
        </collision>
        <visual name='Wall_46_Visual'>
          <pose>0 0 1.25 0 -0 0</pose>
          <geometry>
            <box>
              <size>3.25 0.15 2.5</size>
            </box>
          </geometry>
          <material>
            <script>
              <uri>file://media/materials/scripts/gazebo.material</uri>
              <name>Gazebo/Bricks</name>
            </script>
            <ambient>1 1 1 1</ambient>
          </material>
        </visual>
        <pose>6.62205 -3.26061 0 0 0 -1.5708</pose>
        <self_collide>0</self_collide>
        <kinematic>0</kinematic>
        <gravity>1</gravity>
      </link>
      <link name='Wall_47'>
        <collision name='Wall_47_Collision'>
          <geometry>
            <box>
              <size>7 0.15 2.5</size>
            </box>
          </geometry>
          <pose>0 0 1.25 0 -0 0</pose>
          <max_contacts>10</max_contacts>
          <surface>
            <contact>
              <ode/>
            </contact>
            <bounce/>
            <friction>
              <ode/>
            </friction>
          </surface>
        </collision>
        <visual name='Wall_47_Visual'>
          <pose>0 0 1.25 0 -0 0</pose>
          <geometry>
            <box>
              <size>7 0.15 2.5</size>
            </box>
          </geometry>
          <material>
            <script>
              <uri>file://media/materials/scripts/gazebo.material</uri>
              <name>Gazebo/Bricks</name>
            </script>
            <ambient>1 1 1 1</ambient>
          </material>
        </visual>
        <pose>3.19706 -4.81061 0 0 -0 3.14159</pose>
        <self_collide>0</self_collide>
        <kinematic>0</kinematic>
        <gravity>1</gravity>
      </link>
      <link name='Wall_48'>
        <collision name='Wall_48_Collision'>
          <geometry>
            <box>
              <size>3.5 0.15 2.5</size>
            </box>
          </geometry>
          <pose>0 0 1.25 0 -0 0</pose>
          <max_contacts>10</max_contacts>
          <surface>
            <contact>
              <ode/>
            </contact>
            <bounce/>
            <friction>
              <ode/>
            </friction>
          </surface>
        </collision>
        <visual name='Wall_48_Visual'>
          <pose>0 0 1.25 0 -0 0</pose>
          <geometry>
            <box>
              <size>3.5 0.15 2.5</size>
            </box>
          </geometry>
          <material>
            <script>
              <uri>file://media/materials/scripts/gazebo.material</uri>
              <name>Gazebo/Bricks</name>
            </script>
            <ambient>1 1 1 1</ambient>
          </material>
        </visual>
        <pose>-0.227945 -3.13561 0 0 -0 1.5708</pose>
        <self_collide>0</self_collide>
        <kinematic>0</kinematic>
        <gravity>1</gravity>
      </link>
      <link name='Wall_5'>
        <collision name='Wall_5_Collision'>
          <geometry>
            <box>
              <size>6.75 0.15 2.5</size>
            </box>
          </geometry>
          <pose>0 0 1.25 0 -0 0</pose>
          <max_contacts>10</max_contacts>
          <surface>
            <contact>
              <ode/>
            </contact>
            <bounce/>
            <friction>
              <ode/>
            </friction>
          </surface>
        </collision>
        <visual name='Wall_5_Visual'>
          <pose>0 0 1.25 0 -0 0</pose>
          <geometry>
            <box>
              <size>6.75 0.15 2.5</size>
            </box>
          </geometry>
          <material>
            <script>
              <uri>file://media/materials/scripts/gazebo.material</uri>
              <name>Gazebo/Bricks</name>
            </script>
            <ambient>1 1 1 1</ambient>
          </material>
        </visual>
        <pose>-6.86098 4.98349 0 0 0 -1.5708</pose>
        <self_collide>0</self_collide>
        <kinematic>0</kinematic>
        <gravity>1</gravity>
      </link>
      <link name='Wall_50'>
        <collision name='Wall_50_Collision'>
          <geometry>
            <box>
              <size>3.75 0.15 2.5</size>
            </box>
          </geometry>
          <pose>0 0 1.25 0 -0 0</pose>
          <max_contacts>10</max_contacts>
          <surface>
            <contact>
              <ode/>
            </contact>
            <bounce/>
            <friction>
              <ode/>
            </friction>
          </surface>
        </collision>
        <visual name='Wall_50_Visual'>
          <pose>0 0 1.25 0 -0 0</pose>
          <geometry>
            <box>
              <size>3.75 0.15 2.5</size>
            </box>
          </geometry>
          <material>
            <script>
              <uri>file://media/materials/scripts/gazebo.material</uri>
              <name>Gazebo/Bricks</name>
            </script>
            <ambient>1 1 1 1</ambient>
          </material>
        </visual>
        <pose>3.23508 -6.59091 0 0 0 -1.5708</pose>
        <self_collide>0</self_collide>
        <kinematic>0</kinematic>
        <gravity>1</gravity>
      </link>
      <link name='Wall_52'>
        <pose>0 8.425 0 0 -0 0</pose>
        <visual name='Wall_52_Visual_0'>
          <pose>-16.7685 0 1.25 0 -0 0</pose>
          <geometry>
            <box>
              <size>0.212903 0.15 2.5</size>
            </box>
          </geometry>
          <material>
            <script>
              <uri>file://media/materials/scripts/gazebo.material</uri>
              <name>Gazebo/Bricks</name>
            </script>
            <ambient>1 1 1 1</ambient>
          </material>
        </visual>
        <collision name='Wall_52_Collision_0'>
          <geometry>
            <box>
              <size>0.212903 0.15 2.5</size>
            </box>
          </geometry>
          <pose>-16.7685 0 1.25 0 -0 0</pose>
          <max_contacts>10</max_contacts>
          <surface>
            <contact>
              <ode/>
            </contact>
            <bounce/>
            <friction>
              <ode/>
            </friction>
          </surface>
        </collision>
        <visual name='Wall_52_Visual_1'>
          <pose>1.45886 0 1.25 0 -0 0</pose>
          <geometry>
            <box>
              <size>30.8323 0.15 2.5</size>
            </box>
          </geometry>
          <material>
            <script>
              <uri>file://media/materials/scripts/gazebo.material</uri>
              <name>Gazebo/Bricks</name>
            </script>
            <ambient>1 1 1 1</ambient>
          </material>
        </visual>
        <collision name='Wall_52_Collision_1'>
          <geometry>
            <box>
              <size>30.8323 0.15 2.5</size>
            </box>
          </geometry>
          <pose>1.45886 0 1.25 0 -0 0</pose>
          <max_contacts>10</max_contacts>
          <surface>
            <contact>
              <ode/>
            </contact>
            <bounce/>
            <friction>
              <ode/>
            </friction>
          </surface>
        </collision>
        <visual name='Wall_52_Visual_2'>
          <pose>-15.3097 0 2.25 0 -0 0</pose>
          <geometry>
            <box>
              <size>2.70482 0.15 0.5</size>
            </box>
          </geometry>
          <material>
            <script>
              <uri>file://media/materials/scripts/gazebo.material</uri>
              <name>Gazebo/Bricks</name>
            </script>
            <ambient>1 1 1 1</ambient>
          </material>
        </visual>
        <collision name='Wall_52_Collision_2'>
          <geometry>
            <box>
              <size>2.70482 0.15 0.5</size>
            </box>
          </geometry>
          <pose>-15.3097 0 2.25 0 -0 0</pose>
          <max_contacts>10</max_contacts>
          <surface>
            <contact>
              <ode/>
            </contact>
            <bounce/>
            <friction>
              <ode/>
            </friction>
          </surface>
        </collision>
        <self_collide>0</self_collide>
        <kinematic>0</kinematic>
        <gravity>1</gravity>
      </link>
      <link name='Wall_6'>
        <collision name='Wall_6_Collision'>
          <geometry>
            <box>
              <size>3.25 0.15 2.5</size>
            </box>
          </geometry>
          <pose>0 0 1.25 0 -0 0</pose>
          <max_contacts>10</max_contacts>
          <surface>
            <contact>
              <ode/>
            </contact>
            <bounce/>
            <friction>
              <ode/>
            </friction>
          </surface>
        </collision>
        <visual name='Wall_6_Visual'>
          <pose>0 0 1.25 0 -0 0</pose>
          <geometry>
            <box>
              <size>3.25 0.15 2.5</size>
            </box>
          </geometry>
          <material>
            <script>
              <uri>file://media/materials/scripts/gazebo.material</uri>
              <name>Gazebo/Bricks</name>
            </script>
            <ambient>1 1 1 1</ambient>
          </material>
        </visual>
        <pose>-5.31098 1.68349 0 0 -0 0</pose>
        <self_collide>0</self_collide>
        <kinematic>0</kinematic>
        <gravity>1</gravity>
      </link>
      <link name='Wall_7'>
        <collision name='Wall_7_Collision'>
          <geometry>
            <box>
              <size>3.5 0.15 2.5</size>
            </box>
          </geometry>
          <pose>0 0 1.25 0 -0 0</pose>
          <max_contacts>10</max_contacts>
          <surface>
            <contact>
              <ode/>
            </contact>
            <bounce/>
            <friction>
              <ode/>
            </friction>
          </surface>
        </collision>
        <visual name='Wall_7_Visual'>
          <pose>0 0 1.25 0 -0 0</pose>
          <geometry>
            <box>
              <size>3.5 0.15 2.5</size>
            </box>
          </geometry>
          <material>
            <script>
              <uri>file://media/materials/scripts/gazebo.material</uri>
              <name>Gazebo/Bricks</name>
            </script>
            <ambient>1 1 1 1</ambient>
          </material>
        </visual>
        <pose>-3.76098 0.008486 0 0 0 -1.5708</pose>
        <self_collide>0</self_collide>
        <kinematic>0</kinematic>
        <gravity>1</gravity>
      </link>
      <link name='Wall_8'>
        <collision name='Wall_8_Collision'>
          <geometry>
            <box>
              <size>3 0.15 2.5</size>
            </box>
          </geometry>
          <pose>0 0 1.25 0 -0 0</pose>
          <max_contacts>10</max_contacts>
          <surface>
            <contact>
              <ode/>
            </contact>
            <bounce/>
            <friction>
              <ode/>
            </friction>
          </surface>
        </collision>
        <visual name='Wall_8_Visual'>
          <pose>0 0 1.25 0 -0 0</pose>
          <geometry>
            <box>
              <size>3 0.15 2.5</size>
            </box>
          </geometry>
          <material>
            <script>
              <uri>file://media/materials/scripts/gazebo.material</uri>
              <name>Gazebo/Bricks</name>
            </script>
            <ambient>1 1 1 1</ambient>
          </material>
        </visual>
        <pose>-5.18598 -1.66651 0 0 -0 3.14159</pose>
        <self_collide>0</self_collide>
        <kinematic>0</kinematic>
        <gravity>1</gravity>
      </link>
      <link name='Wall_9'>
        <collision name='Wall_9_Collision'>
          <geometry>
            <box>
              <size>3.25 0.15 2.5</size>
            </box>
          </geometry>
          <pose>0 0 1.25 0 -0 0</pose>
          <max_contacts>10</max_contacts>
          <surface>
            <contact>
              <ode/>
            </contact>
            <bounce/>
            <friction>
              <ode/>
            </friction>
          </surface>
        </collision>
        <visual name='Wall_9_Visual'>
          <pose>0 0 1.25 0 -0 0</pose>
          <geometry>
            <box>
              <size>3.25 0.15 2.5</size>
            </box>
          </geometry>
          <material>
            <script>
              <uri>file://media/materials/scripts/gazebo.material</uri>
              <name>Gazebo/Bricks</name>
            </script>
            <ambient>1 1 1 1</ambient>
          </material>
        </visual>
        <pose>-6.61098 -3.21651 0 0 0 -1.5708</pose>
        <self_collide>0</self_collide>
        <kinematic>0</kinematic>
        <gravity>1</gravity>
      </link>
      <static>1</static>
    </model>
    <state world_name='default'>
      <sim_time>484 944000000</sim_time>
      <real_time>46 20344280</real_time>
      <wall_time>1448158676 817435637</wall_time>
      <model name='Simple_Maze'>
        <pose>-0 -2 0 0 -0 0</pose>
        <link name='Wall_1'>
          <pose>16.8 -2 0 0 0 -1.5708</pose>
          <velocity>0 0 0 0 -0 0</velocity>
          <acceleration>0 0 0 0 -0 0</acceleration>
          <wrench>0 0 0 0 -0 0</wrench>
        </link>
        <link name='Wall_10'>
          <pose>-10.161 -6.76651 0 0 -0 3.14159</pose>
          <velocity>0 0 0 0 -0 0</velocity>
          <acceleration>0 0 0 0 -0 0</acceleration>
          <wrench>0 0 0 0 -0 0</wrench>
        </link>
        <link name='Wall_16'>
          <pose>-3.5354 -8.66942 0 0 -0 1.5708</pose>
          <velocity>0 0 0 0 -0 0</velocity>
          <acceleration>0 0 0 0 -0 0</acceleration>
          <wrench>0 0 0 0 -0 0</wrench>
        </link>
        <link name='Wall_19'>
          <pose>-15.1813 -3.62924 0 0 -0 0</pose>
          <velocity>0 0 0 0 -0 0</velocity>
          <acceleration>0 0 0 0 -0 0</acceleration>
          <wrench>0 0 0 0 -0 0</wrench>
        </link>
        <link name='Wall_2'>
          <pose>-0 -10.425 0 0 -0 3.14159</pose>
          <velocity>0 0 0 0 -0 0</velocity>
          <acceleration>0 0 0 0 -0 0</acceleration>
          <wrench>0 0 0 0 -0 0</wrench>
        </link>
        <link name='Wall_21'>
          <pose>-11.8153 3.20589 0 0 -0 3.14159</pose>
          <velocity>0 0 0 0 -0 0</velocity>
          <acceleration>0 0 0 0 -0 0</acceleration>
          <wrench>0 0 0 0 -0 0</wrench>
        </link>
        <link name='Wall_22'>
          <pose>-13.4903 1.5309 0 0 0 -1.5708</pose>
          <velocity>0 0 0 0 -0 0</velocity>
          <acceleration>0 0 0 0 -0 0</acceleration>
          <wrench>0 0 0 0 -0 0</wrench>
        </link>
        <link name='Wall_24'>
          <pose>-10.161 -0.31651 0 0 -0 3.14159</pose>
          <velocity>0 0 0 0 -0 0</velocity>
          <acceleration>0 0 0 0 -0 0</acceleration>
          <wrench>0 0 0 0 -0 0</wrench>
        </link>
        <link name='Wall_26'>
          <pose>-10.2217 -2.13078 0 0 0 -1.5708</pose>
          <velocity>0 0 0 0 -0 0</velocity>
          <acceleration>0 0 0 0 -0 0</acceleration>
          <wrench>0 0 0 0 -0 0</wrench>
        </link>
        <link name='Wall_29'>
          <pose>-2.1125 3.12452 0 0 -0 0</pose>
          <velocity>0 0 0 0 -0 0</velocity>
          <acceleration>0 0 0 0 -0 0</acceleration>
          <wrench>0 0 0 0 -0 0</wrench>
        </link>
        <link name='Wall_3'>
          <pose>-16.8 -2 0 0 -0 1.5708</pose>
          <velocity>0 0 0 0 -0 0</velocity>
          <acceleration>0 0 0 0 -0 0</acceleration>
          <wrench>0 0 0 0 -0 0</wrench>
        </link>
        <link name='Wall_30'>
          <pose>-0.187496 1.44952 0 0 0 -1.5708</pose>
          <velocity>0 0 0 0 -0 0</velocity>
          <acceleration>0 0 0 0 -0 0</acceleration>
          <wrench>0 0 0 0 -0 0</wrench>
        </link>
        <link name='Wall_31'>
          <pose>1.4875 -0.22548 0 0 -0 0</pose>
          <velocity>0 0 0 0 -0 0</velocity>
          <acceleration>0 0 0 0 -0 0</acceleration>
          <wrench>0 0 0 0 -0 0</wrench>
        </link>
        <link name='Wall_32'>
          <pose>3.1625 -1.90048 0 0 0 -1.5708</pose>
          <velocity>0 0 0 0 -0 0</velocity>
          <acceleration>0 0 0 0 -0 0</acceleration>
          <wrench>0 0 0 0 -0 0</wrench>
        </link>
        <link name='Wall_33'>
          <pose>6.5875 -3.57548 0 0 -0 0</pose>
          <velocity>0 0 0 0 -0 0</velocity>
          <acceleration>0 0 0 0 -0 0</acceleration>
          <wrench>0 0 0 0 -0 0</wrench>
        </link>
        <link name='Wall_34'>
          <pose>10.0125 -0.27548 0 0 -0 1.5708</pose>
          <velocity>0 0 0 0 -0 0</velocity>
          <acceleration>0 0 0 0 -0 0</acceleration>
          <wrench>0 0 0 0 -0 0</wrench>
        </link>
        <link name='Wall_35'>
          <pose>8.3375 3.02452 0 0 -0 3.14159</pose>
          <velocity>0 0 0 0 -0 0</velocity>
          <acceleration>0 0 0 0 -0 0</acceleration>
          <wrench>0 0 0 0 -0 0</wrench>
        </link>
        <link name='Wall_36'>
          <pose>6.6625 1.09952 0 0 0 -1.5708</pose>
          <velocity>0 0 0 0 -0 0</velocity>
          <acceleration>0 0 0 0 -0 0</acceleration>
          <wrench>0 0 0 0 -0 0</wrench>
        </link>
        <link name='Wall_38'>
          <pose>11.9375 3.02452 0 0 -0 0</pose>
          <velocity>0 0 0 0 -0 0</velocity>
          <acceleration>0 0 0 0 -0 0</acceleration>
          <wrench>0 0 0 0 -0 0</wrench>
        </link>
        <link name='Wall_41'>
          <pose>15.0806 -0.45578 0 0 -0 3.14159</pose>
          <velocity>0 0 0 0 -0 0</velocity>
          <acceleration>0 0 0 0 -0 0</acceleration>
          <wrench>0 0 0 0 -0 0</wrench>
        </link>
        <link name='Wall_42'>
          <pose>13.5306 -2.50578 0 0 0 -1.5708</pose>
          <velocity>0 0 0 0 -0 0</velocity>
          <acceleration>0 0 0 0 -0 0</acceleration>
          <wrench>0 0 0 0 -0 0</wrench>
        </link>
        <link name='Wall_44'>
          <pose>13.287 -7.12817 0 0 -0 3.14159</pose>
          <velocity>0 0 0 0 -0 0</velocity>
          <acceleration>0 0 0 0 -0 0</acceleration>
          <wrench>0 0 0 0 -0 0</wrench>
        </link>
        <link name='Wall_46'>
          <pose>6.62205 -5.26061 0 0 0 -1.5708</pose>
          <velocity>0 0 0 0 -0 0</velocity>
          <acceleration>0 0 0 0 -0 0</acceleration>
          <wrench>0 0 0 0 -0 0</wrench>
        </link>
        <link name='Wall_47'>
          <pose>3.19706 -6.81061 0 0 -0 3.14159</pose>
          <velocity>0 0 0 0 -0 0</velocity>
          <acceleration>0 0 0 0 -0 0</acceleration>
          <wrench>0 0 0 0 -0 0</wrench>
        </link>
        <link name='Wall_48'>
          <pose>-0.227945 -5.13561 0 0 -0 1.5708</pose>
          <velocity>0 0 0 0 -0 0</velocity>
          <acceleration>0 0 0 0 -0 0</acceleration>
          <wrench>0 0 0 0 -0 0</wrench>
        </link>
        <link name='Wall_5'>
          <pose>-6.86098 2.98349 0 0 0 -1.5708</pose>
          <velocity>0 0 0 0 -0 0</velocity>
          <acceleration>0 0 0 0 -0 0</acceleration>
          <wrench>0 0 0 0 -0 0</wrench>
        </link>
        <link name='Wall_50'>
          <pose>3.23508 -8.59091 0 0 0 -1.5708</pose>
          <velocity>0 0 0 0 -0 0</velocity>
          <acceleration>0 0 0 0 -0 0</acceleration>
          <wrench>0 0 0 0 -0 0</wrench>
        </link>
        <link name='Wall_52'>
          <pose>-0 6.425 0 0 -0 0</pose>
          <velocity>0 0 0 0 -0 0</velocity>
          <acceleration>0 0 0 0 -0 0</acceleration>
          <wrench>0 0 0 0 -0 0</wrench>
        </link>
        <link name='Wall_6'>
          <pose>-5.31098 -0.31651 0 0 -0 0</pose>
          <velocity>0 0 0 0 -0 0</velocity>
          <acceleration>0 0 0 0 -0 0</acceleration>
          <wrench>0 0 0 0 -0 0</wrench>
        </link>
        <link name='Wall_7'>
          <pose>-3.76098 -1.99151 0 0 0 -1.5708</pose>
          <velocity>0 0 0 0 -0 0</velocity>
          <acceleration>0 0 0 0 -0 0</acceleration>
          <wrench>0 0 0 0 -0 0</wrench>
        </link>
        <link name='Wall_8'>
          <pose>-5.18598 -3.66651 0 0 -0 3.14159</pose>
          <velocity>0 0 0 0 -0 0</velocity>
          <acceleration>0 0 0 0 -0 0</acceleration>
          <wrench>0 0 0 0 -0 0</wrench>
        </link>
        <link name='Wall_9'>
          <pose>-6.61098 -5.21651 0 0 0 -1.5708</pose>
          <velocity>0 0 0 0 -0 0</velocity>
          <acceleration>0 0 0 0 -0 0</acceleration>
          <wrench>0 0 0 0 -0 0</wrench>
        </link>
      </model>
      <model name='ground_plane'>
        <pose>0 0 0 0 -0 0</pose>
        <link name='link'>
          <pose>0 0 0 0 -0 0</pose>
          <velocity>0 0 0 0 -0 0</velocity>
          <acceleration>0 0 0 0 -0 0</acceleration>
          <wrench>0 0 0 0 -0 0</wrench>
        </link>
      </model>
      <model name='youbot'>
        <pose>15 -11.0001 0.083972 8e-06 2.2e-05 1.5984</pose>
        <link name='arm_link_0'>
          <pose>14.9961 -10.8571 0.129967 1.2e-05 2.4e-05 1.5984</pose>
          <velocity>2e-06 7.1e-05 -0.001681 -0.000577 5.3e-05 0.00076</velocity>
          <acceleration>0.001576 0.055248 -0.37303 0.009006 -0.002753 0.033204</acceleration>
          <wrench>0.001332 0.046685 -0.31521 0 -0 0</wrench>
        </link>
        <link name='arm_link_1'>
          <pose>14.9954 -10.8331 0.225966 -1.9e-05 -3.1e-05 -1.72316</pose>
          <velocity>4.8e-05 8.9e-05 -0.001658 -0.000694 -0.001215 0.006356</velocity>
          <acceleration>-0.010829 -0.13573 -0.300794 -0.002515 0.004656 0.027221</acceleration>
          <wrench>-0.02612 -0.32738 -0.725514 0 -0 0</wrench>
        </link>
        <link name='arm_link_2'>
          <pose>14.9904 -10.8657 0.244966 -7.3e-05 -1.1345 -1.72311</pose>
          <velocity>0.0003 0.000113 -0.001477 0.002396 -0.003568 0.009184</velocity>
          <acceleration>0.779341 0.011413 -0.160436 0.003106 0.003208 0.027912</acceleration>
          <wrench>0.900139 0.013182 -0.185304 0 -0 0</wrench>
        </link>
        <link name='arm_link_3'>
          <pose>15.0117 -10.7269 0.310451 0.000431 1.41372 -1.72274</pose>
          <velocity>-0.000117 4e-05 0.001453 0.053695 0.005476 0.007062</velocity>
          <acceleration>-0.077155 0.476437 -2.30267 0.148864 0.008015 0.002587</acceleration>
          <wrench>-0.072063 0.444992 -2.15069 0 -0 0</wrench>
        </link>
        <link name='arm_link_4'>
          <pose>14.9915 -10.8587 0.331569 9.8e-05 -0.375249 -1.7232</pose>
          <velocity>0.00086 -0.001331 -0.004629 -0.001639 0.019168 0.007126</velocity>
          <acceleration>0.134406 -1.21169 -9.83259 0.015026 0.018263 0.008148</acceleration>
          <wrench>0.117874 -1.06266 -8.62318 0 -0 0</wrench>
        </link>
        <link name='arm_link_5'>
          <pose>14.999 -10.8098 0.451791 -0.09752 0.362936 1.1498</pose>
          <velocity>0.00301 -0.000814 -0.004717 -0.004385 0.008151 -0.003187</velocity>
          <acceleration>1.45514 -1.28081 -9.21922 -0.001785 -8.7e-05 -0.0205</acceleration>
          <wrench>0.365239 -0.321484 -2.31402 0 -0 0</wrench>
        </link>
        <link name='base_footprint'>
          <pose>15 -11.0001 0.083972 8e-06 2.2e-05 1.5984</pose>
          <velocity>-5.9e-05 3.5e-05 -0.001723 -0.000111 0.00045 -0.000187</velocity>
          <acceleration>0.129673 0.190341 -0.566411 1.3695 -0.25168 -2.20236</acceleration>
          <wrench>0.012967 0.019034 -0.056641 0 -0 0</wrench>
        </link>
        <link name='base_laser_front_link'>
          <pose>14.9917 -10.7002 0.053966 8e-06 2.2e-05 1.5984</pose>
          <velocity>-1.7e-05 3.3e-05 -0.001752 -0.000106 0.000447 -0.000201</velocity>
          <acceleration>-0.021808 0.146095 0.040092 1.27296 -0.807558 0.238422</acceleration>
          <wrench>-0.003489 0.023375 0.006415 0 -0 0</wrench>
        </link>
        <link name='base_link'>
          <pose>15 -11.0001 0.083972 8e-06 2.2e-05 1.5984</pose>
          <velocity>-5.9e-05 3.6e-05 -0.001727 -0.000119 0.000456 -0.00019</velocity>
          <acceleration>0.067159 0.091162 -0.572002 0.539894 -0.328213 0.186269</acceleration>
          <wrench>1.4775 2.00556 -12.584 0 -0 0</wrench>
        </link>
        <link name='caster_link_bl'>
          <pose>14.8483 -11.2323 0.049995 9e-06 2.2e-05 1.59844</pose>
          <velocity>-0.000147 6e-05 -0.006163 -9.9e-05 0.000383 0</velocity>
          <acceleration>-0.064169 0.039535 -6.57023 0.25294 -0.205989 0.019194</acceleration>
          <wrench>-0.006417 0.003953 -0.657023 0 -0 0</wrench>
        </link>
        <link name='caster_link_br'>
          <pose>15.1642 -11.2236 0.049998 9e-06 2.2e-05 1.59849</pose>
          <velocity>-3.3e-05 -7e-05 0.000638 -0.000133 0.000506 -8e-06</velocity>
          <acceleration>0.046316 0.060101 0.134172 0.22686 -0.188572 0.014359</acceleration>
          <wrench>0.004632 0.00601 0.013417 0 -0 0</wrench>
        </link>
        <link name='caster_link_fl'>
          <pose>14.8358 -10.7765 0.049998 9e-06 2.2e-05 1.5986</pose>
          <velocity>2e-06 4.8e-05 0.000756 -0.000122 0.000526 2.9e-05</velocity>
          <acceleration>-0.02805 0.022145 0.076636 0.25007 -0.198133 0.0179</acceleration>
          <wrench>-0.002805 0.002214 0.007664 0 -0 0</wrench>
        </link>
        <link name='caster_link_fr'>
          <pose>15.1516 -10.7678 0.049994 9e-06 2.2e-05 1.59868</pose>
          <velocity>5e-06 -2.9e-05 0.000809 -0.000135 0.000521 -3.5e-05</velocity>
          <acceleration>0.029293 0.183388 9.52259 0.23959 -0.174084 0.013748</acceleration>
          <wrench>0.002929 0.018339 0.952259 0 -0 0</wrench>
        </link>
        <link name='gripper_finger_link_l'>
          <pose>14.9851 -10.7824 0.491395 0.09752 -0.362937 -1.99179</pose>
          <velocity>0.004449 -0.00096 -0.004673 -0.004107 0.009064 -0.00485</velocity>
          <acceleration>7.24979 -3.23889 -8.55347 0.606478 1.4259 0.983585</acceleration>
          <wrench>0.072498 -0.032389 -0.085535 0 -0 0</wrench>
        </link>
        <link name='gripper_finger_link_r'>
          <pose>15.0104 -10.7927 0.493898 -0.09752 0.362937 1.1498</pose>
          <velocity>0.004422 -0.001074 -0.004872 -0.004083 0.009148 -0.004885</velocity>
          <acceleration>7.22884 -3.38794 -8.9445 0.601916 1.39224 0.996932</acceleration>
          <wrench>0.072288 -0.033879 -0.089445 0 -0 0</wrench>
        </link>
        <link name='gripper_palm_link'>
          <pose>14.999 -10.8098 0.451791 -0.09752 0.362937 1.1498</pose>
          <velocity>0.003169 -0.000865 -0.004738 -0.00412 0.009024 -0.004834</velocity>
          <acceleration>1.65024 -1.29322 -9.24975 0.061266 1.40168 -0.531049</acceleration>
          <wrench>0.165024 -0.129322 -0.924975 0 -0 0</wrench>
        </link>
        <link name='plate_link'>
          <pose>15.0044 -11.159 0.129975 8e-06 2.2e-05 1.5984</pose>
          <velocity>-6.9e-05 4.1e-05 -0.00172 -0.000143 0.000474 -0.000198</velocity>
          <acceleration>0.073875 0.001835 -0.897687 0.019631 -0.012375 0.003965</acceleration>
          <wrench>0.073875 0.001835 -0.897687 0 -0 0</wrench>
        </link>
        <link name='wheel_link_bl'>
          <pose>14.8483 -11.2323 0.049994 9e-06 -0.003155 1.59844</pose>
          <velocity>-0.000155 6.2e-05 -0.005839 -0.001006 0.000313 3e-06</velocity>
          <acceleration>-0.21985 0.012263 -6.20379 0.004343 -0.04028 0.000759</acceleration>
          <wrench>-0.08794 0.004905 -2.48152 0 -0 0</wrench>
        </link>
        <link name='wheel_link_br'>
          <pose>15.1642 -11.2236 0.049997 9e-06 -0.002593 1.59849</pose>
          <velocity>2.3e-05 -0.000107 0.00051 0.002147 0.000486 -1e-06</velocity>
          <acceleration>-0.04776 -0.029451 0.089198 0.028661 -0.039292 0.001004</acceleration>
          <wrench>-0.019104 -0.01178 0.035679 0 -0 0</wrench>
        </link>
        <link name='wheel_link_fl'>
          <pose>14.8358 -10.7765 0.049997 8e-06 0.002314 1.5986</pose>
          <velocity>2.2e-05 4e-05 0.000629 -0.000803 0.000486 3e-05</velocity>
          <acceleration>-0.059564 -0.014817 0.056408 0.013922 -0.046421 0.001019</acceleration>
          <wrench>-0.023826 -0.005927 0.022563 0 -0 0</wrench>
        </link>
        <link name='wheel_link_fr'>
          <pose>15.1516 -10.7678 0.049993 9e-06 0.003348 1.59868</pose>
          <velocity>2.6e-05 -4.3e-05 0.000659 0.000859 0.000529 -3.4e-05</velocity>
          <acceleration>0.033446 0.172277 8.95578 0.039179 -0.039816 0.00096</acceleration>
          <wrench>0.013378 0.068911 3.58231 0 -0 0</wrench>
        </link>
      </model>
    </state>
    <gui fullscreen='0'>
      <camera name='user_camera'>
        <pose>16.7588 -13.4391 3.78274 0 0.945797 2.3322</pose>
        <view_controller>orbit</view_controller>
      </camera>
    </gui>
    <model name='youbot'>
      <pose>15 -11 0.09 0 -0 0</pose>
      <link name='base_footprint'>
        <pose>0 0 0 0 -0 0</pose>
        <inertial>
          <pose>0 0 -0.05 0 -0 0</pose>
          <inertia>
            <ixx>1</ixx>
            <ixy>0</ixy>
            <ixz>0</ixz>
            <iyy>1</iyy>
            <iyz>0</iyz>
            <izz>1</izz>
          </inertia>
          <mass>0.1</mass>
        </inertial>
        <collision name='base_footprint_geom'>
          <pose>0 0 -0.05 0 -0 0</pose>
          <geometry>
            <box>
              <size>0.001 0.001 0.001</size>
            </box>
          </geometry>
          <surface>
            <friction>
              <ode>
                <mu>1</mu>
                <mu2>1</mu2>
                <fdir1>0 0 0</fdir1>
                <slip1>0</slip1>
                <slip2>0</slip2>
              </ode>
            </friction>
            <bounce>
              <restitution_coefficient>0</restitution_coefficient>
              <threshold>0</threshold>
            </bounce>
            <contact>
              <ode>
                <soft_cfm>0</soft_cfm>
                <soft_erp>0.2</soft_erp>
                <kp>1e+13</kp>
                <kd>1e+11</kd>
                <max_vel>-1</max_vel>
                <min_depth>0</min_depth>
              </ode>
            </contact>
          </surface>
          <laser_retro>0</laser_retro>
          <max_contacts>10</max_contacts>
        </collision>
        <visual name='base_footprint_geom_visual'>
          <pose>0 0 0 0 -0 0</pose>
          <geometry>
            <box>
              <size>0.001 0.001 0.001</size>
            </box>
          </geometry>
        </visual>
        <gravity>1</gravity>
        <self_collide>0</self_collide>
        <kinematic>0</kinematic>
      </link>
      <link name='base_link'>
        <pose>0 0 0 0 -0 0</pose>
        <inertial>
          <pose>0 0 0 0 -0 0</pose>
          <inertia>
            <ixx>5.65223</ixx>
            <ixy>-0.00972</ixy>
            <ixz>1.29399</ixz>
            <iyy>5.66947</iyy>
            <iyz>-0.00738</iyz>
            <izz>3.6832</izz>
          </inertia>
          <mass>22</mass>
        </inertial>
        <collision name='base_link_geom'>
          <pose>0 0 0 0 -0 0</pose>
          <geometry>
            <mesh>
              <uri>model://youbot/meshes/base/base_convex.stl</uri>
            </mesh>
          </geometry>
          <surface>
            <friction>
              <ode>
                <mu>1</mu>
                <mu2>1</mu2>
                <fdir1>0 0 0</fdir1>
                <slip1>0</slip1>
                <slip2>0</slip2>
              </ode>
            </friction>
            <bounce>
              <restitution_coefficient>0</restitution_coefficient>
              <threshold>0</threshold>
            </bounce>
            <contact>
              <ode>
                <soft_cfm>0</soft_cfm>
                <soft_erp>0.2</soft_erp>
                <kp>1e+13</kp>
                <kd>1e+11</kd>
                <max_vel>-1</max_vel>
                <min_depth>0</min_depth>
              </ode>
            </contact>
          </surface>
          <laser_retro>0</laser_retro>
          <max_contacts>10</max_contacts>
        </collision>
        <visual name='base_link_geom_visual'>
          <pose>0 0 0 0 -0 0</pose>
          <geometry>
            <mesh>
              <uri>model://youbot/meshes/base/base.dae</uri>
            </mesh>
          </geometry>
        </visual>
        <gravity>1</gravity>
        <self_collide>0</self_collide>
        <kinematic>0</kinematic>
      </link>
      <link name='arm_link_0'>
        <pose>0.143 0 0.046 0 -0 0</pose>
        <inertial>
          <pose>0 0 0 0 -0 0</pose>
          <inertia>
            <ixx>0.01</ixx>
            <ixy>0</ixy>
            <ixz>0</ixz>
            <iyy>0.01</iyy>
            <iyz>0</iyz>
            <izz>0.01</izz>
          </inertia>
          <mass>0.845</mass>
        </inertial>
        <collision name='arm_link_0_geom'>
          <pose>0 0 0 0 -0 0</pose>
          <geometry>
            <mesh>
              <uri>model://youbot/meshes/arm/arm0_convex.stl</uri>
            </mesh>
          </geometry>
          <surface>
            <friction>
              <ode>
                <mu>1</mu>
                <mu2>1</mu2>
                <fdir1>0 0 0</fdir1>
                <slip1>0</slip1>
                <slip2>0</slip2>
              </ode>
            </friction>
            <bounce>
              <restitution_coefficient>0</restitution_coefficient>
              <threshold>0</threshold>
            </bounce>
            <contact>
              <ode>
                <soft_cfm>0</soft_cfm>
                <soft_erp>0.2</soft_erp>
                <kp>1e+13</kp>
                <kd>1e+11</kd>
                <max_vel>-1</max_vel>
                <min_depth>0</min_depth>
              </ode>
            </contact>
          </surface>
          <laser_retro>0</laser_retro>
          <max_contacts>10</max_contacts>
        </collision>
        <visual name='arm_link_0_geom_visual'>
          <pose>0 0 0 0 -0 0</pose>
          <geometry>
            <mesh>
              <uri>model://youbot/meshes/arm/arm0.dae</uri>
            </mesh>
          </geometry>
          <material>
            <script>
              <uri>model://youbot/materials/scripts/youbot.material</uri>
              <name>youbot/DarkGrey</name>
            </script>
          </material>
        </visual>
        <gravity>1</gravity>
        <self_collide>0</self_collide>
        <kinematic>0</kinematic>
      </link>
      <link name='arm_link_1'>
        <pose>0.167 0 0.142 0 -0 2.96706</pose>
        <inertial>
          <pose>0.01489 0.00213 0.00213 0 -0 0</pose>
          <inertia>
            <ixx>0.003863</ixx>
            <ixy>-0.000979</ixy>
            <ixz>0</ixz>
            <iyy>0.006196</iyy>
            <iyz>0</iyz>
            <izz>0.006369</izz>
          </inertia>
          <mass>2.412</mass>
        </inertial>
        <collision name='arm_link_1_geom'>
          <pose>0 0 0 0 -0 0</pose>
          <geometry>
            <mesh>
              <uri>model://youbot/meshes/arm/arm1_convex.stl</uri>
            </mesh>
          </geometry>
          <surface>
            <friction>
              <ode>
                <mu>1</mu>
                <mu2>1</mu2>
                <fdir1>0 0 0</fdir1>
                <slip1>0</slip1>
                <slip2>0</slip2>
              </ode>
            </friction>
            <bounce>
              <restitution_coefficient>0</restitution_coefficient>
              <threshold>0</threshold>
            </bounce>
            <contact>
              <ode>
                <soft_cfm>0</soft_cfm>
                <soft_erp>0.2</soft_erp>
                <kp>1e+13</kp>
                <kd>1e+11</kd>
                <max_vel>-1</max_vel>
                <min_depth>0</min_depth>
              </ode>
            </contact>
          </surface>
          <laser_retro>0</laser_retro>
          <max_contacts>10</max_contacts>
        </collision>
        <visual name='arm_link_1_geom_visual'>
          <pose>0 0 0 0 -0 0</pose>
          <geometry>
            <mesh>
              <uri>model://youbot/meshes/arm/arm1.dae</uri>
            </mesh>
          </geometry>
        </visual>
        <gravity>1</gravity>
        <self_collide>0</self_collide>
        <kinematic>0</kinematic>
      </link>
      <link name='arm_link_2'>
        <pose>0.134501 0.00573 0.161 1.31349e-16 -1.13446 2.96706</pose>
        <inertial>
          <pose>0.10453 0.0017 -0.00297 0 -0 0</pose>
          <inertia>
            <ixx>0.000823</ixx>
            <ixy>0</ixy>
            <ixz>-0</ixz>
            <iyy>0.004447</iyy>
            <iyz>0</iyz>
            <izz>0.004439</izz>
          </inertia>
          <mass>1.155</mass>
        </inertial>
        <collision name='arm_link_2_geom'>
          <pose>0 -0.032 0.078 0 -0 0</pose>
          <geometry>
            <mesh>
              <uri>model://youbot/meshes/arm/arm2_convex.stl</uri>
            </mesh>
          </geometry>
          <surface>
            <friction>
              <ode>
                <mu>1</mu>
                <mu2>1</mu2>
                <fdir1>0 0 0</fdir1>
                <slip1>0</slip1>
                <slip2>0</slip2>
              </ode>
            </friction>
            <bounce>
              <restitution_coefficient>0</restitution_coefficient>
              <threshold>0</threshold>
            </bounce>
            <contact>
              <ode>
                <soft_cfm>0</soft_cfm>
                <soft_erp>0.2</soft_erp>
                <kp>1e+13</kp>
                <kd>1e+11</kd>
                <max_vel>-1</max_vel>
                <min_depth>0</min_depth>
              </ode>
            </contact>
          </surface>
          <laser_retro>0</laser_retro>
          <max_contacts>10</max_contacts>
        </collision>
        <visual name='arm_link_2_geom_visual'>
          <pose>0 -0.032 0.078 0 -0 0</pose>
          <geometry>
            <mesh>
              <uri>model://youbot/meshes/arm/arm2.dae</uri>
            </mesh>
          </geometry>
        </visual>
        <gravity>1</gravity>
        <self_collide>0</self_collide>
        <kinematic>0</kinematic>
      </link>
      <link name='arm_link_3'>
        <pose>0.272845 -0.018663 0.226506 -8.8715e-16 1.41372 2.96706</pose>
        <inertial>
          <pose>0.0001 0.0967 0.02107 0 -0 0</pose>
          <inertia>
            <ixx>0.002459</ixx>
            <ixy>0</ixy>
            <ixz>0</ixz>
            <iyy>0.002571</iyy>
            <iyz>-0</iyz>
            <izz>0.000535</izz>
          </inertia>
          <mass>0.934</mass>
        </inertial>
        <collision name='arm_link_3_geom'>
          <pose>0 0.028 0.079 0 -0 0</pose>
          <geometry>
            <mesh>
              <uri>model://youbot/meshes/arm/arm3_convex.stl</uri>
            </mesh>
          </geometry>
          <surface>
            <friction>
              <ode>
                <mu>1</mu>
                <mu2>1</mu2>
                <fdir1>0 0 0</fdir1>
                <slip1>0</slip1>
                <slip2>0</slip2>
              </ode>
            </friction>
            <bounce>
              <restitution_coefficient>0</restitution_coefficient>
              <threshold>0</threshold>
            </bounce>
            <contact>
              <ode>
                <soft_cfm>0</soft_cfm>
                <soft_erp>0.2</soft_erp>
                <kp>1e+13</kp>
                <kd>1e+11</kd>
                <max_vel>-1</max_vel>
                <min_depth>0</min_depth>
              </ode>
            </contact>
          </surface>
          <laser_retro>0</laser_retro>
          <max_contacts>10</max_contacts>
        </collision>
        <visual name='arm_link_3_geom_visual'>
          <pose>0 0.028 0.079 0 -0 0</pose>
          <geometry>
            <mesh>
              <uri>model://youbot/meshes/arm/arm3.dae</uri>
            </mesh>
          </geometry>
        </visual>
        <gravity>1</gravity>
        <self_collide>0</self_collide>
        <kinematic>0</kinematic>
      </link>
      <link name='arm_link_4'>
        <pose>0.141533 0.004491 0.247624 0 -0.375246 2.96706</pose>
        <inertial>
          <pose>0.00011 0.05103 -0.02319 0 -0 0</pose>
          <inertia>
            <ixx>0.000869</ixx>
            <ixy>0</ixy>
            <ixz>-0</ixz>
            <iyy>0.001173</iyy>
            <iyz>-0.000231</iyz>
            <izz>0.001091</izz>
          </inertia>
          <mass>0.877</mass>
        </inertial>
        <collision name='arm_link_4_geom'>
          <pose>0 -0.01 0.029 0 -0 0</pose>
          <geometry>
            <mesh>
              <uri>model://youbot/meshes/arm/arm4_convex.stl</uri>
            </mesh>
          </geometry>
          <surface>
            <friction>
              <ode>
                <mu>1</mu>
                <mu2>1</mu2>
                <fdir1>0 0 0</fdir1>
                <slip1>0</slip1>
                <slip2>0</slip2>
              </ode>
            </friction>
            <bounce>
              <restitution_coefficient>0</restitution_coefficient>
              <threshold>0</threshold>
            </bounce>
            <contact>
              <ode>
                <soft_cfm>0</soft_cfm>
                <soft_erp>0.2</soft_erp>
                <kp>1e+13</kp>
                <kd>1e+11</kd>
                <max_vel>-1</max_vel>
                <min_depth>0</min_depth>
              </ode>
            </contact>
          </surface>
          <laser_retro>0</laser_retro>
          <max_contacts>10</max_contacts>
        </collision>
        <visual name='arm_link_4_geom_visual'>
          <pose>0 -0.01 0.029 0 -0 0</pose>
          <geometry>
            <mesh>
              <uri>model://youbot/meshes/arm/arm4.dae</uri>
            </mesh>
          </geometry>
        </visual>
        <gravity>1</gravity>
        <self_collide>0</self_collide>
        <kinematic>0</kinematic>
      </link>
      <link name='arm_link_5'>
        <pose>0.190287 -0.004106 0.367846 -0.085052 0.365926 -0.408445</pose>
        <inertial>
          <pose>0 0.00115 -0.01683 0 -0 0</pose>
          <inertia>
            <ixx>0.00028</ixx>
            <ixy>0</ixy>
            <ixz>0</ixz>
            <iyy>0.000339</iyy>
            <iyz>0</iyz>
            <izz>0.000119</izz>
          </inertia>
          <mass>0.251</mass>
        </inertial>
        <collision name='arm_link_5_geom'>
          <pose>0.003 0 -0.034 0 -0 0</pose>
          <geometry>
            <mesh>
              <uri>model://youbot/meshes/arm/arm5_convex.stl</uri>
            </mesh>
          </geometry>
          <surface>
            <friction>
              <ode>
                <mu>1</mu>
                <mu2>1</mu2>
                <fdir1>0 0 0</fdir1>
                <slip1>0</slip1>
                <slip2>0</slip2>
              </ode>
            </friction>
            <bounce>
              <restitution_coefficient>0</restitution_coefficient>
              <threshold>0</threshold>
            </bounce>
            <contact>
              <ode>
                <soft_cfm>0</soft_cfm>
                <soft_erp>0.2</soft_erp>
                <kp>1e+13</kp>
                <kd>1e+11</kd>
                <max_vel>-1</max_vel>
                <min_depth>0</min_depth>
              </ode>
            </contact>
          </surface>
          <laser_retro>0</laser_retro>
          <max_contacts>10</max_contacts>
        </collision>
        <visual name='arm_link_5_geom_visual'>
          <pose>0.003 0 -0.034 0 -0 0</pose>
          <geometry>
            <mesh>
              <uri>model://youbot/meshes/arm/arm5.dae</uri>
            </mesh>
          </geometry>
        </visual>
        <gravity>1</gravity>
        <self_collide>0</self_collide>
        <kinematic>0</kinematic>
      </link>
      <link name='gripper_palm_link'>
        <pose>0.190287 -0.004106 0.367846 -0.085052 0.365926 -0.408445</pose>
        <inertial>
          <pose>0 0 0 0 -0 0</pose>
          <inertia>
            <ixx>0.01</ixx>
            <ixy>0</ixy>
            <ixz>0</ixz>
            <iyy>0.01</iyy>
            <iyz>0</iyz>
            <izz>0.01</izz>
          </inertia>
          <mass>0.1</mass>
        </inertial>
        <collision name='gripper_palm_link_geom'>
          <pose>0 0 0 0 -0 0</pose>
          <geometry>
            <mesh>
              <uri>model://youbot/meshes/gripper/palm_convex.stl</uri>
            </mesh>
          </geometry>
          <surface>
            <friction>
              <ode>
                <mu>1</mu>
                <mu2>1</mu2>
                <fdir1>0 0 0</fdir1>
                <slip1>0</slip1>
                <slip2>0</slip2>
              </ode>
            </friction>
            <bounce>
              <restitution_coefficient>0</restitution_coefficient>
              <threshold>0</threshold>
            </bounce>
            <contact>
              <ode>
                <soft_cfm>0</soft_cfm>
                <soft_erp>0.2</soft_erp>
                <kp>1e+13</kp>
                <kd>1e+11</kd>
                <max_vel>-1</max_vel>
                <min_depth>0</min_depth>
              </ode>
            </contact>
          </surface>
          <laser_retro>0</laser_retro>
          <max_contacts>10</max_contacts>
        </collision>
        <visual name='gripper_palm_link_geom_visual'>
          <pose>0 0 0 0 -0 0</pose>
          <geometry>
            <mesh>
              <uri>model://youbot/meshes/gripper/palm.stl</uri>
            </mesh>
          </geometry>
          <material>
            <script>
              <uri>file://media/materials/scripts/gazebo.material</uri>
              <name>Gazebo/Black</name>
            </script>
          </material>
        </visual>
        <gravity>1</gravity>
        <self_collide>1</self_collide>
        <kinematic>0</kinematic>
      </link>
      <link name='gripper_finger_link_l'>
        <pose>0.21326 -0.001105 0.408579 0.085052 -0.365926 2.73315</pose>
        <inertial>
          <pose>0 -0.001 0 0 -0 0</pose>
          <inertia>
            <ixx>0.01</ixx>
            <ixy>0</ixy>
            <ixz>0</ixz>
            <iyy>0.01</iyy>
            <iyz>0</iyz>
            <izz>0.01</izz>
          </inertia>
          <mass>0.01</mass>
        </inertial>
        <collision name='gripper_finger_link_l_geom'>
          <pose>0 0 0 0 -0 0</pose>
          <geometry>
            <mesh>
              <uri>model://youbot/meshes/gripper/finger_convex.stl</uri>
            </mesh>
          </geometry>
          <surface>
            <friction>
              <ode>
                <mu>1</mu>
                <mu2>1</mu2>
                <fdir1>0 0 0</fdir1>
                <slip1>0</slip1>
                <slip2>0</slip2>
              </ode>
            </friction>
            <bounce>
              <restitution_coefficient>0</restitution_coefficient>
              <threshold>0</threshold>
            </bounce>
            <contact>
              <ode>
                <soft_cfm>0</soft_cfm>
                <soft_erp>0.2</soft_erp>
                <kp>1e+13</kp>
                <kd>1e+11</kd>
                <max_vel>-1</max_vel>
                <min_depth>0</min_depth>
              </ode>
            </contact>
          </surface>
          <laser_retro>0</laser_retro>
          <max_contacts>10</max_contacts>
        </collision>
        <visual name='gripper_finger_link_l_geom_visual'>
          <pose>0 0 0 0 -0 0</pose>
          <geometry>
            <mesh>
              <uri>model://youbot/meshes/gripper/finger.stl</uri>
            </mesh>
          </geometry>
        </visual>
        <gravity>1</gravity>
        <self_collide>0</self_collide>
        <kinematic>0</kinematic>
      </link>
      <link name='gripper_finger_link_r'>
        <pose>0.207375 -0.015929 0.409848 -0.085052 0.365926 -0.408445</pose>
        <inertial>
          <pose>0 -0.001 0 0 -0 0</pose>
          <inertia>
            <ixx>0.01</ixx>
            <ixy>0</ixy>
            <ixz>0</ixz>
            <iyy>0.01</iyy>
            <iyz>0</iyz>
            <izz>0.01</izz>
          </inertia>
          <mass>0.01</mass>
        </inertial>
        <collision name='gripper_finger_link_r_geom'>
          <pose>0 0 0 0 -0 0</pose>
          <geometry>
            <mesh>
              <uri>model://youbot/meshes/gripper/finger_convex.stl</uri>
            </mesh>
          </geometry>
          <surface>
            <friction>
              <ode>
                <mu>1</mu>
                <mu2>1</mu2>
                <fdir1>0 0 0</fdir1>
                <slip1>0</slip1>
                <slip2>0</slip2>
              </ode>
            </friction>
            <bounce>
              <restitution_coefficient>0</restitution_coefficient>
              <threshold>0</threshold>
            </bounce>
            <contact>
              <ode>
                <soft_cfm>0</soft_cfm>
                <soft_erp>0.2</soft_erp>
                <kp>1e+13</kp>
                <kd>1e+11</kd>
                <max_vel>-1</max_vel>
                <min_depth>0</min_depth>
              </ode>
            </contact>
          </surface>
          <laser_retro>0</laser_retro>
          <max_contacts>10</max_contacts>
        </collision>
        <visual name='gripper_finger_link_r_geom_visual'>
          <pose>0 0 0 0 -0 0</pose>
          <geometry>
            <mesh>
              <uri>model://youbot/meshes/gripper/finger.stl</uri>
            </mesh>
          </geometry>
        </visual>
        <gravity>1</gravity>
        <self_collide>0</self_collide>
        <kinematic>0</kinematic>
      </link>
      <link name='base_laser_front_link'>
        <pose>0.3 0 -0.03 0 -0 0</pose>
        <inertial>
          <pose>0 0 0 0 -0 0</pose>
          <inertia>
            <ixx>0.1</ixx>
            <ixy>0</ixy>
            <ixz>0</ixz>
            <iyy>0.1</iyy>
            <iyz>0</iyz>
            <izz>0.1</izz>
          </inertia>
          <mass>0.16</mass>
        </inertial>
        <collision name='base_laser_front_link_geom'>
          <pose>0 0 0 0 -0 0</pose>
          <geometry>
            <mesh>
              <uri>model://hokuyo/meshes/hokuyo_convex.stl</uri>
            </mesh>
          </geometry>
          <surface>
            <friction>
              <ode>
                <mu>1</mu>
                <mu2>1</mu2>
                <fdir1>0 0 0</fdir1>
                <slip1>0</slip1>
                <slip2>0</slip2>
              </ode>
            </friction>
            <bounce>
              <restitution_coefficient>0</restitution_coefficient>
              <threshold>0</threshold>
            </bounce>
            <contact>
              <ode>
                <soft_cfm>0</soft_cfm>
                <soft_erp>0.2</soft_erp>
                <kp>1e+13</kp>
                <kd>1e+11</kd>
                <max_vel>-1</max_vel>
                <min_depth>0</min_depth>
              </ode>
            </contact>
          </surface>
          <laser_retro>0</laser_retro>
          <max_contacts>10</max_contacts>
        </collision>
        <visual name='base_laser_front_link_geom_visual'>
          <pose>0 0 0 0 -0 0</pose>
          <geometry>
            <mesh>
              <uri>model://hokuyo/meshes/hokuyo.dae</uri>
            </mesh>
          </geometry>
        </visual>
        <sensor name='base_laser_front' type='ray'>
          <plugin name="gazebo_rayscan_sensor_plugin" filename="librayscan.so"/>
          <pose>0 0 0 0 -0 0</pose>
          <ray>
            <scan>
              <horizontal>
                <samples>640</samples>
                <resolution>1</resolution>
                <min_angle>-1.57</min_angle>
                <max_angle>1.57</max_angle>
              </horizontal>
            </scan>
            <range>
              <min>0.05</min>
              <max>5.6</max>
              <resolution>0.36</resolution>
            </range>
          </ray>
          <always_on>0</always_on>
          <update_rate>10</update_rate>
          <visualize>0</visualize>
        </sensor>
        <gravity>1</gravity>
        <self_collide>0</self_collide>
        <kinematic>0</kinematic>
      </link>
      <link name='caster_link_bl'>
        <pose>-0.228 0.158 -0.034 0 -0 0</pose>
        <inertial>
          <pose>0 0 0 0 -0 0</pose>
          <inertia>
            <ixx>0.012412</ixx>
            <ixy>-0.000712</ixy>
            <ixz>0.000503</ixz>
            <iyy>0.015218</iyy>
            <iyz>-4e-06</iyz>
            <izz>0.011764</izz>
          </inertia>
          <mass>0.1</mass>
        </inertial>
        <gravity>1</gravity>
        <self_collide>0</self_collide>
        <kinematic>0</kinematic>
      </link>
      <link name='wheel_link_bl'>
        <pose>-0.228 0.158 -0.034 0 -0 0</pose>
        <inertial>
          <pose>0 0 0 0 -0 0</pose>
          <inertia>
            <ixx>0.012412</ixx>
            <ixy>-0.000712</ixy>
            <ixz>0.000503</ixz>
            <iyy>0.015218</iyy>
            <iyz>-4e-06</iyz>
            <izz>0.011764</izz>
          </inertia>
          <mass>0.4</mass>
        </inertial>
        <collision name='wheel_link_bl_geom'>
          <pose>0 0 0 1.5708 -0 0</pose>
          <geometry>
            <cylinder>
              <radius>0.05</radius>
              <length>0.005</length>
            </cylinder>
          </geometry>
          <surface>
            <friction>
              <ode>
                <mu>1</mu>
                <mu2>1</mu2>
                <fdir1>0 0 0</fdir1>
                <slip1>0</slip1>
                <slip2>0</slip2>
              </ode>
            </friction>
            <bounce>
              <restitution_coefficient>0</restitution_coefficient>
              <threshold>0</threshold>
            </bounce>
            <contact>
              <ode>
                <soft_cfm>0</soft_cfm>
                <soft_erp>0.2</soft_erp>
                <kp>1e+13</kp>
                <kd>1e+11</kd>
                <max_vel>-1</max_vel>
                <min_depth>0</min_depth>
              </ode>
            </contact>
          </surface>
          <laser_retro>0</laser_retro>
          <max_contacts>10</max_contacts>
        </collision>
        <visual name='wheel_link_bl_geom_visual'>
          <pose>0 0 0 0 -0 0</pose>
          <geometry>
            <mesh>
              <uri>model://youbot/meshes/base/back-left_wheel.dae</uri>
            </mesh>
          </geometry>
          <material>
            <script>
              <uri>model://youbot/materials/scripts/youbot.material</uri>
              <name>youbot/Orange</name>
            </script>
          </material>
        </visual>
        <gravity>1</gravity>
        <self_collide>0</self_collide>
        <kinematic>0</kinematic>
      </link>
      <link name='caster_link_br'>
        <pose>-0.228 -0.158 -0.034 0 -0 0</pose>
        <inertial>
          <pose>0 0 0 0 -0 0</pose>
          <inertia>
            <ixx>0.012412</ixx>
            <ixy>-0.000712</ixy>
            <ixz>0.000503</ixz>
            <iyy>0.015218</iyy>
            <iyz>-4e-06</iyz>
            <izz>0.011764</izz>
          </inertia>
          <mass>0.1</mass>
        </inertial>
        <gravity>1</gravity>
        <self_collide>0</self_collide>
        <kinematic>0</kinematic>
      </link>
      <link name='wheel_link_br'>
        <pose>-0.228 -0.158 -0.034 0 -0 0</pose>
        <inertial>
          <pose>0 0 0 0 -0 0</pose>
          <inertia>
            <ixx>0.012412</ixx>
            <ixy>-0.000712</ixy>
            <ixz>0.000503</ixz>
            <iyy>0.015218</iyy>
            <iyz>-4e-06</iyz>
            <izz>0.011764</izz>
          </inertia>
          <mass>0.4</mass>
        </inertial>
        <collision name='wheel_link_br_geom'>
          <pose>0 0 0 1.5708 -0 0</pose>
          <geometry>
            <cylinder>
              <radius>0.05</radius>
              <length>0.005</length>
            </cylinder>
          </geometry>
          <surface>
            <friction>
              <ode>
                <mu>1</mu>
                <mu2>1</mu2>
                <fdir1>0 0 0</fdir1>
                <slip1>0</slip1>
                <slip2>0</slip2>
              </ode>
            </friction>
            <bounce>
              <restitution_coefficient>0</restitution_coefficient>
              <threshold>0</threshold>
            </bounce>
            <contact>
              <ode>
                <soft_cfm>0</soft_cfm>
                <soft_erp>0.2</soft_erp>
                <kp>1e+13</kp>
                <kd>1e+11</kd>
                <max_vel>-1</max_vel>
                <min_depth>0</min_depth>
              </ode>
            </contact>
          </surface>
          <laser_retro>0</laser_retro>
          <max_contacts>10</max_contacts>
        </collision>
        <visual name='wheel_link_br_geom_visual'>
          <pose>0 0 0 0 -0 0</pose>
          <geometry>
            <mesh>
              <uri>model://youbot/meshes/base/back-right_wheel.dae</uri>
            </mesh>
          </geometry>
          <material>
            <script>
              <uri>model://youbot/materials/scripts/youbot.material</uri>
              <name>youbot/Orange</name>
            </script>
          </material>
        </visual>
        <gravity>1</gravity>
        <self_collide>0</self_collide>
        <kinematic>0</kinematic>
      </link>
      <link name='caster_link_fl'>
        <pose>0.228 0.158 -0.034 0 -0 0</pose>
        <inertial>
          <pose>0 0 0 0 -0 0</pose>
          <inertia>
            <ixx>0.012412</ixx>
            <ixy>-0.000712</ixy>
            <ixz>0.000503</ixz>
            <iyy>0.015218</iyy>
            <iyz>-4e-06</iyz>
            <izz>0.011764</izz>
          </inertia>
          <mass>0.1</mass>
        </inertial>
        <gravity>1</gravity>
        <self_collide>0</self_collide>
        <kinematic>0</kinematic>
      </link>
      <link name='wheel_link_fl'>
        <pose>0.228 0.158 -0.034 0 -0 0</pose>
        <inertial>
          <pose>0 0 0 0 -0 0</pose>
          <inertia>
            <ixx>0.012412</ixx>
            <ixy>-0.000712</ixy>
            <ixz>0.000503</ixz>
            <iyy>0.015218</iyy>
            <iyz>-4e-06</iyz>
            <izz>0.011764</izz>
          </inertia>
          <mass>0.4</mass>
        </inertial>
        <collision name='wheel_link_fl_geom'>
          <pose>0 0 0 1.5708 -0 0</pose>
          <geometry>
            <cylinder>
              <radius>0.05</radius>
              <length>0.005</length>
            </cylinder>
          </geometry>
          <surface>
            <friction>
              <ode>
                <mu>1</mu>
                <mu2>1</mu2>
                <fdir1>0 0 0</fdir1>
                <slip1>0</slip1>
                <slip2>0</slip2>
              </ode>
            </friction>
            <bounce>
              <restitution_coefficient>0</restitution_coefficient>
              <threshold>0</threshold>
            </bounce>
            <contact>
              <ode>
                <soft_cfm>0</soft_cfm>
                <soft_erp>0.2</soft_erp>
                <kp>1e+13</kp>
                <kd>1e+11</kd>
                <max_vel>-1</max_vel>
                <min_depth>0</min_depth>
              </ode>
            </contact>
          </surface>
          <laser_retro>0</laser_retro>
          <max_contacts>10</max_contacts>
        </collision>
        <visual name='wheel_link_fl_geom_visual'>
          <pose>0 0 0 0 -0 0</pose>
          <geometry>
            <mesh>
              <uri>model://youbot/meshes/base/front-left_wheel.dae</uri>
            </mesh>
          </geometry>
          <material>
            <script>
              <uri>model://youbot/materials/scripts/youbot.material</uri>
              <name>youbot/Orange</name>
            </script>
          </material>
        </visual>
        <gravity>1</gravity>
        <self_collide>0</self_collide>
        <kinematic>0</kinematic>
      </link>
      <link name='caster_link_fr'>
        <pose>0.228 -0.158 -0.034 0 -0 0</pose>
        <inertial>
          <pose>0 0 0 0 -0 0</pose>
          <inertia>
            <ixx>0.012412</ixx>
            <ixy>-0.000712</ixy>
            <ixz>0.000503</ixz>
            <iyy>0.015218</iyy>
            <iyz>-4e-06</iyz>
            <izz>0.011764</izz>
          </inertia>
          <mass>0.1</mass>
        </inertial>
        <gravity>1</gravity>
        <self_collide>0</self_collide>
        <kinematic>0</kinematic>
      </link>
      <link name='wheel_link_fr'>
        <pose>0.228 -0.158 -0.034 0 -0 0</pose>
        <inertial>
          <pose>0 0 0 0 -0 0</pose>
          <inertia>
            <ixx>0.012412</ixx>
            <ixy>-0.000712</ixy>
            <ixz>0.000503</ixz>
            <iyy>0.015218</iyy>
            <iyz>-4e-06</iyz>
            <izz>0.011764</izz>
          </inertia>
          <mass>0.4</mass>
        </inertial>
        <collision name='wheel_link_fr_geom'>
          <pose>0 0 0 1.5708 -0 0</pose>
          <geometry>
            <cylinder>
              <radius>0.05</radius>
              <length>0.005</length>
            </cylinder>
          </geometry>
          <surface>
            <friction>
              <ode>
                <mu>1</mu>
                <mu2>1</mu2>
                <fdir1>0 0 0</fdir1>
                <slip1>0</slip1>
                <slip2>0</slip2>
              </ode>
            </friction>
            <bounce>
              <restitution_coefficient>0</restitution_coefficient>
              <threshold>0</threshold>
            </bounce>
            <contact>
              <ode>
                <soft_cfm>0</soft_cfm>
                <soft_erp>0.2</soft_erp>
                <kp>1e+13</kp>
                <kd>1e+11</kd>
                <max_vel>-1</max_vel>
                <min_depth>0</min_depth>
              </ode>
            </contact>
          </surface>
          <laser_retro>0</laser_retro>
          <max_contacts>10</max_contacts>
        </collision>
        <visual name='wheel_link_fr_geom_visual'>
          <pose>0 0 0 0 -0 0</pose>
          <geometry>
            <mesh>
              <uri>model://youbot/meshes/base/front-right_wheel.dae</uri>
            </mesh>
          </geometry>
          <material>
            <script>
              <uri>model://youbot/materials/scripts/youbot.material</uri>
              <name>youbot/Orange</name>
            </script>
          </material>
        </visual>
        <gravity>1</gravity>
        <self_collide>0</self_collide>
        <kinematic>0</kinematic>
      </link>
      <link name='plate_link'>
        <pose>-0.159 0 0.046 0 -0 0</pose>
        <inertial>
          <pose>0 0 0 0 -0 0</pose>
          <inertia>
            <ixx>0.01</ixx>
            <ixy>0</ixy>
            <ixz>0</ixz>
            <iyy>0.01</iyy>
            <iyz>0</iyz>
            <izz>0.01</izz>
          </inertia>
          <mass>1</mass>
        </inertial>
        <collision name='plate_link_geom'>
          <pose>0 0 0 0 -0 0</pose>
          <geometry>
            <mesh>
              <uri>model://youbot/meshes/plate/plate_convex.stl</uri>
            </mesh>
          </geometry>
          <surface>
            <friction>
              <ode>
                <mu>1</mu>
                <mu2>1</mu2>
                <fdir1>0 0 0</fdir1>
                <slip1>0</slip1>
                <slip2>0</slip2>
              </ode>
            </friction>
            <bounce>
              <restitution_coefficient>0</restitution_coefficient>
              <threshold>0</threshold>
            </bounce>
            <contact>
              <ode>
                <soft_cfm>0</soft_cfm>
                <soft_erp>0.2</soft_erp>
                <kp>1e+13</kp>
                <kd>1e+11</kd>
                <max_vel>-1</max_vel>
                <min_depth>0</min_depth>
              </ode>
            </contact>
          </surface>
          <laser_retro>0</laser_retro>
          <max_contacts>10</max_contacts>
        </collision>
        <visual name='plate_link_geom_visual'>
          <pose>0 0 0 0 -0 0</pose>
          <geometry>
            <mesh>
              <uri>model://youbot/meshes/plate/plate.dae</uri>
            </mesh>
          </geometry>
        </visual>
        <gravity>1</gravity>
        <self_collide>0</self_collide>
        <kinematic>0</kinematic>
      </link>
      <joint name='base_footprint_joint' type='revolute'>
        <pose>0 0 0 0 -0 0</pose>
        <parent>base_footprint</parent>
        <child>base_link</child>
        <axis>
          <dynamics>
            <damping>0</damping>
            <friction>0</friction>
            <spring_reference>0</spring_reference>
            <spring_stiffness>0</spring_stiffness>
          </dynamics>
          <limit>
            <lower>0</lower>
            <upper>0</upper>
            <effort>100</effort>
            <velocity>100</velocity>
          </limit>
          <xyz>0 0 1</xyz>
          <use_parent_model_frame>1</use_parent_model_frame>
        </axis>
      </joint>
      <joint name='arm_joint_0' type='revolute'>
        <pose>0 0 0 0 -0 0</pose>
        <parent>base_link</parent>
        <child>arm_link_0</child>
        <axis>
          <dynamics>
            <damping>0</damping>
            <friction>0</friction>
            <spring_reference>0</spring_reference>
            <spring_stiffness>0</spring_stiffness>
          </dynamics>
          <limit>
            <lower>0</lower>
            <upper>0</upper>
            <effort>100</effort>
            <velocity>100</velocity>
          </limit>
          <xyz>0 0 1</xyz>
          <use_parent_model_frame>1</use_parent_model_frame>
        </axis>
      </joint>
      <joint name='arm_joint_1' type='revolute'>
        <pose>0 0 0 0 -0 0</pose>
        <parent>arm_link_0</parent>
        <child>arm_link_1</child>
        <axis>
          <dynamics>
            <damping>1</damping>
            <friction>0</friction>
            <spring_reference>0</spring_reference>
            <spring_stiffness>0</spring_stiffness>
          </dynamics>
          <limit>
            <lower>0</lower>
            <upper>5.89921</upper>
            <effort>100</effort>
            <velocity>100</velocity>
          </limit>
          <xyz>0 0 -1</xyz>
          <use_parent_model_frame>1</use_parent_model_frame>
        </axis>
      </joint>
      <joint name='arm_joint_2' type='revolute'>
        <pose>0 0 0 0 -0 0</pose>
        <parent>arm_link_1</parent>
        <child>arm_link_2</child>
        <axis>
          <dynamics>
            <damping>1</damping>
            <friction>0</friction>
            <spring_reference>0</spring_reference>
            <spring_stiffness>0</spring_stiffness>
          </dynamics>
          <limit>
            <lower>0</lower>
            <upper>2.70526</upper>
            <effort>100</effort>
            <velocity>100</velocity>
          </limit>
          <xyz>-0.173648 -0.984808 0</xyz>
          <use_parent_model_frame>1</use_parent_model_frame>
        </axis>
      </joint>
      <joint name='arm_joint_3' type='revolute'>
        <pose>0 0 0 0 -0 0</pose>
        <parent>arm_link_2</parent>
        <child>arm_link_3</child>
        <axis>
          <dynamics>
            <damping>1</damping>
            <friction>0</friction>
            <spring_reference>0</spring_reference>
            <spring_stiffness>0</spring_stiffness>
          </dynamics>
          <limit>
            <lower>-5.18363</lower>
            <upper>0</upper>
            <effort>100</effort>
            <velocity>100</velocity>
          </limit>
          <xyz>-0.173648 -0.984808 0</xyz>
          <use_parent_model_frame>1</use_parent_model_frame>
        </axis>
      </joint>
      <joint name='arm_joint_4' type='revolute'>
        <pose>0 0 0 0 -0 0</pose>
        <parent>arm_link_3</parent>
        <child>arm_link_4</child>
        <axis>
          <dynamics>
            <damping>1</damping>
            <friction>0</friction>
            <spring_reference>0</spring_reference>
            <spring_stiffness>0</spring_stiffness>
          </dynamics>
          <limit>
            <lower>0</lower>
            <upper>3.57793</upper>
            <effort>100</effort>
            <velocity>100</velocity>
          </limit>
          <xyz>-0.173648 -0.984808 0</xyz>
          <use_parent_model_frame>1</use_parent_model_frame>
        </axis>
      </joint>
      <joint name='arm_joint_5' type='revolute'>
        <pose>0 0 0 0 -0 0</pose>
        <parent>arm_link_4</parent>
        <child>arm_link_5</child>
        <axis>
          <dynamics>
            <damping>1</damping>
            <friction>0</friction>
            <spring_reference>0</spring_reference>
            <spring_stiffness>0</spring_stiffness>
          </dynamics>
          <limit>
            <lower>0</lower>
            <upper>5.84685</upper>
            <effort>100</effort>
            <velocity>100</velocity>
          </limit>
          <xyz>-0.360933 0.063642 -0.930418</xyz>
          <use_parent_model_frame>1</use_parent_model_frame>
        </axis>
      </joint>
      <joint name='gripper_palm_joint' type='revolute'>
        <pose>0 0 0 0 -0 0</pose>
        <parent>arm_link_5</parent>
        <child>gripper_palm_link</child>
        <axis>
          <dynamics>
            <damping>0</damping>
            <friction>0</friction>
            <spring_reference>0</spring_reference>
            <spring_stiffness>0</spring_stiffness>
          </dynamics>
          <limit>
            <lower>0</lower>
            <upper>0</upper>
            <effort>100</effort>
            <velocity>100</velocity>
          </limit>
          <xyz>0 0 1</xyz>
          <use_parent_model_frame>1</use_parent_model_frame>
        </axis>
      </joint>
      <joint name='gripper_finger_joint_l' type='prismatic'>
        <pose>0 0 0 0 -0 0</pose>
        <parent>gripper_palm_link</parent>
        <child>gripper_finger_link_l</child>
        <axis>
          <dynamics>
            <damping>1</damping>
            <friction>0</friction>
            <spring_reference>0</spring_reference>
            <spring_stiffness>0</spring_stiffness>
          </dynamics>
          <limit>
            <lower>0</lower>
            <upper>0.0115</upper>
            <effort>100</effort>
            <velocity>100</velocity>
          </limit>
          <xyz>0.367852 0.926495 -0.079325</xyz>
          <use_parent_model_frame>1</use_parent_model_frame>
        </axis>
      </joint>
      <joint name='gripper_finger_joint_r' type='prismatic'>
        <pose>0 0 0 0 -0 0</pose>
        <parent>gripper_palm_link</parent>
        <child>gripper_finger_link_r</child>
        <axis>
          <dynamics>
            <damping>1</damping>
            <friction>0</friction>
            <spring_reference>0</spring_reference>
            <spring_stiffness>0</spring_stiffness>
          </dynamics>
          <limit>
            <lower>0</lower>
            <upper>0.0115</upper>
            <effort>100</effort>
            <velocity>100</velocity>
          </limit>
          <xyz>-0.367852 -0.926495 0.079325</xyz>
          <use_parent_model_frame>1</use_parent_model_frame>
        </axis>
      </joint>
      <joint name='base_laser_front_hokuyo_urg04_laser_joint' type='revolute'>
        <pose>0 0 0 0 -0 0</pose>
        <parent>base_link</parent>
        <child>base_laser_front_link</child>
        <axis>
          <dynamics>
            <damping>0</damping>
            <friction>0</friction>
            <spring_reference>0</spring_reference>
            <spring_stiffness>0</spring_stiffness>
          </dynamics>
          <limit>
            <lower>0</lower>
            <upper>0</upper>
            <effort>100</effort>
            <velocity>100</velocity>
          </limit>
          <xyz>0 0 1</xyz>
          <use_parent_model_frame>1</use_parent_model_frame>
        </axis>
      </joint>
      <joint name='caster_joint_bl' type='revolute'>
        <pose>0 0 0 0 -0 0</pose>
        <parent>base_link</parent>
        <child>caster_link_bl</child>
        <axis>
          <dynamics>
            <damping>1</damping>
            <friction>0</friction>
            <spring_reference>0</spring_reference>
            <spring_stiffness>0</spring_stiffness>
          </dynamics>
          <limit>
            <lower>-1e+16</lower>
            <upper>1e+16</upper>
            <effort>100</effort>
            <velocity>100</velocity>
          </limit>
          <xyz>0 0 1</xyz>
          <use_parent_model_frame>1</use_parent_model_frame>
        </axis>
      </joint>
      <joint name='wheel_joint_bl' type='revolute'>
        <pose>0 0 0 0 -0 0</pose>
        <parent>caster_link_bl</parent>
        <child>wheel_link_bl</child>
        <axis>
          <dynamics>
            <damping>1</damping>
            <friction>0</friction>
            <spring_reference>0</spring_reference>
            <spring_stiffness>0</spring_stiffness>
          </dynamics>
          <limit>
            <lower>-1e+16</lower>
            <upper>1e+16</upper>
            <effort>100</effort>
            <velocity>100</velocity>
          </limit>
          <xyz>0 1 0</xyz>
          <use_parent_model_frame>1</use_parent_model_frame>
        </axis>
      </joint>
      <joint name='caster_joint_br' type='revolute'>
        <pose>0 0 0 0 -0 0</pose>
        <parent>base_link</parent>
        <child>caster_link_br</child>
        <axis>
          <dynamics>
            <damping>1</damping>
            <friction>0</friction>
            <spring_reference>0</spring_reference>
            <spring_stiffness>0</spring_stiffness>
          </dynamics>
          <limit>
            <lower>-1e+16</lower>
            <upper>1e+16</upper>
            <effort>100</effort>
            <velocity>100</velocity>
          </limit>
          <xyz>0 0 1</xyz>
          <use_parent_model_frame>1</use_parent_model_frame>
        </axis>
      </joint>
      <joint name='wheel_joint_br' type='revolute'>
        <pose>0 0 0 0 -0 0</pose>
        <parent>caster_link_br</parent>
        <child>wheel_link_br</child>
        <axis>
          <dynamics>
            <damping>1</damping>
            <friction>0</friction>
            <spring_reference>0</spring_reference>
            <spring_stiffness>0</spring_stiffness>
          </dynamics>
          <limit>
            <lower>-1e+16</lower>
            <upper>1e+16</upper>
            <effort>100</effort>
            <velocity>100</velocity>
          </limit>
          <xyz>0 1 0</xyz>
          <use_parent_model_frame>1</use_parent_model_frame>
        </axis>
      </joint>
      <joint name='caster_joint_fl' type='revolute'>
        <pose>0 0 0 0 -0 0</pose>
        <parent>base_link</parent>
        <child>caster_link_fl</child>
        <axis>
          <dynamics>
            <damping>1</damping>
            <friction>0</friction>
            <spring_reference>0</spring_reference>
            <spring_stiffness>0</spring_stiffness>
          </dynamics>
          <limit>
            <lower>-1e+16</lower>
            <upper>1e+16</upper>
            <effort>100</effort>
            <velocity>100</velocity>
          </limit>
          <xyz>0 0 1</xyz>
          <use_parent_model_frame>1</use_parent_model_frame>
        </axis>
      </joint>
      <joint name='wheel_joint_fl' type='revolute'>
        <pose>0 0 0 0 -0 0</pose>
        <parent>caster_link_fl</parent>
        <child>wheel_link_fl</child>
        <axis>
          <dynamics>
            <damping>1</damping>
            <friction>0</friction>
            <spring_reference>0</spring_reference>
            <spring_stiffness>0</spring_stiffness>
          </dynamics>
          <limit>
            <lower>-1e+16</lower>
            <upper>1e+16</upper>
            <effort>100</effort>
            <velocity>100</velocity>
          </limit>
          <xyz>0 1 0</xyz>
          <use_parent_model_frame>1</use_parent_model_frame>
        </axis>
      </joint>
      <joint name='caster_joint_fr' type='revolute'>
        <pose>0 0 0 0 -0 0</pose>
        <parent>base_link</parent>
        <child>caster_link_fr</child>
        <axis>
          <dynamics>
            <damping>1</damping>
            <friction>0</friction>
            <spring_reference>0</spring_reference>
            <spring_stiffness>0</spring_stiffness>
          </dynamics>
          <limit>
            <lower>-1e+16</lower>
            <upper>1e+16</upper>
            <effort>100</effort>
            <velocity>100</velocity>
          </limit>
          <xyz>0 0 1</xyz>
          <use_parent_model_frame>1</use_parent_model_frame>
        </axis>
      </joint>
      <joint name='wheel_joint_fr' type='revolute'>
        <pose>0 0 0 0 -0 0</pose>
        <parent>caster_link_fr</parent>
        <child>wheel_link_fr</child>
        <axis>
          <dynamics>
            <damping>1</damping>
            <friction>0</friction>
            <spring_reference>0</spring_reference>
            <spring_stiffness>0</spring_stiffness>
          </dynamics>
          <limit>
            <lower>-1e+16</lower>
            <upper>1e+16</upper>
            <effort>100</effort>
            <velocity>100</velocity>
          </limit>
          <xyz>0 1 0</xyz>
          <use_parent_model_frame>1</use_parent_model_frame>
        </axis>
      </joint>
      <joint name='plate_joint' type='revolute'>
        <parent>base_link</parent>
        <child>plate_link</child>
        <axis>
          <dynamics>
            <damping>0</damping>
            <friction>0</friction>
            <spring_reference>0</spring_reference>
            <spring_stiffness>0</spring_stiffness>
          </dynamics>
          <limit>
            <lower>0</lower>
            <upper>0</upper>
            <effort>100</effort>
            <velocity>100</velocity>
          </limit>
          <xyz>0 0 1</xyz>
          <use_parent_model_frame>1</use_parent_model_frame>
        </axis>
      </joint>
      <plugin name="gazebo_joint_cmd_plugin" filename="libwheelcmd.so">
          <topicName>/gazebo/commands</topicName>
      </plugin>
      <static>0</static>
    </model>
  </world>
</sdf>
